[2022-06-11 07:00:27,993] {taskinstance.py:1037} INFO - Dependencies all met for <TaskInstance: match_details_dag.daily_transform scheduled__2022-05-23T09:00:00+00:00 [queued]>
[2022-06-11 07:00:28,004] {taskinstance.py:1037} INFO - Dependencies all met for <TaskInstance: match_details_dag.daily_transform scheduled__2022-05-23T09:00:00+00:00 [queued]>
[2022-06-11 07:00:28,005] {taskinstance.py:1243} INFO - 
--------------------------------------------------------------------------------
[2022-06-11 07:00:28,005] {taskinstance.py:1244} INFO - Starting attempt 1 of 2
[2022-06-11 07:00:28,005] {taskinstance.py:1245} INFO - 
--------------------------------------------------------------------------------
[2022-06-11 07:00:28,019] {taskinstance.py:1264} INFO - Executing <Task(BashOperator): daily_transform> on 2022-05-23 09:00:00+00:00
[2022-06-11 07:00:28,025] {standard_task_runner.py:52} INFO - Started process 90 to run task
[2022-06-11 07:00:28,027] {standard_task_runner.py:76} INFO - Running: ['***', 'tasks', 'run', 'match_details_dag', 'daily_transform', 'scheduled__2022-05-23T09:00:00+00:00', '--job-id', '53', '--raw', '--subdir', 'DAGS_FOLDER/matchData_dag.py', '--cfg-path', '/tmp/tmpep60x4_f', '--error-file', '/tmp/tmpl6ctoccg']
[2022-06-11 07:00:28,028] {standard_task_runner.py:77} INFO - Job 53: Subtask daily_transform
[2022-06-11 07:00:28,073] {logging_mixin.py:109} INFO - Running <TaskInstance: match_details_dag.daily_transform scheduled__2022-05-23T09:00:00+00:00 [running]> on host a1cebf1185bf
[2022-06-11 07:00:28,120] {taskinstance.py:1429} INFO - Exporting the following env vars:
AIRFLOW_CTX_DAG_OWNER=admin
AIRFLOW_CTX_DAG_ID=match_details_dag
AIRFLOW_CTX_TASK_ID=daily_transform
AIRFLOW_CTX_EXECUTION_DATE=2022-05-23T09:00:00+00:00
AIRFLOW_CTX_DAG_RUN_ID=scheduled__2022-05-23T09:00:00+00:00
[2022-06-11 07:00:28,121] {subprocess.py:62} INFO - Tmp dir root location: 
 /tmp
[2022-06-11 07:00:28,121] {subprocess.py:74} INFO - Running command: ['bash', '-c', 'cd /opt/***/dbt && dbt deps && dbt run --project-dir /opt/***/dbt --profiles-dir /opt/***/dbt --target dev']
[2022-06-11 07:00:28,130] {subprocess.py:85} INFO - Output:
[2022-06-11 07:00:31,374] {subprocess.py:89} INFO - 07:00:31  Running with dbt=1.1.0
[2022-06-11 07:00:32,144] {subprocess.py:89} INFO - 07:00:32  Installing dbt-labs/dbt_utils
[2022-06-11 07:00:32,693] {subprocess.py:89} INFO - 07:00:32    Installed from version 0.8.5
[2022-06-11 07:00:32,693] {subprocess.py:89} INFO - 07:00:32    Up to date!
[2022-06-11 07:00:37,686] {subprocess.py:89} INFO - 07:00:37  Running with dbt=1.1.0
[2022-06-11 07:00:37,713] {subprocess.py:89} INFO - 07:00:37  Partial parse save file not found. Starting full parse.
[2022-06-11 07:00:39,268] {subprocess.py:89} INFO - 07:00:39  [[33mWARNING[0m]: Configuration paths exist in your dbt_project.yml file which do not apply to any resources.
[2022-06-11 07:00:39,268] {subprocess.py:89} INFO - There are 2 unused configuration paths:
[2022-06-11 07:00:39,269] {subprocess.py:89} INFO - - models.leagueoflegendsdbt.warehouse
[2022-06-11 07:00:39,269] {subprocess.py:89} INFO - - models.leagueoflegendsdbt.view
[2022-06-11 07:00:39,269] {subprocess.py:89} INFO - 
[2022-06-11 07:00:39,293] {subprocess.py:89} INFO - 07:00:39  Found 7 models, 14 tests, 0 snapshots, 0 analyses, 400 macros, 0 operations, 0 seed files, 9 sources, 0 exposures, 0 metrics
[2022-06-11 07:00:39,296] {subprocess.py:89} INFO - 07:00:39
[2022-06-11 07:00:41,314] {subprocess.py:89} INFO - 07:00:41  Concurrency: 10 threads (target='dev')
[2022-06-11 07:00:41,315] {subprocess.py:89} INFO - 07:00:41
[2022-06-11 07:00:41,343] {subprocess.py:89} INFO - 07:00:41  1 of 7 START view model PUBLIC.stg_champions ................................... [RUN]
[2022-06-11 07:00:41,347] {subprocess.py:89} INFO - 07:00:41  2 of 7 START view model PUBLIC.stg_items ....................................... [RUN]
[2022-06-11 07:00:41,350] {subprocess.py:89} INFO - 07:00:41  3 of 7 START view model PUBLIC.stg_maps ........................................ [RUN]
[2022-06-11 07:00:41,351] {subprocess.py:89} INFO - 07:00:41  4 of 7 START view model PUBLIC.stg_match_details ............................... [RUN]
[2022-06-11 07:00:41,352] {subprocess.py:89} INFO - 07:00:41  5 of 7 START view model PUBLIC.stg_match_info .................................. [RUN]
[2022-06-11 07:00:41,353] {subprocess.py:89} INFO - 07:00:41  6 of 7 START view model PUBLIC.stg_runes_reforged .............................. [RUN]
[2022-06-11 07:00:41,355] {subprocess.py:89} INFO - 07:00:41  7 of 7 START view model PUBLIC.stg_summonerspells .............................. [RUN]
[2022-06-11 07:00:44,120] {subprocess.py:89} INFO - 07:00:44  4 of 7 ERROR creating view model PUBLIC.stg_match_details ...................... [[31mERROR[0m in 2.77s]
[2022-06-11 07:00:44,129] {subprocess.py:89} INFO - 07:00:44  5 of 7 ERROR creating view model PUBLIC.stg_match_info ......................... [[31mERROR[0m in 2.78s]
[2022-06-11 07:00:44,177] {subprocess.py:89} INFO - 07:00:44  7 of 7 ERROR creating view model PUBLIC.stg_summonerspells ..................... [[31mERROR[0m in 2.82s]
[2022-06-11 07:00:44,222] {subprocess.py:89} INFO - 07:00:44  6 of 7 OK created view model PUBLIC.stg_runes_reforged ......................... [[32mSUCCESS 1[0m in 2.87s]
[2022-06-11 07:00:44,293] {subprocess.py:89} INFO - 07:00:44  2 of 7 OK created view model PUBLIC.stg_items .................................. [[32mSUCCESS 1[0m in 2.94s]
[2022-06-11 07:00:44,294] {subprocess.py:89} INFO - 07:00:44  1 of 7 OK created view model PUBLIC.stg_champions .............................. [[32mSUCCESS 1[0m in 2.95s]
[2022-06-11 07:00:44,396] {subprocess.py:89} INFO - 07:00:44  3 of 7 OK created view model PUBLIC.stg_maps ................................... [[32mSUCCESS 1[0m in 3.04s]
[2022-06-11 07:00:44,403] {subprocess.py:89} INFO - 07:00:44
[2022-06-11 07:00:44,405] {subprocess.py:89} INFO - 07:00:44  Finished running 7 view models in 5.11s.
[2022-06-11 07:00:44,428] {subprocess.py:89} INFO - 07:00:44
[2022-06-11 07:00:44,429] {subprocess.py:89} INFO - 07:00:44  [31mCompleted with 3 errors and 0 warnings:[0m
[2022-06-11 07:00:44,430] {subprocess.py:89} INFO - 07:00:44
[2022-06-11 07:00:44,431] {subprocess.py:89} INFO - 07:00:44  [33mDatabase Error in model stg_match_details (models/staging/stg_match_details.sql)[0m
[2022-06-11 07:00:44,432] {subprocess.py:89} INFO - 07:00:44    002003 (42S02): SQL compilation error:
[2022-06-11 07:00:44,433] {subprocess.py:89} INFO - 07:00:44    Object 'LEAGUE_OF_LEGENDSDB.PUBLIC.STAGING_MATCH_DETAILS' does not exist or not authorized.
[2022-06-11 07:00:44,435] {subprocess.py:89} INFO - 07:00:44    compiled SQL at target/run/leagueoflegendsdbt/models/staging/stg_match_details.sql
[2022-06-11 07:00:44,436] {subprocess.py:89} INFO - 07:00:44
[2022-06-11 07:00:44,437] {subprocess.py:89} INFO - 07:00:44  [33mDatabase Error in model stg_match_info (models/staging/stg_match_info.sql)[0m
[2022-06-11 07:00:44,440] {subprocess.py:89} INFO - 07:00:44    002003 (42S02): SQL compilation error:
[2022-06-11 07:00:44,441] {subprocess.py:89} INFO - 07:00:44    Object 'LEAGUE_OF_LEGENDSDB.PUBLIC.STAGING_MATCH_INFO' does not exist or not authorized.
[2022-06-11 07:00:44,441] {subprocess.py:89} INFO - 07:00:44    compiled SQL at target/run/leagueoflegendsdbt/models/staging/stg_match_info.sql
[2022-06-11 07:00:44,443] {subprocess.py:89} INFO - 07:00:44
[2022-06-11 07:00:44,444] {subprocess.py:89} INFO - 07:00:44  [33mDatabase Error in model stg_summonerspells (models/staging_datadragon/stg_summonerspells.sql)[0m
[2022-06-11 07:00:44,444] {subprocess.py:89} INFO - 07:00:44    002025 (42S21): SQL compilation error:
[2022-06-11 07:00:44,445] {subprocess.py:89} INFO - 07:00:44    duplicate column name 'COOLDOWN'
[2022-06-11 07:00:44,446] {subprocess.py:89} INFO - 07:00:44    compiled SQL at target/run/leagueoflegendsdbt/models/staging_datadragon/stg_summonerspells.sql
[2022-06-11 07:00:44,448] {subprocess.py:89} INFO - 07:00:44
[2022-06-11 07:00:44,449] {subprocess.py:89} INFO - 07:00:44  Done. PASS=4 WARN=0 ERROR=3 SKIP=0 TOTAL=7
[2022-06-11 07:00:45,122] {subprocess.py:93} INFO - Command exited with return code 1
[2022-06-11 07:00:45,136] {taskinstance.py:1718} ERROR - Task failed with exception
Traceback (most recent call last):
  File "/home/airflow/.local/lib/python3.8/site-packages/airflow/models/taskinstance.py", line 1334, in _run_raw_task
    self._execute_task_with_callbacks(context)
  File "/home/airflow/.local/lib/python3.8/site-packages/airflow/models/taskinstance.py", line 1460, in _execute_task_with_callbacks
    result = self._execute_task(context, self.task)
  File "/home/airflow/.local/lib/python3.8/site-packages/airflow/models/taskinstance.py", line 1516, in _execute_task
    result = execute_callable(context=context)
  File "/home/airflow/.local/lib/python3.8/site-packages/airflow/operators/bash.py", line 187, in execute
    raise AirflowException(
airflow.exceptions.AirflowException: Bash command failed. The command returned a non-zero exit code 1.
[2022-06-11 07:00:45,142] {taskinstance.py:1272} INFO - Marking task as UP_FOR_RETRY. dag_id=match_details_dag, task_id=daily_transform, execution_date=20220523T090000, start_date=20220611T070027, end_date=20220611T070045
[2022-06-11 07:00:45,157] {standard_task_runner.py:89} ERROR - Failed to execute job 53 for task daily_transform
Traceback (most recent call last):
  File "/home/airflow/.local/lib/python3.8/site-packages/airflow/task/task_runner/standard_task_runner.py", line 85, in _start_by_fork
    args.func(args, dag=self.dag)
  File "/home/airflow/.local/lib/python3.8/site-packages/airflow/cli/cli_parser.py", line 48, in command
    return func(*args, **kwargs)
  File "/home/airflow/.local/lib/python3.8/site-packages/airflow/utils/cli.py", line 92, in wrapper
    return f(*args, **kwargs)
  File "/home/airflow/.local/lib/python3.8/site-packages/airflow/cli/commands/task_command.py", line 298, in task_run
    _run_task_by_selected_method(args, dag, ti)
  File "/home/airflow/.local/lib/python3.8/site-packages/airflow/cli/commands/task_command.py", line 107, in _run_task_by_selected_method
    _run_raw_task(args, ti)
  File "/home/airflow/.local/lib/python3.8/site-packages/airflow/cli/commands/task_command.py", line 180, in _run_raw_task
    ti._run_raw_task(
  File "/home/airflow/.local/lib/python3.8/site-packages/airflow/utils/session.py", line 70, in wrapper
    return func(*args, session=session, **kwargs)
  File "/home/airflow/.local/lib/python3.8/site-packages/airflow/models/taskinstance.py", line 1334, in _run_raw_task
    self._execute_task_with_callbacks(context)
  File "/home/airflow/.local/lib/python3.8/site-packages/airflow/models/taskinstance.py", line 1460, in _execute_task_with_callbacks
    result = self._execute_task(context, self.task)
  File "/home/airflow/.local/lib/python3.8/site-packages/airflow/models/taskinstance.py", line 1516, in _execute_task
    result = execute_callable(context=context)
  File "/home/airflow/.local/lib/python3.8/site-packages/airflow/operators/bash.py", line 187, in execute
    raise AirflowException(
airflow.exceptions.AirflowException: Bash command failed. The command returned a non-zero exit code 1.
[2022-06-11 07:00:45,197] {local_task_job.py:154} INFO - Task exited with return code 1
[2022-06-11 07:00:45,228] {local_task_job.py:264} INFO - 0 downstream tasks scheduled from follow-on schedule check
