[2022-06-11 07:02:00,004] {taskinstance.py:1037} INFO - Dependencies all met for <TaskInstance: match_details_dag.daily_transform scheduled__2022-05-23T09:00:00+00:00 [None]>
[2022-06-11 07:02:00,012] {taskinstance.py:1037} INFO - Dependencies all met for <TaskInstance: match_details_dag.daily_transform scheduled__2022-05-23T09:00:00+00:00 [None]>
[2022-06-11 07:02:00,012] {taskinstance.py:1243} INFO - 
--------------------------------------------------------------------------------
[2022-06-11 07:02:00,013] {taskinstance.py:1244} INFO - Starting attempt 2 of 3
[2022-06-11 07:02:00,013] {taskinstance.py:1245} INFO - 
--------------------------------------------------------------------------------
[2022-06-11 07:02:00,026] {taskinstance.py:1264} INFO - Executing <Task(BashOperator): daily_transform> on 2022-05-23 09:00:00+00:00
[2022-06-11 07:02:00,031] {standard_task_runner.py:52} INFO - Started process 177 to run task
[2022-06-11 07:02:00,034] {standard_task_runner.py:76} INFO - Running: ['***', 'tasks', 'run', 'match_details_dag', 'daily_transform', 'scheduled__2022-05-23T09:00:00+00:00', '--job-id', '54', '--pool', 'default_pool', '--raw', '--subdir', 'DAGS_FOLDER/matchData_dag.py', '--cfg-path', '/tmp/tmph9eszc1e', '--error-file', '/tmp/tmpo9zfbb3j']
[2022-06-11 07:02:00,034] {standard_task_runner.py:77} INFO - Job 54: Subtask daily_transform
[2022-06-11 07:02:00,079] {logging_mixin.py:109} INFO - Running <TaskInstance: match_details_dag.daily_transform scheduled__2022-05-23T09:00:00+00:00 [running]> on host a1cebf1185bf
[2022-06-11 07:02:00,117] {taskinstance.py:1429} INFO - Exporting the following env vars:
AIRFLOW_CTX_DAG_OWNER=admin
AIRFLOW_CTX_DAG_ID=match_details_dag
AIRFLOW_CTX_TASK_ID=daily_transform
AIRFLOW_CTX_EXECUTION_DATE=2022-05-23T09:00:00+00:00
AIRFLOW_CTX_DAG_RUN_ID=scheduled__2022-05-23T09:00:00+00:00
[2022-06-11 07:02:00,118] {subprocess.py:62} INFO - Tmp dir root location: 
 /tmp
[2022-06-11 07:02:00,118] {subprocess.py:74} INFO - Running command: ['bash', '-c', 'cd /opt/***/dbt && dbt deps && dbt run --project-dir /opt/***/dbt --profiles-dir /opt/***/dbt --target dev']
[2022-06-11 07:02:00,127] {subprocess.py:85} INFO - Output:
[2022-06-11 07:02:03,140] {subprocess.py:89} INFO - 07:02:03  Running with dbt=1.1.0
[2022-06-11 07:02:03,539] {subprocess.py:89} INFO - 07:02:03  Installing dbt-labs/dbt_utils
[2022-06-11 07:02:04,148] {subprocess.py:89} INFO - 07:02:04    Installed from version 0.8.5
[2022-06-11 07:02:04,148] {subprocess.py:89} INFO - 07:02:04    Up to date!
[2022-06-11 07:02:08,961] {subprocess.py:89} INFO - 07:02:08  Running with dbt=1.1.0
[2022-06-11 07:02:09,044] {subprocess.py:89} INFO - 07:02:09  [[33mWARNING[0m]: Configuration paths exist in your dbt_project.yml file which do not apply to any resources.
[2022-06-11 07:02:09,044] {subprocess.py:89} INFO - There are 2 unused configuration paths:
[2022-06-11 07:02:09,044] {subprocess.py:89} INFO - - models.leagueoflegendsdbt.view
[2022-06-11 07:02:09,045] {subprocess.py:89} INFO - - models.leagueoflegendsdbt.warehouse
[2022-06-11 07:02:09,045] {subprocess.py:89} INFO - 
[2022-06-11 07:02:09,069] {subprocess.py:89} INFO - 07:02:09  Found 7 models, 14 tests, 0 snapshots, 0 analyses, 400 macros, 0 operations, 0 seed files, 9 sources, 0 exposures, 0 metrics
[2022-06-11 07:02:09,072] {subprocess.py:89} INFO - 07:02:09
[2022-06-11 07:02:10,974] {subprocess.py:89} INFO - 07:02:10  Concurrency: 10 threads (target='dev')
[2022-06-11 07:02:10,974] {subprocess.py:89} INFO - 07:02:10
[2022-06-11 07:02:10,999] {subprocess.py:89} INFO - 07:02:10  1 of 7 START view model PUBLIC.stg_champions ................................... [RUN]
[2022-06-11 07:02:11,001] {subprocess.py:89} INFO - 07:02:11  2 of 7 START view model PUBLIC.stg_items ....................................... [RUN]
[2022-06-11 07:02:11,005] {subprocess.py:89} INFO - 07:02:11  3 of 7 START view model PUBLIC.stg_maps ........................................ [RUN]
[2022-06-11 07:02:11,006] {subprocess.py:89} INFO - 07:02:11  4 of 7 START view model PUBLIC.stg_match_details ............................... [RUN]
[2022-06-11 07:02:11,007] {subprocess.py:89} INFO - 07:02:11  5 of 7 START view model PUBLIC.stg_match_info .................................. [RUN]
[2022-06-11 07:02:11,008] {subprocess.py:89} INFO - 07:02:11  6 of 7 START view model PUBLIC.stg_runes_reforged .............................. [RUN]
[2022-06-11 07:02:11,009] {subprocess.py:89} INFO - 07:02:11  7 of 7 START view model PUBLIC.stg_summonerspells .............................. [RUN]
[2022-06-11 07:02:14,029] {subprocess.py:89} INFO - 07:02:14  1 of 7 OK created view model PUBLIC.stg_champions .............................. [[32mSUCCESS 1[0m in 3.03s]
[2022-06-11 07:02:14,330] {subprocess.py:89} INFO - 07:02:14  6 of 7 OK created view model PUBLIC.stg_runes_reforged ......................... [[32mSUCCESS 1[0m in 3.31s]
[2022-06-11 07:02:14,333] {subprocess.py:89} INFO - 07:02:14  2 of 7 OK created view model PUBLIC.stg_items .................................. [[32mSUCCESS 1[0m in 3.32s]
[2022-06-11 07:02:14,338] {subprocess.py:89} INFO - 07:02:14  3 of 7 OK created view model PUBLIC.stg_maps ................................... [[32mSUCCESS 1[0m in 3.33s]
[2022-06-11 07:02:14,339] {subprocess.py:89} INFO - 07:02:14  7 of 7 ERROR creating view model PUBLIC.stg_summonerspells ..................... [[31mERROR[0m in 3.32s]
[2022-06-11 07:02:14,341] {subprocess.py:89} INFO - 07:02:14  5 of 7 ERROR creating view model PUBLIC.stg_match_info ......................... [[31mERROR[0m in 3.33s]
[2022-06-11 07:02:14,342] {subprocess.py:89} INFO - 07:02:14  4 of 7 ERROR creating view model PUBLIC.stg_match_details ...................... [[31mERROR[0m in 3.33s]
[2022-06-11 07:02:14,350] {subprocess.py:89} INFO - 07:02:14
[2022-06-11 07:02:14,351] {subprocess.py:89} INFO - 07:02:14  Finished running 7 view models in 5.28s.
[2022-06-11 07:02:14,444] {subprocess.py:89} INFO - 07:02:14
[2022-06-11 07:02:14,445] {subprocess.py:89} INFO - 07:02:14  [31mCompleted with 3 errors and 0 warnings:[0m
[2022-06-11 07:02:14,445] {subprocess.py:89} INFO - 07:02:14
[2022-06-11 07:02:14,446] {subprocess.py:89} INFO - 07:02:14  [33mDatabase Error in model stg_summonerspells (models/staging_datadragon/stg_summonerspells.sql)[0m
[2022-06-11 07:02:14,446] {subprocess.py:89} INFO - 07:02:14    002025 (42S21): SQL compilation error:
[2022-06-11 07:02:14,447] {subprocess.py:89} INFO - 07:02:14    duplicate column name 'COOLDOWN'
[2022-06-11 07:02:14,448] {subprocess.py:89} INFO - 07:02:14    compiled SQL at target/run/leagueoflegendsdbt/models/staging_datadragon/stg_summonerspells.sql
[2022-06-11 07:02:14,448] {subprocess.py:89} INFO - 07:02:14
[2022-06-11 07:02:14,448] {subprocess.py:89} INFO - 07:02:14  [33mDatabase Error in model stg_match_info (models/staging/stg_match_info.sql)[0m
[2022-06-11 07:02:14,449] {subprocess.py:89} INFO - 07:02:14    002003 (42S02): SQL compilation error:
[2022-06-11 07:02:14,449] {subprocess.py:89} INFO - 07:02:14    Object 'LEAGUE_OF_LEGENDSDB.PUBLIC.STAGING_MATCH_INFO' does not exist or not authorized.
[2022-06-11 07:02:14,450] {subprocess.py:89} INFO - 07:02:14    compiled SQL at target/run/leagueoflegendsdbt/models/staging/stg_match_info.sql
[2022-06-11 07:02:14,450] {subprocess.py:89} INFO - 07:02:14
[2022-06-11 07:02:14,451] {subprocess.py:89} INFO - 07:02:14  [33mDatabase Error in model stg_match_details (models/staging/stg_match_details.sql)[0m
[2022-06-11 07:02:14,451] {subprocess.py:89} INFO - 07:02:14    002003 (42S02): SQL compilation error:
[2022-06-11 07:02:14,451] {subprocess.py:89} INFO - 07:02:14    Object 'LEAGUE_OF_LEGENDSDB.PUBLIC.STAGING_MATCH_DETAILS' does not exist or not authorized.
[2022-06-11 07:02:14,452] {subprocess.py:89} INFO - 07:02:14    compiled SQL at target/run/leagueoflegendsdbt/models/staging/stg_match_details.sql
[2022-06-11 07:02:14,452] {subprocess.py:89} INFO - 07:02:14
[2022-06-11 07:02:14,453] {subprocess.py:89} INFO - 07:02:14  Done. PASS=4 WARN=0 ERROR=3 SKIP=0 TOTAL=7
[2022-06-11 07:02:15,192] {subprocess.py:93} INFO - Command exited with return code 1
[2022-06-11 07:02:15,202] {taskinstance.py:1718} ERROR - Task failed with exception
Traceback (most recent call last):
  File "/home/airflow/.local/lib/python3.8/site-packages/airflow/models/taskinstance.py", line 1334, in _run_raw_task
    self._execute_task_with_callbacks(context)
  File "/home/airflow/.local/lib/python3.8/site-packages/airflow/models/taskinstance.py", line 1460, in _execute_task_with_callbacks
    result = self._execute_task(context, self.task)
  File "/home/airflow/.local/lib/python3.8/site-packages/airflow/models/taskinstance.py", line 1516, in _execute_task
    result = execute_callable(context=context)
  File "/home/airflow/.local/lib/python3.8/site-packages/airflow/operators/bash.py", line 187, in execute
    raise AirflowException(
airflow.exceptions.AirflowException: Bash command failed. The command returned a non-zero exit code 1.
[2022-06-11 07:02:15,209] {taskinstance.py:1272} INFO - Marking task as UP_FOR_RETRY. dag_id=match_details_dag, task_id=daily_transform, execution_date=20220523T090000, start_date=20220611T070200, end_date=20220611T070215
[2022-06-11 07:02:15,223] {standard_task_runner.py:89} ERROR - Failed to execute job 54 for task daily_transform
Traceback (most recent call last):
  File "/home/airflow/.local/lib/python3.8/site-packages/airflow/task/task_runner/standard_task_runner.py", line 85, in _start_by_fork
    args.func(args, dag=self.dag)
  File "/home/airflow/.local/lib/python3.8/site-packages/airflow/cli/cli_parser.py", line 48, in command
    return func(*args, **kwargs)
  File "/home/airflow/.local/lib/python3.8/site-packages/airflow/utils/cli.py", line 92, in wrapper
    return f(*args, **kwargs)
  File "/home/airflow/.local/lib/python3.8/site-packages/airflow/cli/commands/task_command.py", line 298, in task_run
    _run_task_by_selected_method(args, dag, ti)
  File "/home/airflow/.local/lib/python3.8/site-packages/airflow/cli/commands/task_command.py", line 107, in _run_task_by_selected_method
    _run_raw_task(args, ti)
  File "/home/airflow/.local/lib/python3.8/site-packages/airflow/cli/commands/task_command.py", line 180, in _run_raw_task
    ti._run_raw_task(
  File "/home/airflow/.local/lib/python3.8/site-packages/airflow/utils/session.py", line 70, in wrapper
    return func(*args, session=session, **kwargs)
  File "/home/airflow/.local/lib/python3.8/site-packages/airflow/models/taskinstance.py", line 1334, in _run_raw_task
    self._execute_task_with_callbacks(context)
  File "/home/airflow/.local/lib/python3.8/site-packages/airflow/models/taskinstance.py", line 1460, in _execute_task_with_callbacks
    result = self._execute_task(context, self.task)
  File "/home/airflow/.local/lib/python3.8/site-packages/airflow/models/taskinstance.py", line 1516, in _execute_task
    result = execute_callable(context=context)
  File "/home/airflow/.local/lib/python3.8/site-packages/airflow/operators/bash.py", line 187, in execute
    raise AirflowException(
airflow.exceptions.AirflowException: Bash command failed. The command returned a non-zero exit code 1.
[2022-06-11 07:02:15,230] {local_task_job.py:211} WARNING - State of this instance has been externally set to up_for_retry. Terminating instance.
[2022-06-11 07:02:15,231] {process_utils.py:120} INFO - Sending Signals.SIGTERM to group 177. PIDs of all processes in the group: [177]
[2022-06-11 07:02:15,231] {process_utils.py:75} INFO - Sending the signal Signals.SIGTERM to group 177
[2022-06-11 07:02:15,231] {process_utils.py:70} INFO - Process psutil.Process(pid=177, status='terminated', exitcode=1, started='07:01:59') (177) terminated with exit code 1
