[2022-05-19 22:40:55,397] {taskinstance.py:1037} INFO - Dependencies all met for <TaskInstance: league_of_legends_dag.paths.path_runesreforged.staging_runesreforged manual__2022-05-19T22:40:51.845419+00:00 [queued]>
[2022-05-19 22:40:55,413] {taskinstance.py:1037} INFO - Dependencies all met for <TaskInstance: league_of_legends_dag.paths.path_runesreforged.staging_runesreforged manual__2022-05-19T22:40:51.845419+00:00 [queued]>
[2022-05-19 22:40:55,414] {taskinstance.py:1243} INFO - 
--------------------------------------------------------------------------------
[2022-05-19 22:40:55,414] {taskinstance.py:1244} INFO - Starting attempt 1 of 2
[2022-05-19 22:40:55,414] {taskinstance.py:1245} INFO - 
--------------------------------------------------------------------------------
[2022-05-19 22:40:55,430] {taskinstance.py:1264} INFO - Executing <Task(riot_dataDragonToADLSOperator): paths.path_runesreforged.staging_runesreforged> on 2022-05-19 22:40:51.845419+00:00
[2022-05-19 22:40:55,438] {standard_task_runner.py:52} INFO - Started process 1478 to run task
[2022-05-19 22:40:55,443] {standard_task_runner.py:76} INFO - Running: ['***', 'tasks', 'run', 'league_of_legends_dag', 'paths.path_runesreforged.staging_runesreforged', 'manual__2022-05-19T22:40:51.845419+00:00', '--job-id', '283', '--raw', '--subdir', 'DAGS_FOLDER/dataDragon_dag.py', '--cfg-path', '/tmp/tmpmjr46q9h', '--error-file', '/tmp/tmp3erpm873']
[2022-05-19 22:40:55,444] {standard_task_runner.py:77} INFO - Job 283: Subtask paths.path_runesreforged.staging_runesreforged
[2022-05-19 22:40:55,504] {logging_mixin.py:109} INFO - Running <TaskInstance: league_of_legends_dag.paths.path_runesreforged.staging_runesreforged manual__2022-05-19T22:40:51.845419+00:00 [running]> on host ca9a242fab95
[2022-05-19 22:40:55,564] {taskinstance.py:1429} INFO - Exporting the following env vars:
AIRFLOW_CTX_DAG_OWNER=admin
AIRFLOW_CTX_DAG_ID=league_of_legends_dag
AIRFLOW_CTX_TASK_ID=paths.path_runesreforged.staging_runesreforged
AIRFLOW_CTX_EXECUTION_DATE=2022-05-19T22:40:51.845419+00:00
AIRFLOW_CTX_DAG_RUN_ID=manual__2022-05-19T22:40:51.845419+00:00
[2022-05-19 22:40:55,565] {riot_datadragon_toADLS_Operator.py:55} INFO - StageToAzureLake not implemented yet
[2022-05-19 22:40:55,578] {riot_datadragon_toADLS_Operator.py:63} INFO - <bound method WasbHook.get_conn of <airflow.providers.microsoft.azure.hooks.wasb.WasbHook object at 0x7f26be130e50>>
[2022-05-19 22:40:55,578] {riot_datadragon_toADLS_Operator.py:64} INFO - Created Azure Connections
[2022-05-19 22:40:55,682] {riot_datadragon_toADLS_Operator.py:86} INFO - About to load to Azure!
[2022-05-19 22:40:55,685] {_universal.py:472} INFO - Request URL: 'https://leagueoflegends.blob.core.windows.net/leagueoflegends/datadragon-runesreforged/2022/5/19/22.json'/nRequest method: 'PUT'/nRequest headers:/n    'x-ms-blob-type': 'REDACTED'/n    'Content-Length': '39147'/n    'If-None-Match': '*'/n    'x-ms-version': 'REDACTED'/n    'Content-Type': 'application/octet-stream'/n    'Accept': 'application/xml'/n    'User-Agent': 'azsdk-python-storage-blob/12.8.1 Python/3.8.12 (Linux-5.10.102.1-microsoft-standard-WSL2-x86_64-with-glibc2.2.5)'/n    'x-ms-date': 'REDACTED'/n    'x-ms-client-request-id': 'bed53556-d7c4-11ec-9e45-0242ac140007'/n    'Authorization': 'REDACTED'/nA body is sent with the request
[2022-05-19 22:40:55,825] {_universal.py:503} INFO - Response status: 404/nResponse headers:/n    'Content-Length': '225'/n    'Content-Type': 'application/xml'/n    'Server': 'Windows-Azure-Blob/1.0 Microsoft-HTTPAPI/2.0'/n    'x-ms-request-id': '27b6e687-901e-0062-3ad1-6ba6f3000000'/n    'x-ms-client-request-id': 'bed53556-d7c4-11ec-9e45-0242ac140007'/n    'x-ms-version': 'REDACTED'/n    'x-ms-error-code': 'REDACTED'/n    'Date': 'Thu, 19 May 2022 22:40:56 GMT'
[2022-05-19 22:40:55,828] {taskinstance.py:1718} ERROR - Task failed with exception
Traceback (most recent call last):
  File "/home/airflow/.local/lib/python3.8/site-packages/azure/storage/blob/_upload_helpers.py", line 94, in upload_block_blob
    return client.upload(
  File "/home/airflow/.local/lib/python3.8/site-packages/azure/storage/blob/_generated/operations/_block_blob_operations.py", line 228, in upload
    map_error(status_code=response.status_code, response=response, error_map=error_map)
  File "/home/airflow/.local/lib/python3.8/site-packages/azure/core/exceptions.py", line 105, in map_error
    raise error
azure.core.exceptions.ResourceNotFoundError: Operation returned an invalid status 'The specified container does not exist.'
Content: <?xml version="1.0" encoding="utf-8"?><Error><Code>ContainerNotFound</Code><Message>The specified container does not exist.
RequestId:27b6e687-901e-0062-3ad1-6ba6f3000000
Time:2022-05-19T22:40:57.3463633Z</Message></Error>

During handling of the above exception, another exception occurred:

Traceback (most recent call last):
  File "/home/airflow/.local/lib/python3.8/site-packages/airflow/models/taskinstance.py", line 1334, in _run_raw_task
    self._execute_task_with_callbacks(context)
  File "/home/airflow/.local/lib/python3.8/site-packages/airflow/models/taskinstance.py", line 1460, in _execute_task_with_callbacks
    result = self._execute_task(context, self.task)
  File "/home/airflow/.local/lib/python3.8/site-packages/airflow/models/taskinstance.py", line 1516, in _execute_task
    result = execute_callable(context=context)
  File "/opt/airflow/plugins/custom_operators/riot_datadragon_toADLS_Operator.py", line 56, in execute
    self.upload_to_azureLake()
  File "/opt/airflow/plugins/custom_operators/riot_datadragon_toADLS_Operator.py", line 87, in upload_to_azureLake
    wasb_hook.load_file(
  File "/home/airflow/.local/lib/python3.8/site-packages/airflow/providers/microsoft/azure/hooks/wasb.py", line 254, in load_file
    self.upload(
  File "/home/airflow/.local/lib/python3.8/site-packages/airflow/providers/microsoft/azure/hooks/wasb.py", line 339, in upload
    return blob_client.upload_blob(data, blob_type, length=length, **kwargs)
  File "/home/airflow/.local/lib/python3.8/site-packages/azure/core/tracing/decorator.py", line 83, in wrapper_use_tracer
    return func(*args, **kwargs)
  File "/home/airflow/.local/lib/python3.8/site-packages/azure/storage/blob/_blob_client.py", line 693, in upload_blob
    return upload_block_blob(**options)
  File "/home/airflow/.local/lib/python3.8/site-packages/azure/storage/blob/_upload_helpers.py", line 157, in upload_block_blob
    process_storage_error(error)
  File "/home/airflow/.local/lib/python3.8/site-packages/azure/storage/blob/_shared/response_handlers.py", line 150, in process_storage_error
    error.raise_with_traceback()
  File "/home/airflow/.local/lib/python3.8/site-packages/azure/core/exceptions.py", line 247, in raise_with_traceback
    raise super(AzureError, self).with_traceback(self.exc_traceback)
  File "/home/airflow/.local/lib/python3.8/site-packages/azure/storage/blob/_upload_helpers.py", line 94, in upload_block_blob
    return client.upload(
  File "/home/airflow/.local/lib/python3.8/site-packages/azure/storage/blob/_generated/operations/_block_blob_operations.py", line 228, in upload
    map_error(status_code=response.status_code, response=response, error_map=error_map)
  File "/home/airflow/.local/lib/python3.8/site-packages/azure/core/exceptions.py", line 105, in map_error
    raise error
azure.core.exceptions.ResourceNotFoundError: The specified container does not exist.
RequestId:27b6e687-901e-0062-3ad1-6ba6f3000000
Time:2022-05-19T22:40:57.3463633Z
ErrorCode:ContainerNotFound
Error:None
Content: <?xml version="1.0" encoding="utf-8"?><Error><Code>ContainerNotFound</Code><Message>The specified container does not exist.
RequestId:27b6e687-901e-0062-3ad1-6ba6f3000000
Time:2022-05-19T22:40:57.3463633Z</Message></Error>
[2022-05-19 22:40:55,843] {taskinstance.py:1272} INFO - Marking task as UP_FOR_RETRY. dag_id=league_of_legends_dag, task_id=paths.path_runesreforged.staging_runesreforged, execution_date=20220519T224051, start_date=20220519T224055, end_date=20220519T224055
[2022-05-19 22:40:55,858] {standard_task_runner.py:89} ERROR - Failed to execute job 283 for task paths.path_runesreforged.staging_runesreforged
Traceback (most recent call last):
  File "/home/airflow/.local/lib/python3.8/site-packages/azure/storage/blob/_upload_helpers.py", line 94, in upload_block_blob
    return client.upload(
  File "/home/airflow/.local/lib/python3.8/site-packages/azure/storage/blob/_generated/operations/_block_blob_operations.py", line 228, in upload
    map_error(status_code=response.status_code, response=response, error_map=error_map)
  File "/home/airflow/.local/lib/python3.8/site-packages/azure/core/exceptions.py", line 105, in map_error
    raise error
azure.core.exceptions.ResourceNotFoundError: Operation returned an invalid status 'The specified container does not exist.'
Content: <?xml version="1.0" encoding="utf-8"?><Error><Code>ContainerNotFound</Code><Message>The specified container does not exist.
RequestId:27b6e687-901e-0062-3ad1-6ba6f3000000
Time:2022-05-19T22:40:57.3463633Z</Message></Error>

During handling of the above exception, another exception occurred:

Traceback (most recent call last):
  File "/home/airflow/.local/lib/python3.8/site-packages/airflow/task/task_runner/standard_task_runner.py", line 85, in _start_by_fork
    args.func(args, dag=self.dag)
  File "/home/airflow/.local/lib/python3.8/site-packages/airflow/cli/cli_parser.py", line 48, in command
    return func(*args, **kwargs)
  File "/home/airflow/.local/lib/python3.8/site-packages/airflow/utils/cli.py", line 92, in wrapper
    return f(*args, **kwargs)
  File "/home/airflow/.local/lib/python3.8/site-packages/airflow/cli/commands/task_command.py", line 298, in task_run
    _run_task_by_selected_method(args, dag, ti)
  File "/home/airflow/.local/lib/python3.8/site-packages/airflow/cli/commands/task_command.py", line 107, in _run_task_by_selected_method
    _run_raw_task(args, ti)
  File "/home/airflow/.local/lib/python3.8/site-packages/airflow/cli/commands/task_command.py", line 180, in _run_raw_task
    ti._run_raw_task(
  File "/home/airflow/.local/lib/python3.8/site-packages/airflow/utils/session.py", line 70, in wrapper
    return func(*args, session=session, **kwargs)
  File "/home/airflow/.local/lib/python3.8/site-packages/airflow/models/taskinstance.py", line 1334, in _run_raw_task
    self._execute_task_with_callbacks(context)
  File "/home/airflow/.local/lib/python3.8/site-packages/airflow/models/taskinstance.py", line 1460, in _execute_task_with_callbacks
    result = self._execute_task(context, self.task)
  File "/home/airflow/.local/lib/python3.8/site-packages/airflow/models/taskinstance.py", line 1516, in _execute_task
    result = execute_callable(context=context)
  File "/opt/airflow/plugins/custom_operators/riot_datadragon_toADLS_Operator.py", line 56, in execute
    self.upload_to_azureLake()
  File "/opt/airflow/plugins/custom_operators/riot_datadragon_toADLS_Operator.py", line 87, in upload_to_azureLake
    wasb_hook.load_file(
  File "/home/airflow/.local/lib/python3.8/site-packages/airflow/providers/microsoft/azure/hooks/wasb.py", line 254, in load_file
    self.upload(
  File "/home/airflow/.local/lib/python3.8/site-packages/airflow/providers/microsoft/azure/hooks/wasb.py", line 339, in upload
    return blob_client.upload_blob(data, blob_type, length=length, **kwargs)
  File "/home/airflow/.local/lib/python3.8/site-packages/azure/core/tracing/decorator.py", line 83, in wrapper_use_tracer
    return func(*args, **kwargs)
  File "/home/airflow/.local/lib/python3.8/site-packages/azure/storage/blob/_blob_client.py", line 693, in upload_blob
    return upload_block_blob(**options)
  File "/home/airflow/.local/lib/python3.8/site-packages/azure/storage/blob/_upload_helpers.py", line 157, in upload_block_blob
    process_storage_error(error)
  File "/home/airflow/.local/lib/python3.8/site-packages/azure/storage/blob/_shared/response_handlers.py", line 150, in process_storage_error
    error.raise_with_traceback()
  File "/home/airflow/.local/lib/python3.8/site-packages/azure/core/exceptions.py", line 247, in raise_with_traceback
    raise super(AzureError, self).with_traceback(self.exc_traceback)
  File "/home/airflow/.local/lib/python3.8/site-packages/azure/storage/blob/_upload_helpers.py", line 94, in upload_block_blob
    return client.upload(
  File "/home/airflow/.local/lib/python3.8/site-packages/azure/storage/blob/_generated/operations/_block_blob_operations.py", line 228, in upload
    map_error(status_code=response.status_code, response=response, error_map=error_map)
  File "/home/airflow/.local/lib/python3.8/site-packages/azure/core/exceptions.py", line 105, in map_error
    raise error
azure.core.exceptions.ResourceNotFoundError: The specified container does not exist.
RequestId:27b6e687-901e-0062-3ad1-6ba6f3000000
Time:2022-05-19T22:40:57.3463633Z
ErrorCode:ContainerNotFound
Error:None
Content: <?xml version="1.0" encoding="utf-8"?><Error><Code>ContainerNotFound</Code><Message>The specified container does not exist.
RequestId:27b6e687-901e-0062-3ad1-6ba6f3000000
Time:2022-05-19T22:40:57.3463633Z</Message></Error>
[2022-05-19 22:40:55,896] {local_task_job.py:154} INFO - Task exited with return code 1
[2022-05-19 22:40:55,940] {local_task_job.py:264} INFO - 0 downstream tasks scheduled from follow-on schedule check
