[2022-06-14 02:31:53,118] {taskinstance.py:1037} INFO - Dependencies all met for <TaskInstance: match_details_dag.daily_transform manual__2022-06-14T02:31:24.795440+00:00 [queued]>
[2022-06-14 02:31:53,127] {taskinstance.py:1037} INFO - Dependencies all met for <TaskInstance: match_details_dag.daily_transform manual__2022-06-14T02:31:24.795440+00:00 [queued]>
[2022-06-14 02:31:53,128] {taskinstance.py:1243} INFO - 
--------------------------------------------------------------------------------
[2022-06-14 02:31:53,128] {taskinstance.py:1244} INFO - Starting attempt 1 of 2
[2022-06-14 02:31:53,128] {taskinstance.py:1245} INFO - 
--------------------------------------------------------------------------------
[2022-06-14 02:31:53,139] {taskinstance.py:1264} INFO - Executing <Task(BashOperator): daily_transform> on 2022-06-14 02:31:24.795440+00:00
[2022-06-14 02:31:53,143] {standard_task_runner.py:52} INFO - Started process 97 to run task
[2022-06-14 02:31:53,146] {standard_task_runner.py:76} INFO - Running: ['***', 'tasks', 'run', 'match_details_dag', 'daily_transform', 'manual__2022-06-14T02:31:24.795440+00:00', '--job-id', '73', '--raw', '--subdir', 'DAGS_FOLDER/matchData_dag.py', '--cfg-path', '/tmp/tmpd9dfoic5', '--error-file', '/tmp/tmpp1w_tmc7']
[2022-06-14 02:31:53,147] {standard_task_runner.py:77} INFO - Job 73: Subtask daily_transform
[2022-06-14 02:31:53,188] {logging_mixin.py:109} INFO - Running <TaskInstance: match_details_dag.daily_transform manual__2022-06-14T02:31:24.795440+00:00 [running]> on host a1cebf1185bf
[2022-06-14 02:31:53,229] {taskinstance.py:1429} INFO - Exporting the following env vars:
AIRFLOW_CTX_DAG_OWNER=admin
AIRFLOW_CTX_DAG_ID=match_details_dag
AIRFLOW_CTX_TASK_ID=daily_transform
AIRFLOW_CTX_EXECUTION_DATE=2022-06-14T02:31:24.795440+00:00
AIRFLOW_CTX_DAG_RUN_ID=manual__2022-06-14T02:31:24.795440+00:00
[2022-06-14 02:31:53,230] {subprocess.py:62} INFO - Tmp dir root location: 
 /tmp
[2022-06-14 02:31:53,230] {subprocess.py:74} INFO - Running command: ['bash', '-c', 'cd /opt/***/dbt && dbt deps && dbt run --target dev']
[2022-06-14 02:31:53,240] {subprocess.py:85} INFO - Output:
[2022-06-14 02:31:55,903] {subprocess.py:89} INFO - 02:31:55  Running with dbt=1.1.0
[2022-06-14 02:31:56,367] {subprocess.py:89} INFO - 02:31:56  Installing dbt-labs/dbt_utils
[2022-06-14 02:31:56,929] {subprocess.py:89} INFO - 02:31:56    Installed from version 0.8.5
[2022-06-14 02:31:56,929] {subprocess.py:89} INFO - 02:31:56    Up to date!
[2022-06-14 02:32:00,897] {subprocess.py:89} INFO - 02:32:00  Running with dbt=1.1.0
[2022-06-14 02:32:00,930] {subprocess.py:89} INFO - 02:32:00  Unable to do partial parsing because config vars, config profile, or config target have changed
[2022-06-14 02:32:02,210] {subprocess.py:89} INFO - 02:32:02  Found 7 models, 14 tests, 0 snapshots, 0 analyses, 400 macros, 0 operations, 0 seed files, 7 sources, 0 exposures, 0 metrics
[2022-06-14 02:32:02,213] {subprocess.py:89} INFO - 02:32:02
[2022-06-14 02:32:02,554] {subprocess.py:89} INFO - 02:32:02  Encountered an error:
[2022-06-14 02:32:02,554] {subprocess.py:89} INFO - max_workers must be greater than 0
[2022-06-14 02:32:02,815] {subprocess.py:93} INFO - Command exited with return code 2
[2022-06-14 02:32:02,827] {taskinstance.py:1718} ERROR - Task failed with exception
Traceback (most recent call last):
  File "/home/airflow/.local/lib/python3.8/site-packages/airflow/models/taskinstance.py", line 1334, in _run_raw_task
    self._execute_task_with_callbacks(context)
  File "/home/airflow/.local/lib/python3.8/site-packages/airflow/models/taskinstance.py", line 1460, in _execute_task_with_callbacks
    result = self._execute_task(context, self.task)
  File "/home/airflow/.local/lib/python3.8/site-packages/airflow/models/taskinstance.py", line 1516, in _execute_task
    result = execute_callable(context=context)
  File "/home/airflow/.local/lib/python3.8/site-packages/airflow/operators/bash.py", line 187, in execute
    raise AirflowException(
airflow.exceptions.AirflowException: Bash command failed. The command returned a non-zero exit code 2.
[2022-06-14 02:32:02,832] {taskinstance.py:1272} INFO - Marking task as UP_FOR_RETRY. dag_id=match_details_dag, task_id=daily_transform, execution_date=20220614T023124, start_date=20220614T023153, end_date=20220614T023202
[2022-06-14 02:32:02,846] {standard_task_runner.py:89} ERROR - Failed to execute job 73 for task daily_transform
Traceback (most recent call last):
  File "/home/airflow/.local/lib/python3.8/site-packages/airflow/task/task_runner/standard_task_runner.py", line 85, in _start_by_fork
    args.func(args, dag=self.dag)
  File "/home/airflow/.local/lib/python3.8/site-packages/airflow/cli/cli_parser.py", line 48, in command
    return func(*args, **kwargs)
  File "/home/airflow/.local/lib/python3.8/site-packages/airflow/utils/cli.py", line 92, in wrapper
    return f(*args, **kwargs)
  File "/home/airflow/.local/lib/python3.8/site-packages/airflow/cli/commands/task_command.py", line 298, in task_run
    _run_task_by_selected_method(args, dag, ti)
  File "/home/airflow/.local/lib/python3.8/site-packages/airflow/cli/commands/task_command.py", line 107, in _run_task_by_selected_method
    _run_raw_task(args, ti)
  File "/home/airflow/.local/lib/python3.8/site-packages/airflow/cli/commands/task_command.py", line 180, in _run_raw_task
    ti._run_raw_task(
  File "/home/airflow/.local/lib/python3.8/site-packages/airflow/utils/session.py", line 70, in wrapper
    return func(*args, session=session, **kwargs)
  File "/home/airflow/.local/lib/python3.8/site-packages/airflow/models/taskinstance.py", line 1334, in _run_raw_task
    self._execute_task_with_callbacks(context)
  File "/home/airflow/.local/lib/python3.8/site-packages/airflow/models/taskinstance.py", line 1460, in _execute_task_with_callbacks
    result = self._execute_task(context, self.task)
  File "/home/airflow/.local/lib/python3.8/site-packages/airflow/models/taskinstance.py", line 1516, in _execute_task
    result = execute_callable(context=context)
  File "/home/airflow/.local/lib/python3.8/site-packages/airflow/operators/bash.py", line 187, in execute
    raise AirflowException(
airflow.exceptions.AirflowException: Bash command failed. The command returned a non-zero exit code 2.
[2022-06-14 02:32:02,880] {local_task_job.py:154} INFO - Task exited with return code 1
[2022-06-14 02:32:02,910] {local_task_job.py:264} INFO - 0 downstream tasks scheduled from follow-on schedule check
