[2022-05-19 22:36:06,652] {taskinstance.py:1037} INFO - Dependencies all met for <TaskInstance: league_of_legends_dag.paths.path_champions.staging_champions manual__2022-05-19T22:36:02.083363+00:00 [queued]>
[2022-05-19 22:36:06,665] {taskinstance.py:1037} INFO - Dependencies all met for <TaskInstance: league_of_legends_dag.paths.path_champions.staging_champions manual__2022-05-19T22:36:02.083363+00:00 [queued]>
[2022-05-19 22:36:06,665] {taskinstance.py:1243} INFO - 
--------------------------------------------------------------------------------
[2022-05-19 22:36:06,666] {taskinstance.py:1244} INFO - Starting attempt 1 of 2
[2022-05-19 22:36:06,666] {taskinstance.py:1245} INFO - 
--------------------------------------------------------------------------------
[2022-05-19 22:36:06,683] {taskinstance.py:1264} INFO - Executing <Task(riot_dataDragonToADLSOperator): paths.path_champions.staging_champions> on 2022-05-19 22:36:02.083363+00:00
[2022-05-19 22:36:06,690] {standard_task_runner.py:52} INFO - Started process 1256 to run task
[2022-05-19 22:36:06,693] {standard_task_runner.py:76} INFO - Running: ['***', 'tasks', 'run', 'league_of_legends_dag', 'paths.path_champions.staging_champions', 'manual__2022-05-19T22:36:02.083363+00:00', '--job-id', '276', '--raw', '--subdir', 'DAGS_FOLDER/dataDragon_dag.py', '--cfg-path', '/tmp/tmpho4w757n', '--error-file', '/tmp/tmppkrz01u6']
[2022-05-19 22:36:06,694] {standard_task_runner.py:77} INFO - Job 276: Subtask paths.path_champions.staging_champions
[2022-05-19 22:36:06,747] {logging_mixin.py:109} INFO - Running <TaskInstance: league_of_legends_dag.paths.path_champions.staging_champions manual__2022-05-19T22:36:02.083363+00:00 [running]> on host ca9a242fab95
[2022-05-19 22:36:06,797] {taskinstance.py:1429} INFO - Exporting the following env vars:
AIRFLOW_CTX_DAG_OWNER=admin
AIRFLOW_CTX_DAG_ID=league_of_legends_dag
AIRFLOW_CTX_TASK_ID=paths.path_champions.staging_champions
AIRFLOW_CTX_EXECUTION_DATE=2022-05-19T22:36:02.083363+00:00
AIRFLOW_CTX_DAG_RUN_ID=manual__2022-05-19T22:36:02.083363+00:00
[2022-05-19 22:36:06,797] {riot_datadragon_toADLS_Operator.py:55} INFO - StageToAzureLake not implemented yet
[2022-05-19 22:36:06,806] {taskinstance.py:1718} ERROR - Task failed with exception
Traceback (most recent call last):
  File "/home/airflow/.local/lib/python3.8/site-packages/airflow/models/taskinstance.py", line 1334, in _run_raw_task
    self._execute_task_with_callbacks(context)
  File "/home/airflow/.local/lib/python3.8/site-packages/airflow/models/taskinstance.py", line 1460, in _execute_task_with_callbacks
    result = self._execute_task(context, self.task)
  File "/home/airflow/.local/lib/python3.8/site-packages/airflow/models/taskinstance.py", line 1516, in _execute_task
    result = execute_callable(context=context)
  File "/opt/airflow/plugins/custom_operators/riot_datadragon_toADLS_Operator.py", line 56, in execute
    self.upload_to_azureLake()
  File "/opt/airflow/plugins/custom_operators/riot_datadragon_toADLS_Operator.py", line 61, in upload_to_azureLake
    wasb_hook = WasbHook(self.azure_conn_id)
  File "/home/airflow/.local/lib/python3.8/site-packages/airflow/providers/microsoft/azure/hooks/wasb.py", line 113, in __init__
    self.blob_service_client = self.get_conn()
  File "/home/airflow/.local/lib/python3.8/site-packages/airflow/providers/microsoft/azure/hooks/wasb.py", line 156, in get_conn
    return BlobServiceClient(
  File "/home/airflow/.local/lib/python3.8/site-packages/azure/storage/blob/_blob_service_client.py", line 134, in __init__
    super(BlobServiceClient, self).__init__(parsed_url, service='blob', credential=credential, **kwargs)
  File "/home/airflow/.local/lib/python3.8/site-packages/azure/storage/blob/_shared/base_client.py", line 89, in __init__
    self.credential = _format_shared_key_credential(self.account_name, credential)
  File "/home/airflow/.local/lib/python3.8/site-packages/azure/storage/blob/_shared/base_client.py", line 351, in _format_shared_key_credential
    raise ValueError("Unable to determine account name for shared key credential.")
ValueError: Unable to determine account name for shared key credential.
[2022-05-19 22:36:06,818] {taskinstance.py:1272} INFO - Marking task as UP_FOR_RETRY. dag_id=league_of_legends_dag, task_id=paths.path_champions.staging_champions, execution_date=20220519T223602, start_date=20220519T223606, end_date=20220519T223606
[2022-05-19 22:36:06,833] {standard_task_runner.py:89} ERROR - Failed to execute job 276 for task paths.path_champions.staging_champions
Traceback (most recent call last):
  File "/home/airflow/.local/lib/python3.8/site-packages/airflow/task/task_runner/standard_task_runner.py", line 85, in _start_by_fork
    args.func(args, dag=self.dag)
  File "/home/airflow/.local/lib/python3.8/site-packages/airflow/cli/cli_parser.py", line 48, in command
    return func(*args, **kwargs)
  File "/home/airflow/.local/lib/python3.8/site-packages/airflow/utils/cli.py", line 92, in wrapper
    return f(*args, **kwargs)
  File "/home/airflow/.local/lib/python3.8/site-packages/airflow/cli/commands/task_command.py", line 298, in task_run
    _run_task_by_selected_method(args, dag, ti)
  File "/home/airflow/.local/lib/python3.8/site-packages/airflow/cli/commands/task_command.py", line 107, in _run_task_by_selected_method
    _run_raw_task(args, ti)
  File "/home/airflow/.local/lib/python3.8/site-packages/airflow/cli/commands/task_command.py", line 180, in _run_raw_task
    ti._run_raw_task(
  File "/home/airflow/.local/lib/python3.8/site-packages/airflow/utils/session.py", line 70, in wrapper
    return func(*args, session=session, **kwargs)
  File "/home/airflow/.local/lib/python3.8/site-packages/airflow/models/taskinstance.py", line 1334, in _run_raw_task
    self._execute_task_with_callbacks(context)
  File "/home/airflow/.local/lib/python3.8/site-packages/airflow/models/taskinstance.py", line 1460, in _execute_task_with_callbacks
    result = self._execute_task(context, self.task)
  File "/home/airflow/.local/lib/python3.8/site-packages/airflow/models/taskinstance.py", line 1516, in _execute_task
    result = execute_callable(context=context)
  File "/opt/airflow/plugins/custom_operators/riot_datadragon_toADLS_Operator.py", line 56, in execute
    self.upload_to_azureLake()
  File "/opt/airflow/plugins/custom_operators/riot_datadragon_toADLS_Operator.py", line 61, in upload_to_azureLake
    wasb_hook = WasbHook(self.azure_conn_id)
  File "/home/airflow/.local/lib/python3.8/site-packages/airflow/providers/microsoft/azure/hooks/wasb.py", line 113, in __init__
    self.blob_service_client = self.get_conn()
  File "/home/airflow/.local/lib/python3.8/site-packages/airflow/providers/microsoft/azure/hooks/wasb.py", line 156, in get_conn
    return BlobServiceClient(
  File "/home/airflow/.local/lib/python3.8/site-packages/azure/storage/blob/_blob_service_client.py", line 134, in __init__
    super(BlobServiceClient, self).__init__(parsed_url, service='blob', credential=credential, **kwargs)
  File "/home/airflow/.local/lib/python3.8/site-packages/azure/storage/blob/_shared/base_client.py", line 89, in __init__
    self.credential = _format_shared_key_credential(self.account_name, credential)
  File "/home/airflow/.local/lib/python3.8/site-packages/azure/storage/blob/_shared/base_client.py", line 351, in _format_shared_key_credential
    raise ValueError("Unable to determine account name for shared key credential.")
ValueError: Unable to determine account name for shared key credential.
[2022-05-19 22:36:06,865] {local_task_job.py:154} INFO - Task exited with return code 1
[2022-05-19 22:36:06,897] {local_task_job.py:264} INFO - 0 downstream tasks scheduled from follow-on schedule check
