[2022-05-11 20:31:49,424] {taskinstance.py:1037} INFO - Dependencies all met for <TaskInstance: league_of_legends_dag.staging scheduled__2022-04-02T22:00:00+00:00 [queued]>
[2022-05-11 20:31:49,436] {taskinstance.py:1037} INFO - Dependencies all met for <TaskInstance: league_of_legends_dag.staging scheduled__2022-04-02T22:00:00+00:00 [queued]>
[2022-05-11 20:31:49,436] {taskinstance.py:1243} INFO - 
--------------------------------------------------------------------------------
[2022-05-11 20:31:49,436] {taskinstance.py:1244} INFO - Starting attempt 2 of 2
[2022-05-11 20:31:49,436] {taskinstance.py:1245} INFO - 
--------------------------------------------------------------------------------
[2022-05-11 20:31:49,451] {taskinstance.py:1264} INFO - Executing <Task(riotOperator): staging> on 2022-04-02 22:00:00+00:00
[2022-05-11 20:31:49,457] {standard_task_runner.py:52} INFO - Started process 8734 to run task
[2022-05-11 20:31:49,460] {standard_task_runner.py:76} INFO - Running: ['***', 'tasks', 'run', 'league_of_legends_dag', 'staging', 'scheduled__2022-04-02T22:00:00+00:00', '--job-id', '110', '--raw', '--subdir', 'DAGS_FOLDER/main_dag.py', '--cfg-path', '/tmp/tmpsxq9h2z9', '--error-file', '/tmp/tmpd8fj9cx8']
[2022-05-11 20:31:49,461] {standard_task_runner.py:77} INFO - Job 110: Subtask staging
[2022-05-11 20:31:49,521] {logging_mixin.py:109} INFO - Running <TaskInstance: league_of_legends_dag.staging scheduled__2022-04-02T22:00:00+00:00 [running]> on host c411fdaf6506
[2022-05-11 20:31:49,570] {taskinstance.py:1429} INFO - Exporting the following env vars:
AIRFLOW_CTX_DAG_OWNER=admin
AIRFLOW_CTX_DAG_ID=league_of_legends_dag
AIRFLOW_CTX_TASK_ID=staging
AIRFLOW_CTX_EXECUTION_DATE=2022-04-02T22:00:00+00:00
AIRFLOW_CTX_DAG_RUN_ID=scheduled__2022-04-02T22:00:00+00:00
[2022-05-11 20:31:49,570] {riot_operator.py:61} INFO - StageToAzureLake not implemented yet
[2022-05-11 20:31:49,582] {riot_operator.py:68} INFO - <bound method WasbHook.get_conn of <airflow.providers.microsoft.azure.hooks.wasb.WasbHook object at 0x7f119a991040>>
[2022-05-11 20:31:49,582] {riot_operator.py:69} INFO - Created Azure Connection
[2022-05-11 20:31:49,590] {riot_operator.py:72} INFO - Created Riot Connection
[2022-05-11 20:31:49,867] {taskinstance.py:1718} ERROR - Task failed with exception
Traceback (most recent call last):
  File "/home/airflow/.local/lib/python3.8/site-packages/riotwatcher/Handlers/ThrowOnErrorHandler.py", line 18, in after_request
    response.raise_for_status()
  File "/home/airflow/.local/lib/python3.8/site-packages/requests/models.py", line 960, in raise_for_status
    raise HTTPError(http_error_msg, response=self)
requests.exceptions.HTTPError: 403 Client Error: Forbidden for url: https://na1.api.riotgames.com/lol/summoner/v4/summoners/by-name/dild0wacker

During handling of the above exception, another exception occurred:

Traceback (most recent call last):
  File "/home/airflow/.local/lib/python3.8/site-packages/airflow/models/taskinstance.py", line 1334, in _run_raw_task
    self._execute_task_with_callbacks(context)
  File "/home/airflow/.local/lib/python3.8/site-packages/airflow/models/taskinstance.py", line 1460, in _execute_task_with_callbacks
    result = self._execute_task(context, self.task)
  File "/home/airflow/.local/lib/python3.8/site-packages/airflow/models/taskinstance.py", line 1516, in _execute_task
    result = execute_callable(context=context)
  File "/opt/airflow/plugins/custom_operators/riot_operator.py", line 62, in execute
    self.upload_to_azureLake()
  File "/opt/airflow/plugins/custom_operators/riot_operator.py", line 74, in upload_to_azureLake
    match_history = riot_hook.get_latest_match_history(
  File "/opt/airflow/plugins/custom_hooks/riot_hook.py", line 26, in get_latest_match_history
    me = self.lol_watcher.summoner.by_name(my_region, summoner_name)
  File "/home/airflow/.local/lib/python3.8/site-packages/riotwatcher/_apis/league_of_legends/SummonerApiV4.py", line 46, in by_name
    return self._request_endpoint(
  File "/home/airflow/.local/lib/python3.8/site-packages/riotwatcher/_apis/NamedEndpoint.py", line 36, in _request_endpoint
    return self._base_api.raw_request(
  File "/home/airflow/.local/lib/python3.8/site-packages/riotwatcher/_apis/BaseApi.py", line 51, in raw_request
    mod = handler.after_request(
  File "/home/airflow/.local/lib/python3.8/site-packages/riotwatcher/Handlers/ThrowOnErrorHandler.py", line 20, in after_request
    raise ApiError(*err.args, request=err.request, response=err.response)
requests.exceptions.HTTPError: 403 Client Error: Forbidden for url: https://na1.api.riotgames.com/lol/summoner/v4/summoners/by-name/dild0wacker
[2022-05-11 20:31:49,966] {taskinstance.py:1272} INFO - Marking task as FAILED. dag_id=league_of_legends_dag, task_id=staging, execution_date=20220402T220000, start_date=20220511T203149, end_date=20220511T203149
[2022-05-11 20:31:50,000] {standard_task_runner.py:89} ERROR - Failed to execute job 110 for task staging
Traceback (most recent call last):
  File "/home/airflow/.local/lib/python3.8/site-packages/riotwatcher/Handlers/ThrowOnErrorHandler.py", line 18, in after_request
    response.raise_for_status()
  File "/home/airflow/.local/lib/python3.8/site-packages/requests/models.py", line 960, in raise_for_status
    raise HTTPError(http_error_msg, response=self)
requests.exceptions.HTTPError: 403 Client Error: Forbidden for url: https://na1.api.riotgames.com/lol/summoner/v4/summoners/by-name/dild0wacker

During handling of the above exception, another exception occurred:

Traceback (most recent call last):
  File "/home/airflow/.local/lib/python3.8/site-packages/airflow/task/task_runner/standard_task_runner.py", line 85, in _start_by_fork
    args.func(args, dag=self.dag)
  File "/home/airflow/.local/lib/python3.8/site-packages/airflow/cli/cli_parser.py", line 48, in command
    return func(*args, **kwargs)
  File "/home/airflow/.local/lib/python3.8/site-packages/airflow/utils/cli.py", line 92, in wrapper
    return f(*args, **kwargs)
  File "/home/airflow/.local/lib/python3.8/site-packages/airflow/cli/commands/task_command.py", line 298, in task_run
    _run_task_by_selected_method(args, dag, ti)
  File "/home/airflow/.local/lib/python3.8/site-packages/airflow/cli/commands/task_command.py", line 107, in _run_task_by_selected_method
    _run_raw_task(args, ti)
  File "/home/airflow/.local/lib/python3.8/site-packages/airflow/cli/commands/task_command.py", line 180, in _run_raw_task
    ti._run_raw_task(
  File "/home/airflow/.local/lib/python3.8/site-packages/airflow/utils/session.py", line 70, in wrapper
    return func(*args, session=session, **kwargs)
  File "/home/airflow/.local/lib/python3.8/site-packages/airflow/models/taskinstance.py", line 1334, in _run_raw_task
    self._execute_task_with_callbacks(context)
  File "/home/airflow/.local/lib/python3.8/site-packages/airflow/models/taskinstance.py", line 1460, in _execute_task_with_callbacks
    result = self._execute_task(context, self.task)
  File "/home/airflow/.local/lib/python3.8/site-packages/airflow/models/taskinstance.py", line 1516, in _execute_task
    result = execute_callable(context=context)
  File "/opt/airflow/plugins/custom_operators/riot_operator.py", line 62, in execute
    self.upload_to_azureLake()
  File "/opt/airflow/plugins/custom_operators/riot_operator.py", line 74, in upload_to_azureLake
    match_history = riot_hook.get_latest_match_history(
  File "/opt/airflow/plugins/custom_hooks/riot_hook.py", line 26, in get_latest_match_history
    me = self.lol_watcher.summoner.by_name(my_region, summoner_name)
  File "/home/airflow/.local/lib/python3.8/site-packages/riotwatcher/_apis/league_of_legends/SummonerApiV4.py", line 46, in by_name
    return self._request_endpoint(
  File "/home/airflow/.local/lib/python3.8/site-packages/riotwatcher/_apis/NamedEndpoint.py", line 36, in _request_endpoint
    return self._base_api.raw_request(
  File "/home/airflow/.local/lib/python3.8/site-packages/riotwatcher/_apis/BaseApi.py", line 51, in raw_request
    mod = handler.after_request(
  File "/home/airflow/.local/lib/python3.8/site-packages/riotwatcher/Handlers/ThrowOnErrorHandler.py", line 20, in after_request
    raise ApiError(*err.args, request=err.request, response=err.response)
requests.exceptions.HTTPError: 403 Client Error: Forbidden for url: https://na1.api.riotgames.com/lol/summoner/v4/summoners/by-name/dild0wacker
[2022-05-11 20:31:50,034] {local_task_job.py:154} INFO - Task exited with return code 1
[2022-05-11 20:31:50,067] {local_task_job.py:264} INFO - 0 downstream tasks scheduled from follow-on schedule check
