[2022-06-10 01:20:44,613] {taskinstance.py:1037} INFO - Dependencies all met for <TaskInstance: match_details_dag.daily_transform scheduled__2022-05-23T00:00:00+00:00 [None]>
[2022-06-10 01:20:44,622] {taskinstance.py:1037} INFO - Dependencies all met for <TaskInstance: match_details_dag.daily_transform scheduled__2022-05-23T00:00:00+00:00 [None]>
[2022-06-10 01:20:44,622] {taskinstance.py:1243} INFO - 
--------------------------------------------------------------------------------
[2022-06-10 01:20:44,623] {taskinstance.py:1244} INFO - Starting attempt 12 of 13
[2022-06-10 01:20:44,623] {taskinstance.py:1245} INFO - 
--------------------------------------------------------------------------------
[2022-06-10 01:20:44,634] {taskinstance.py:1264} INFO - Executing <Task(BashOperator): daily_transform> on 2022-05-23 00:00:00+00:00
[2022-06-10 01:20:44,638] {standard_task_runner.py:52} INFO - Started process 64 to run task
[2022-06-10 01:20:44,642] {standard_task_runner.py:76} INFO - Running: ['***', 'tasks', 'run', 'match_details_dag', 'daily_transform', 'scheduled__2022-05-23T00:00:00+00:00', '--job-id', '24', '--pool', 'default_pool', '--raw', '--subdir', 'DAGS_FOLDER/matchData_dag.py', '--cfg-path', '/tmp/tmpce79b5oe', '--error-file', '/tmp/tmpz7kfxeui']
[2022-06-10 01:20:44,642] {standard_task_runner.py:77} INFO - Job 24: Subtask daily_transform
[2022-06-10 01:20:44,686] {logging_mixin.py:109} INFO - Running <TaskInstance: match_details_dag.daily_transform scheduled__2022-05-23T00:00:00+00:00 [running]> on host 47c01c51522a
[2022-06-10 01:20:44,728] {taskinstance.py:1429} INFO - Exporting the following env vars:
AIRFLOW_CTX_DAG_OWNER=admin
AIRFLOW_CTX_DAG_ID=match_details_dag
AIRFLOW_CTX_TASK_ID=daily_transform
AIRFLOW_CTX_EXECUTION_DATE=2022-05-23T00:00:00+00:00
AIRFLOW_CTX_DAG_RUN_ID=scheduled__2022-05-23T00:00:00+00:00
[2022-06-10 01:20:44,728] {subprocess.py:62} INFO - Tmp dir root location: 
 /tmp
[2022-06-10 01:20:44,729] {subprocess.py:74} INFO - Running command: ['bash', '-c', 'cd /opt/***/dbt && dbt deps && dbt run --project-dir /opt/***/dbt --profiles-dir /opt/***/dbt --target dev']
[2022-06-10 01:20:44,737] {subprocess.py:85} INFO - Output:
[2022-06-10 01:20:47,837] {subprocess.py:89} INFO - 01:20:47  Running with dbt=1.1.0
[2022-06-10 01:20:48,627] {subprocess.py:89} INFO - 01:20:48  Installing dbt-labs/dbt_utils
[2022-06-10 01:20:49,227] {subprocess.py:89} INFO - 01:20:49    Installed from version 0.8.5
[2022-06-10 01:20:49,228] {subprocess.py:89} INFO - 01:20:49    Up to date!
[2022-06-10 01:20:53,831] {subprocess.py:89} INFO - 01:20:53  Running with dbt=1.1.0
[2022-06-10 01:20:53,861] {subprocess.py:89} INFO - 01:20:53  Partial parse save file not found. Starting full parse.
[2022-06-10 01:20:55,544] {subprocess.py:89} INFO - 01:20:55  Encountered an error:
[2022-06-10 01:20:55,544] {subprocess.py:89} INFO - [Errno 13] Permission denied: 'target/partial_parse.msgpack'
[2022-06-10 01:20:55,915] {subprocess.py:93} INFO - Command exited with return code 2
[2022-06-10 01:20:55,935] {taskinstance.py:1718} ERROR - Task failed with exception
Traceback (most recent call last):
  File "/home/airflow/.local/lib/python3.8/site-packages/airflow/models/taskinstance.py", line 1334, in _run_raw_task
    self._execute_task_with_callbacks(context)
  File "/home/airflow/.local/lib/python3.8/site-packages/airflow/models/taskinstance.py", line 1460, in _execute_task_with_callbacks
    result = self._execute_task(context, self.task)
  File "/home/airflow/.local/lib/python3.8/site-packages/airflow/models/taskinstance.py", line 1516, in _execute_task
    result = execute_callable(context=context)
  File "/home/airflow/.local/lib/python3.8/site-packages/airflow/operators/bash.py", line 187, in execute
    raise AirflowException(
airflow.exceptions.AirflowException: Bash command failed. The command returned a non-zero exit code 2.
[2022-06-10 01:20:55,941] {taskinstance.py:1272} INFO - Marking task as UP_FOR_RETRY. dag_id=match_details_dag, task_id=daily_transform, execution_date=20220523T000000, start_date=20220610T012044, end_date=20220610T012055
[2022-06-10 01:20:55,953] {standard_task_runner.py:89} ERROR - Failed to execute job 24 for task daily_transform
Traceback (most recent call last):
  File "/home/airflow/.local/lib/python3.8/site-packages/airflow/task/task_runner/standard_task_runner.py", line 85, in _start_by_fork
    args.func(args, dag=self.dag)
  File "/home/airflow/.local/lib/python3.8/site-packages/airflow/cli/cli_parser.py", line 48, in command
    return func(*args, **kwargs)
  File "/home/airflow/.local/lib/python3.8/site-packages/airflow/utils/cli.py", line 92, in wrapper
    return f(*args, **kwargs)
  File "/home/airflow/.local/lib/python3.8/site-packages/airflow/cli/commands/task_command.py", line 298, in task_run
    _run_task_by_selected_method(args, dag, ti)
  File "/home/airflow/.local/lib/python3.8/site-packages/airflow/cli/commands/task_command.py", line 107, in _run_task_by_selected_method
    _run_raw_task(args, ti)
  File "/home/airflow/.local/lib/python3.8/site-packages/airflow/cli/commands/task_command.py", line 180, in _run_raw_task
    ti._run_raw_task(
  File "/home/airflow/.local/lib/python3.8/site-packages/airflow/utils/session.py", line 70, in wrapper
    return func(*args, session=session, **kwargs)
  File "/home/airflow/.local/lib/python3.8/site-packages/airflow/models/taskinstance.py", line 1334, in _run_raw_task
    self._execute_task_with_callbacks(context)
  File "/home/airflow/.local/lib/python3.8/site-packages/airflow/models/taskinstance.py", line 1460, in _execute_task_with_callbacks
    result = self._execute_task(context, self.task)
  File "/home/airflow/.local/lib/python3.8/site-packages/airflow/models/taskinstance.py", line 1516, in _execute_task
    result = execute_callable(context=context)
  File "/home/airflow/.local/lib/python3.8/site-packages/airflow/operators/bash.py", line 187, in execute
    raise AirflowException(
airflow.exceptions.AirflowException: Bash command failed. The command returned a non-zero exit code 2.
[2022-06-10 01:20:55,982] {local_task_job.py:154} INFO - Task exited with return code 1
[2022-06-10 01:20:56,018] {local_task_job.py:264} INFO - 0 downstream tasks scheduled from follow-on schedule check
