[2022-06-07 21:43:38,219] {taskinstance.py:1037} INFO - Dependencies all met for <TaskInstance: match_details_dag.daily_transform scheduled__2022-05-23T00:00:00+00:00 [None]>
[2022-06-07 21:43:38,229] {taskinstance.py:1037} INFO - Dependencies all met for <TaskInstance: match_details_dag.daily_transform scheduled__2022-05-23T00:00:00+00:00 [None]>
[2022-06-07 21:43:38,230] {taskinstance.py:1243} INFO - 
--------------------------------------------------------------------------------
[2022-06-07 21:43:38,230] {taskinstance.py:1244} INFO - Starting attempt 5 of 6
[2022-06-07 21:43:38,230] {taskinstance.py:1245} INFO - 
--------------------------------------------------------------------------------
[2022-06-07 21:43:38,240] {taskinstance.py:1264} INFO - Executing <Task(BashOperator): daily_transform> on 2022-05-23 00:00:00+00:00
[2022-06-07 21:43:38,244] {standard_task_runner.py:52} INFO - Started process 109 to run task
[2022-06-07 21:43:38,246] {standard_task_runner.py:76} INFO - Running: ['***', 'tasks', 'run', 'match_details_dag', 'daily_transform', 'scheduled__2022-05-23T00:00:00+00:00', '--job-id', '13', '--pool', 'default_pool', '--raw', '--subdir', 'DAGS_FOLDER/matchData_dag.py', '--cfg-path', '/tmp/tmpaz8_ovw9', '--error-file', '/tmp/tmp6fv3b91s']
[2022-06-07 21:43:38,246] {standard_task_runner.py:77} INFO - Job 13: Subtask daily_transform
[2022-06-07 21:43:38,286] {logging_mixin.py:109} INFO - Running <TaskInstance: match_details_dag.daily_transform scheduled__2022-05-23T00:00:00+00:00 [running]> on host 3a2d88aef85a
[2022-06-07 21:43:38,327] {taskinstance.py:1429} INFO - Exporting the following env vars:
AIRFLOW_CTX_DAG_OWNER=admin
AIRFLOW_CTX_DAG_ID=match_details_dag
AIRFLOW_CTX_TASK_ID=daily_transform
AIRFLOW_CTX_EXECUTION_DATE=2022-05-23T00:00:00+00:00
AIRFLOW_CTX_DAG_RUN_ID=scheduled__2022-05-23T00:00:00+00:00
[2022-06-07 21:43:38,327] {subprocess.py:62} INFO - Tmp dir root location: 
 /tmp
[2022-06-07 21:43:38,328] {subprocess.py:74} INFO - Running command: ['bash', '-c', 'cd /opt/***/dbt && dbt deps && dbt run --project-dir /opt/***/dbt --profiles-dir /opt/***/dbt --target dev']
[2022-06-07 21:43:38,336] {subprocess.py:85} INFO - Output:
[2022-06-07 21:43:41,354] {subprocess.py:89} INFO - 21:43:41  Running with dbt=1.1.0
[2022-06-07 21:43:42,226] {subprocess.py:89} INFO - 21:43:42  Installing dbt-labs/dbt_utils
[2022-06-07 21:43:42,781] {subprocess.py:89} INFO - 21:43:42    Installed from version 0.8.0
[2022-06-07 21:43:42,782] {subprocess.py:89} INFO - 21:43:42    Updated version available: 0.8.5
[2022-06-07 21:43:42,782] {subprocess.py:89} INFO - 21:43:42
[2022-06-07 21:43:42,783] {subprocess.py:89} INFO - 21:43:42  Updates available for packages: ['dbt-labs/dbt_utils']
[2022-06-07 21:43:42,783] {subprocess.py:89} INFO - Update your versions in packages.yml, then run dbt deps
[2022-06-07 21:43:47,542] {subprocess.py:89} INFO - 21:43:47  Running with dbt=1.1.0
[2022-06-07 21:43:47,565] {subprocess.py:89} INFO - 21:43:47  Partial parse save file not found. Starting full parse.
[2022-06-07 21:43:48,641] {subprocess.py:89} INFO - 21:43:48  Encountered an error:
[2022-06-07 21:43:48,641] {subprocess.py:89} INFO - Compilation Error in model stg_items (models/staging_datadragon/stg_items.sql)
[2022-06-07 21:43:48,641] {subprocess.py:89} INFO -   Encountered unknown tag 'SET'.
[2022-06-07 21:43:48,641] {subprocess.py:89} INFO -     line 11
[2022-06-07 21:43:48,641] {subprocess.py:89} INFO -       {% SET pivot_cols = dbt_utils.get_column_values(table=pivot_source, column='KEY') %}
[2022-06-07 21:43:48,919] {subprocess.py:93} INFO - Command exited with return code 2
[2022-06-07 21:43:48,930] {taskinstance.py:1718} ERROR - Task failed with exception
Traceback (most recent call last):
  File "/home/airflow/.local/lib/python3.8/site-packages/airflow/models/taskinstance.py", line 1334, in _run_raw_task
    self._execute_task_with_callbacks(context)
  File "/home/airflow/.local/lib/python3.8/site-packages/airflow/models/taskinstance.py", line 1460, in _execute_task_with_callbacks
    result = self._execute_task(context, self.task)
  File "/home/airflow/.local/lib/python3.8/site-packages/airflow/models/taskinstance.py", line 1516, in _execute_task
    result = execute_callable(context=context)
  File "/home/airflow/.local/lib/python3.8/site-packages/airflow/operators/bash.py", line 187, in execute
    raise AirflowException(
airflow.exceptions.AirflowException: Bash command failed. The command returned a non-zero exit code 2.
[2022-06-07 21:43:48,935] {taskinstance.py:1272} INFO - Marking task as UP_FOR_RETRY. dag_id=match_details_dag, task_id=daily_transform, execution_date=20220523T000000, start_date=20220607T214338, end_date=20220607T214348
[2022-06-07 21:43:48,946] {standard_task_runner.py:89} ERROR - Failed to execute job 13 for task daily_transform
Traceback (most recent call last):
  File "/home/airflow/.local/lib/python3.8/site-packages/airflow/task/task_runner/standard_task_runner.py", line 85, in _start_by_fork
    args.func(args, dag=self.dag)
  File "/home/airflow/.local/lib/python3.8/site-packages/airflow/cli/cli_parser.py", line 48, in command
    return func(*args, **kwargs)
  File "/home/airflow/.local/lib/python3.8/site-packages/airflow/utils/cli.py", line 92, in wrapper
    return f(*args, **kwargs)
  File "/home/airflow/.local/lib/python3.8/site-packages/airflow/cli/commands/task_command.py", line 298, in task_run
    _run_task_by_selected_method(args, dag, ti)
  File "/home/airflow/.local/lib/python3.8/site-packages/airflow/cli/commands/task_command.py", line 107, in _run_task_by_selected_method
    _run_raw_task(args, ti)
  File "/home/airflow/.local/lib/python3.8/site-packages/airflow/cli/commands/task_command.py", line 180, in _run_raw_task
    ti._run_raw_task(
  File "/home/airflow/.local/lib/python3.8/site-packages/airflow/utils/session.py", line 70, in wrapper
    return func(*args, session=session, **kwargs)
  File "/home/airflow/.local/lib/python3.8/site-packages/airflow/models/taskinstance.py", line 1334, in _run_raw_task
    self._execute_task_with_callbacks(context)
  File "/home/airflow/.local/lib/python3.8/site-packages/airflow/models/taskinstance.py", line 1460, in _execute_task_with_callbacks
    result = self._execute_task(context, self.task)
  File "/home/airflow/.local/lib/python3.8/site-packages/airflow/models/taskinstance.py", line 1516, in _execute_task
    result = execute_callable(context=context)
  File "/home/airflow/.local/lib/python3.8/site-packages/airflow/operators/bash.py", line 187, in execute
    raise AirflowException(
airflow.exceptions.AirflowException: Bash command failed. The command returned a non-zero exit code 2.
[2022-06-07 21:43:48,973] {local_task_job.py:154} INFO - Task exited with return code 1
[2022-06-07 21:43:48,999] {local_task_job.py:264} INFO - 0 downstream tasks scheduled from follow-on schedule check
[2022-06-14 18:07:34,666] {taskinstance.py:1037} INFO - Dependencies all met for <TaskInstance: match_details_dag.daily_transform scheduled__2022-05-23T00:00:00+00:00 [None]>
[2022-06-14 18:07:34,676] {taskinstance.py:1037} INFO - Dependencies all met for <TaskInstance: match_details_dag.daily_transform scheduled__2022-05-23T00:00:00+00:00 [None]>
[2022-06-14 18:07:34,676] {taskinstance.py:1243} INFO - 
--------------------------------------------------------------------------------
[2022-06-14 18:07:34,676] {taskinstance.py:1244} INFO - Starting attempt 5 of 6
[2022-06-14 18:07:34,677] {taskinstance.py:1245} INFO - 
--------------------------------------------------------------------------------
[2022-06-14 18:07:34,688] {taskinstance.py:1264} INFO - Executing <Task(BashOperator): daily_transform> on 2022-05-23 00:00:00+00:00
[2022-06-14 18:07:34,693] {standard_task_runner.py:52} INFO - Started process 65 to run task
[2022-06-14 18:07:34,695] {standard_task_runner.py:76} INFO - Running: ['***', 'tasks', 'run', 'match_details_dag', 'daily_transform', 'scheduled__2022-05-23T00:00:00+00:00', '--job-id', '95', '--pool', 'default_pool', '--raw', '--subdir', 'DAGS_FOLDER/matchData_dag.py', '--cfg-path', '/tmp/tmp764uioc6', '--error-file', '/tmp/tmpy3e52afe']
[2022-06-14 18:07:34,696] {standard_task_runner.py:77} INFO - Job 95: Subtask daily_transform
[2022-06-14 18:07:34,750] {logging_mixin.py:109} INFO - Running <TaskInstance: match_details_dag.daily_transform scheduled__2022-05-23T00:00:00+00:00 [running]> on host d9bf2c5affbd
[2022-06-14 18:07:34,796] {taskinstance.py:1429} INFO - Exporting the following env vars:
AIRFLOW_CTX_DAG_OWNER=admin
AIRFLOW_CTX_DAG_ID=match_details_dag
AIRFLOW_CTX_TASK_ID=daily_transform
AIRFLOW_CTX_EXECUTION_DATE=2022-05-23T00:00:00+00:00
AIRFLOW_CTX_DAG_RUN_ID=scheduled__2022-05-23T00:00:00+00:00
[2022-06-14 18:07:34,797] {subprocess.py:62} INFO - Tmp dir root location: 
 /tmp
[2022-06-14 18:07:34,797] {subprocess.py:74} INFO - Running command: ['bash', '-c', 'cd /opt/***/dbt && dbt deps && dbt run --target dev']
[2022-06-14 18:07:34,806] {subprocess.py:85} INFO - Output:
[2022-06-14 18:07:37,799] {subprocess.py:89} INFO - 18:07:37  Running with dbt=1.1.0
[2022-06-14 18:07:38,527] {subprocess.py:89} INFO - 18:07:38  Installing dbt-labs/dbt_utils
[2022-06-14 18:07:39,085] {subprocess.py:89} INFO - 18:07:39    Installed from version 0.8.5
[2022-06-14 18:07:39,085] {subprocess.py:89} INFO - 18:07:39    Up to date!
[2022-06-14 18:07:42,993] {subprocess.py:89} INFO - 18:07:42  Running with dbt=1.1.0
[2022-06-14 18:07:43,067] {subprocess.py:89} INFO - 18:07:43  Unable to do partial parsing because config vars, config profile, or config target have changed
[2022-06-14 18:07:43,070] {subprocess.py:89} INFO - 18:07:43  Unable to do partial parsing because a project config has changed
[2022-06-14 18:07:43,435] {subprocess.py:89} INFO - 18:07:43  Encountered an error:
[2022-06-14 18:07:43,435] {subprocess.py:89} INFO - Parsing Error
[2022-06-14 18:07:43,436] {subprocess.py:89} INFO -   Error reading leagueoflegendsdbt: warehouse/schema.yml - Runtime Error
[2022-06-14 18:07:43,436] {subprocess.py:89} INFO -     Syntax error near line 20
[2022-06-14 18:07:43,436] {subprocess.py:89} INFO -     ------------------------------
[2022-06-14 18:07:43,436] {subprocess.py:89} INFO -     17 |
[2022-06-14 18:07:43,436] {subprocess.py:89} INFO -     18 | models:
[2022-06-14 18:07:43,436] {subprocess.py:89} INFO -     19 | +incremental_strategy: "merge"
[2022-06-14 18:07:43,436] {subprocess.py:89} INFO -     20 |   - name: final_match_details
[2022-06-14 18:07:43,436] {subprocess.py:89} INFO -     21 |     columns:
[2022-06-14 18:07:43,436] {subprocess.py:89} INFO -     22 |       - name: match_id
[2022-06-14 18:07:43,437] {subprocess.py:89} INFO -     23 |         tests:
[2022-06-14 18:07:43,437] {subprocess.py:89} INFO - 
[2022-06-14 18:07:43,437] {subprocess.py:89} INFO -     Raw Error:
[2022-06-14 18:07:43,437] {subprocess.py:89} INFO -     ------------------------------
[2022-06-14 18:07:43,437] {subprocess.py:89} INFO -     while parsing a block mapping
[2022-06-14 18:07:43,437] {subprocess.py:89} INFO -       in "<unicode string>", line 1, column 1
[2022-06-14 18:07:43,437] {subprocess.py:89} INFO -     did not find expected key
[2022-06-14 18:07:43,437] {subprocess.py:89} INFO -       in "<unicode string>", line 20, column 3
[2022-06-14 18:07:43,712] {subprocess.py:93} INFO - Command exited with return code 2
[2022-06-14 18:07:43,723] {taskinstance.py:1718} ERROR - Task failed with exception
Traceback (most recent call last):
  File "/home/airflow/.local/lib/python3.8/site-packages/airflow/models/taskinstance.py", line 1334, in _run_raw_task
    self._execute_task_with_callbacks(context)
  File "/home/airflow/.local/lib/python3.8/site-packages/airflow/models/taskinstance.py", line 1460, in _execute_task_with_callbacks
    result = self._execute_task(context, self.task)
  File "/home/airflow/.local/lib/python3.8/site-packages/airflow/models/taskinstance.py", line 1516, in _execute_task
    result = execute_callable(context=context)
  File "/home/airflow/.local/lib/python3.8/site-packages/airflow/operators/bash.py", line 187, in execute
    raise AirflowException(
airflow.exceptions.AirflowException: Bash command failed. The command returned a non-zero exit code 2.
[2022-06-14 18:07:43,728] {taskinstance.py:1272} INFO - Marking task as UP_FOR_RETRY. dag_id=match_details_dag, task_id=daily_transform, execution_date=20220523T000000, start_date=20220614T180734, end_date=20220614T180743
[2022-06-14 18:07:43,740] {standard_task_runner.py:89} ERROR - Failed to execute job 95 for task daily_transform
Traceback (most recent call last):
  File "/home/airflow/.local/lib/python3.8/site-packages/airflow/task/task_runner/standard_task_runner.py", line 85, in _start_by_fork
    args.func(args, dag=self.dag)
  File "/home/airflow/.local/lib/python3.8/site-packages/airflow/cli/cli_parser.py", line 48, in command
    return func(*args, **kwargs)
  File "/home/airflow/.local/lib/python3.8/site-packages/airflow/utils/cli.py", line 92, in wrapper
    return f(*args, **kwargs)
  File "/home/airflow/.local/lib/python3.8/site-packages/airflow/cli/commands/task_command.py", line 298, in task_run
    _run_task_by_selected_method(args, dag, ti)
  File "/home/airflow/.local/lib/python3.8/site-packages/airflow/cli/commands/task_command.py", line 107, in _run_task_by_selected_method
    _run_raw_task(args, ti)
  File "/home/airflow/.local/lib/python3.8/site-packages/airflow/cli/commands/task_command.py", line 180, in _run_raw_task
    ti._run_raw_task(
  File "/home/airflow/.local/lib/python3.8/site-packages/airflow/utils/session.py", line 70, in wrapper
    return func(*args, session=session, **kwargs)
  File "/home/airflow/.local/lib/python3.8/site-packages/airflow/models/taskinstance.py", line 1334, in _run_raw_task
    self._execute_task_with_callbacks(context)
  File "/home/airflow/.local/lib/python3.8/site-packages/airflow/models/taskinstance.py", line 1460, in _execute_task_with_callbacks
    result = self._execute_task(context, self.task)
  File "/home/airflow/.local/lib/python3.8/site-packages/airflow/models/taskinstance.py", line 1516, in _execute_task
    result = execute_callable(context=context)
  File "/home/airflow/.local/lib/python3.8/site-packages/airflow/operators/bash.py", line 187, in execute
    raise AirflowException(
airflow.exceptions.AirflowException: Bash command failed. The command returned a non-zero exit code 2.
[2022-06-14 18:07:43,748] {local_task_job.py:154} INFO - Task exited with return code 1
[2022-06-14 18:07:43,779] {local_task_job.py:264} INFO - 0 downstream tasks scheduled from follow-on schedule check
