[2022-06-10 00:54:54,510] {taskinstance.py:1037} INFO - Dependencies all met for <TaskInstance: match_details_dag.daily_transform scheduled__2022-05-23T00:00:00+00:00 [None]>
[2022-06-10 00:54:54,519] {taskinstance.py:1037} INFO - Dependencies all met for <TaskInstance: match_details_dag.daily_transform scheduled__2022-05-23T00:00:00+00:00 [None]>
[2022-06-10 00:54:54,519] {taskinstance.py:1243} INFO - 
--------------------------------------------------------------------------------
[2022-06-10 00:54:54,519] {taskinstance.py:1244} INFO - Starting attempt 9 of 10
[2022-06-10 00:54:54,519] {taskinstance.py:1245} INFO - 
--------------------------------------------------------------------------------
[2022-06-10 00:54:54,530] {taskinstance.py:1264} INFO - Executing <Task(BashOperator): daily_transform> on 2022-05-23 00:00:00+00:00
[2022-06-10 00:54:54,534] {standard_task_runner.py:52} INFO - Started process 184 to run task
[2022-06-10 00:54:54,537] {standard_task_runner.py:76} INFO - Running: ['***', 'tasks', 'run', 'match_details_dag', 'daily_transform', 'scheduled__2022-05-23T00:00:00+00:00', '--job-id', '18', '--pool', 'default_pool', '--raw', '--subdir', 'DAGS_FOLDER/matchData_dag.py', '--cfg-path', '/tmp/tmpl8xnp6me', '--error-file', '/tmp/tmpq9jcvgqw']
[2022-06-10 00:54:54,537] {standard_task_runner.py:77} INFO - Job 18: Subtask daily_transform
[2022-06-10 00:54:54,582] {logging_mixin.py:109} INFO - Running <TaskInstance: match_details_dag.daily_transform scheduled__2022-05-23T00:00:00+00:00 [running]> on host 3a2d88aef85a
[2022-06-10 00:54:54,621] {taskinstance.py:1429} INFO - Exporting the following env vars:
AIRFLOW_CTX_DAG_OWNER=admin
AIRFLOW_CTX_DAG_ID=match_details_dag
AIRFLOW_CTX_TASK_ID=daily_transform
AIRFLOW_CTX_EXECUTION_DATE=2022-05-23T00:00:00+00:00
AIRFLOW_CTX_DAG_RUN_ID=scheduled__2022-05-23T00:00:00+00:00
[2022-06-10 00:54:54,622] {subprocess.py:62} INFO - Tmp dir root location: 
 /tmp
[2022-06-10 00:54:54,622] {subprocess.py:74} INFO - Running command: ['bash', '-c', 'cd /opt/***/dbt && dbt deps && dbt run --project-dir /opt/***/dbt --profiles-dir /opt/***/dbt --target dev']
[2022-06-10 00:54:54,632] {subprocess.py:85} INFO - Output:
[2022-06-10 00:54:58,545] {subprocess.py:89} INFO - 00:54:58  Running with dbt=1.1.0
[2022-06-10 00:54:59,052] {subprocess.py:89} INFO - 00:54:59  Installing dbt-labs/dbt_utils
[2022-06-10 00:54:59,666] {subprocess.py:89} INFO - 00:54:59    Installed from version 0.8.5
[2022-06-10 00:54:59,667] {subprocess.py:89} INFO - 00:54:59    Up to date!
[2022-06-10 00:55:04,883] {subprocess.py:89} INFO - 00:55:04  Running with dbt=1.1.0
[2022-06-10 00:55:04,907] {subprocess.py:89} INFO - 00:55:04  Partial parse save file not found. Starting full parse.
[2022-06-10 00:55:06,544] {subprocess.py:89} INFO - 00:55:06  Encountered an error:
[2022-06-10 00:55:06,545] {subprocess.py:89} INFO - [Errno 13] Permission denied: 'target'
[2022-06-10 00:55:06,835] {subprocess.py:93} INFO - Command exited with return code 2
[2022-06-10 00:55:06,847] {taskinstance.py:1718} ERROR - Task failed with exception
Traceback (most recent call last):
  File "/home/airflow/.local/lib/python3.8/site-packages/airflow/models/taskinstance.py", line 1334, in _run_raw_task
    self._execute_task_with_callbacks(context)
  File "/home/airflow/.local/lib/python3.8/site-packages/airflow/models/taskinstance.py", line 1460, in _execute_task_with_callbacks
    result = self._execute_task(context, self.task)
  File "/home/airflow/.local/lib/python3.8/site-packages/airflow/models/taskinstance.py", line 1516, in _execute_task
    result = execute_callable(context=context)
  File "/home/airflow/.local/lib/python3.8/site-packages/airflow/operators/bash.py", line 187, in execute
    raise AirflowException(
airflow.exceptions.AirflowException: Bash command failed. The command returned a non-zero exit code 2.
[2022-06-10 00:55:06,852] {taskinstance.py:1272} INFO - Marking task as UP_FOR_RETRY. dag_id=match_details_dag, task_id=daily_transform, execution_date=20220523T000000, start_date=20220610T005454, end_date=20220610T005506
[2022-06-10 00:55:06,864] {standard_task_runner.py:89} ERROR - Failed to execute job 18 for task daily_transform
Traceback (most recent call last):
  File "/home/airflow/.local/lib/python3.8/site-packages/airflow/task/task_runner/standard_task_runner.py", line 85, in _start_by_fork
    args.func(args, dag=self.dag)
  File "/home/airflow/.local/lib/python3.8/site-packages/airflow/cli/cli_parser.py", line 48, in command
    return func(*args, **kwargs)
  File "/home/airflow/.local/lib/python3.8/site-packages/airflow/utils/cli.py", line 92, in wrapper
    return f(*args, **kwargs)
  File "/home/airflow/.local/lib/python3.8/site-packages/airflow/cli/commands/task_command.py", line 298, in task_run
    _run_task_by_selected_method(args, dag, ti)
  File "/home/airflow/.local/lib/python3.8/site-packages/airflow/cli/commands/task_command.py", line 107, in _run_task_by_selected_method
    _run_raw_task(args, ti)
  File "/home/airflow/.local/lib/python3.8/site-packages/airflow/cli/commands/task_command.py", line 180, in _run_raw_task
    ti._run_raw_task(
  File "/home/airflow/.local/lib/python3.8/site-packages/airflow/utils/session.py", line 70, in wrapper
    return func(*args, session=session, **kwargs)
  File "/home/airflow/.local/lib/python3.8/site-packages/airflow/models/taskinstance.py", line 1334, in _run_raw_task
    self._execute_task_with_callbacks(context)
  File "/home/airflow/.local/lib/python3.8/site-packages/airflow/models/taskinstance.py", line 1460, in _execute_task_with_callbacks
    result = self._execute_task(context, self.task)
  File "/home/airflow/.local/lib/python3.8/site-packages/airflow/models/taskinstance.py", line 1516, in _execute_task
    result = execute_callable(context=context)
  File "/home/airflow/.local/lib/python3.8/site-packages/airflow/operators/bash.py", line 187, in execute
    raise AirflowException(
airflow.exceptions.AirflowException: Bash command failed. The command returned a non-zero exit code 2.
[2022-06-10 00:55:06,896] {local_task_job.py:154} INFO - Task exited with return code 1
[2022-06-10 00:55:06,926] {local_task_job.py:264} INFO - 0 downstream tasks scheduled from follow-on schedule check
[2022-06-14 23:49:19,666] {taskinstance.py:1037} INFO - Dependencies all met for <TaskInstance: match_details_dag.daily_transform scheduled__2022-05-23T00:00:00+00:00 [None]>
[2022-06-14 23:49:19,676] {taskinstance.py:1037} INFO - Dependencies all met for <TaskInstance: match_details_dag.daily_transform scheduled__2022-05-23T00:00:00+00:00 [None]>
[2022-06-14 23:49:19,676] {taskinstance.py:1243} INFO - 
--------------------------------------------------------------------------------
[2022-06-14 23:49:19,676] {taskinstance.py:1244} INFO - Starting attempt 9 of 10
[2022-06-14 23:49:19,676] {taskinstance.py:1245} INFO - 
--------------------------------------------------------------------------------
[2022-06-14 23:49:19,687] {taskinstance.py:1264} INFO - Executing <Task(BashOperator): daily_transform> on 2022-05-23 00:00:00+00:00
[2022-06-14 23:49:19,691] {standard_task_runner.py:52} INFO - Started process 136 to run task
[2022-06-14 23:49:19,694] {standard_task_runner.py:76} INFO - Running: ['***', 'tasks', 'run', 'match_details_dag', 'daily_transform', 'scheduled__2022-05-23T00:00:00+00:00', '--job-id', '105', '--pool', 'default_pool', '--raw', '--subdir', 'DAGS_FOLDER/matchData_dag.py', '--cfg-path', '/tmp/tmp8_eepeho', '--error-file', '/tmp/tmpw7ln8gtd']
[2022-06-14 23:49:19,695] {standard_task_runner.py:77} INFO - Job 105: Subtask daily_transform
[2022-06-14 23:49:19,742] {logging_mixin.py:109} INFO - Running <TaskInstance: match_details_dag.daily_transform scheduled__2022-05-23T00:00:00+00:00 [running]> on host ebe3cc7dbee2
[2022-06-14 23:49:19,788] {taskinstance.py:1429} INFO - Exporting the following env vars:
AIRFLOW_CTX_DAG_OWNER=admin
AIRFLOW_CTX_DAG_ID=match_details_dag
AIRFLOW_CTX_TASK_ID=daily_transform
AIRFLOW_CTX_EXECUTION_DATE=2022-05-23T00:00:00+00:00
AIRFLOW_CTX_DAG_RUN_ID=scheduled__2022-05-23T00:00:00+00:00
[2022-06-14 23:49:19,789] {subprocess.py:62} INFO - Tmp dir root location: 
 /tmp
[2022-06-14 23:49:19,789] {subprocess.py:74} INFO - Running command: ['bash', '-c', 'cd /opt/***/dbt && dbt deps && dbt run --target dev']
[2022-06-14 23:49:19,798] {subprocess.py:85} INFO - Output:
[2022-06-14 23:49:22,708] {subprocess.py:89} INFO - 23:49:22  Running with dbt=1.1.0
[2022-06-14 23:49:23,106] {subprocess.py:89} INFO - 23:49:23  Installing dbt-labs/dbt_utils
[2022-06-14 23:49:23,693] {subprocess.py:89} INFO - 23:49:23    Installed from version 0.8.5
[2022-06-14 23:49:23,694] {subprocess.py:89} INFO - 23:49:23    Up to date!
[2022-06-14 23:49:28,008] {subprocess.py:89} INFO - 23:49:28  Running with dbt=1.1.0
[2022-06-14 23:49:28,044] {subprocess.py:89} INFO - 23:49:28  Unable to do partial parsing because config vars, config profile, or config target have changed
[2022-06-14 23:49:28,044] {subprocess.py:89} INFO - 23:49:28  Unable to do partial parsing because a project config has changed
[2022-06-14 23:49:28,392] {subprocess.py:89} INFO - 23:49:28  Encountered an error:
[2022-06-14 23:49:28,392] {subprocess.py:89} INFO - Parsing Error
[2022-06-14 23:49:28,393] {subprocess.py:89} INFO -   Error reading leagueoflegendsdbt: warehouse/schema.yml - Runtime Error
[2022-06-14 23:49:28,393] {subprocess.py:89} INFO -     Syntax error near line 20
[2022-06-14 23:49:28,393] {subprocess.py:89} INFO -     ------------------------------
[2022-06-14 23:49:28,393] {subprocess.py:89} INFO -     17 |
[2022-06-14 23:49:28,393] {subprocess.py:89} INFO -     18 | models:
[2022-06-14 23:49:28,393] {subprocess.py:89} INFO -     19 | +incremental_strategy: "merge"
[2022-06-14 23:49:28,393] {subprocess.py:89} INFO -     20 |   - name: final_match_details
[2022-06-14 23:49:28,393] {subprocess.py:89} INFO -     21 |     columns:
[2022-06-14 23:49:28,394] {subprocess.py:89} INFO -     22 |       - name: match_id
[2022-06-14 23:49:28,394] {subprocess.py:89} INFO -     23 |         tests:
[2022-06-14 23:49:28,394] {subprocess.py:89} INFO - 
[2022-06-14 23:49:28,394] {subprocess.py:89} INFO -     Raw Error:
[2022-06-14 23:49:28,394] {subprocess.py:89} INFO -     ------------------------------
[2022-06-14 23:49:28,394] {subprocess.py:89} INFO -     while parsing a block mapping
[2022-06-14 23:49:28,394] {subprocess.py:89} INFO -       in "<unicode string>", line 1, column 1
[2022-06-14 23:49:28,394] {subprocess.py:89} INFO -     did not find expected key
[2022-06-14 23:49:28,394] {subprocess.py:89} INFO -       in "<unicode string>", line 20, column 3
[2022-06-14 23:49:28,684] {subprocess.py:93} INFO - Command exited with return code 2
[2022-06-14 23:49:28,695] {taskinstance.py:1718} ERROR - Task failed with exception
Traceback (most recent call last):
  File "/home/airflow/.local/lib/python3.8/site-packages/airflow/models/taskinstance.py", line 1334, in _run_raw_task
    self._execute_task_with_callbacks(context)
  File "/home/airflow/.local/lib/python3.8/site-packages/airflow/models/taskinstance.py", line 1460, in _execute_task_with_callbacks
    result = self._execute_task(context, self.task)
  File "/home/airflow/.local/lib/python3.8/site-packages/airflow/models/taskinstance.py", line 1516, in _execute_task
    result = execute_callable(context=context)
  File "/home/airflow/.local/lib/python3.8/site-packages/airflow/operators/bash.py", line 187, in execute
    raise AirflowException(
airflow.exceptions.AirflowException: Bash command failed. The command returned a non-zero exit code 2.
[2022-06-14 23:49:28,700] {taskinstance.py:1272} INFO - Marking task as UP_FOR_RETRY. dag_id=match_details_dag, task_id=daily_transform, execution_date=20220523T000000, start_date=20220614T234919, end_date=20220614T234928
[2022-06-14 23:49:28,715] {standard_task_runner.py:89} ERROR - Failed to execute job 105 for task daily_transform
Traceback (most recent call last):
  File "/home/airflow/.local/lib/python3.8/site-packages/airflow/task/task_runner/standard_task_runner.py", line 85, in _start_by_fork
    args.func(args, dag=self.dag)
  File "/home/airflow/.local/lib/python3.8/site-packages/airflow/cli/cli_parser.py", line 48, in command
    return func(*args, **kwargs)
  File "/home/airflow/.local/lib/python3.8/site-packages/airflow/utils/cli.py", line 92, in wrapper
    return f(*args, **kwargs)
  File "/home/airflow/.local/lib/python3.8/site-packages/airflow/cli/commands/task_command.py", line 298, in task_run
    _run_task_by_selected_method(args, dag, ti)
  File "/home/airflow/.local/lib/python3.8/site-packages/airflow/cli/commands/task_command.py", line 107, in _run_task_by_selected_method
    _run_raw_task(args, ti)
  File "/home/airflow/.local/lib/python3.8/site-packages/airflow/cli/commands/task_command.py", line 180, in _run_raw_task
    ti._run_raw_task(
  File "/home/airflow/.local/lib/python3.8/site-packages/airflow/utils/session.py", line 70, in wrapper
    return func(*args, session=session, **kwargs)
  File "/home/airflow/.local/lib/python3.8/site-packages/airflow/models/taskinstance.py", line 1334, in _run_raw_task
    self._execute_task_with_callbacks(context)
  File "/home/airflow/.local/lib/python3.8/site-packages/airflow/models/taskinstance.py", line 1460, in _execute_task_with_callbacks
    result = self._execute_task(context, self.task)
  File "/home/airflow/.local/lib/python3.8/site-packages/airflow/models/taskinstance.py", line 1516, in _execute_task
    result = execute_callable(context=context)
  File "/home/airflow/.local/lib/python3.8/site-packages/airflow/operators/bash.py", line 187, in execute
    raise AirflowException(
airflow.exceptions.AirflowException: Bash command failed. The command returned a non-zero exit code 2.
[2022-06-14 23:49:28,747] {local_task_job.py:154} INFO - Task exited with return code 1
[2022-06-14 23:49:28,778] {local_task_job.py:264} INFO - 0 downstream tasks scheduled from follow-on schedule check
