[2022-05-20 03:37:08,845] {taskinstance.py:1037} INFO - Dependencies all met for <TaskInstance: league_of_legends_dag.paths.path_items.staging_items scheduled__2022-04-01T16:00:00+00:00 [queued]>
[2022-05-20 03:37:08,863] {taskinstance.py:1037} INFO - Dependencies all met for <TaskInstance: league_of_legends_dag.paths.path_items.staging_items scheduled__2022-04-01T16:00:00+00:00 [queued]>
[2022-05-20 03:37:08,864] {taskinstance.py:1243} INFO - 
--------------------------------------------------------------------------------
[2022-05-20 03:37:08,864] {taskinstance.py:1244} INFO - Starting attempt 2 of 2
[2022-05-20 03:37:08,864] {taskinstance.py:1245} INFO - 
--------------------------------------------------------------------------------
[2022-05-20 03:37:08,884] {taskinstance.py:1264} INFO - Executing <Task(riot_dataDragonToADLSOperator): paths.path_items.staging_items> on 2022-04-01 16:00:00+00:00
[2022-05-20 03:37:08,890] {standard_task_runner.py:52} INFO - Started process 1799 to run task
[2022-05-20 03:37:08,894] {standard_task_runner.py:76} INFO - Running: ['***', 'tasks', 'run', 'league_of_legends_dag', 'paths.path_items.staging_items', 'scheduled__2022-04-01T16:00:00+00:00', '--job-id', '529', '--raw', '--subdir', 'DAGS_FOLDER/dataDragon_dag.py', '--cfg-path', '/tmp/tmpu1n0iojx', '--error-file', '/tmp/tmpujpxpmlf']
[2022-05-20 03:37:08,895] {standard_task_runner.py:77} INFO - Job 529: Subtask paths.path_items.staging_items
[2022-05-20 03:37:08,964] {logging_mixin.py:109} INFO - Running <TaskInstance: league_of_legends_dag.paths.path_items.staging_items scheduled__2022-04-01T16:00:00+00:00 [running]> on host ca9a242fab95
[2022-05-20 03:37:09,038] {taskinstance.py:1429} INFO - Exporting the following env vars:
AIRFLOW_CTX_DAG_OWNER=admin
AIRFLOW_CTX_DAG_ID=league_of_legends_dag
AIRFLOW_CTX_TASK_ID=paths.path_items.staging_items
AIRFLOW_CTX_EXECUTION_DATE=2022-04-01T16:00:00+00:00
AIRFLOW_CTX_DAG_RUN_ID=scheduled__2022-04-01T16:00:00+00:00
[2022-05-20 03:37:09,039] {riot_datadragon_toADLS_Operator.py:55} INFO - StageToAzureLake not implemented yet
[2022-05-20 03:37:09,054] {riot_datadragon_toADLS_Operator.py:63} INFO - <bound method WasbHook.get_conn of <airflow.providers.microsoft.azure.hooks.wasb.WasbHook object at 0x7f9c89964a90>>
[2022-05-20 03:37:09,055] {riot_datadragon_toADLS_Operator.py:64} INFO - Created Azure Connections
[2022-05-20 03:37:09,404] {riot_datadragon_toADLS_Operator.py:86} INFO - About to load to Azure!
[2022-05-20 03:37:09,405] {riot_datadragon_toADLS_Operator.py:87} INFO - items
[2022-05-20 03:37:09,409] {_universal.py:472} INFO - Request URL: 'https://leagueoflegends.blob.core.windows.net/datadragon-items/2022/5/20/3.json'/nRequest method: 'PUT'/nRequest headers:/n    'x-ms-blob-type': 'REDACTED'/n    'Content-Length': '259055'/n    'If-None-Match': '*'/n    'x-ms-version': 'REDACTED'/n    'Content-Type': 'application/octet-stream'/n    'Accept': 'application/xml'/n    'User-Agent': 'azsdk-python-storage-blob/12.8.1 Python/3.8.12 (Linux-5.10.102.1-microsoft-standard-WSL2-x86_64-with-glibc2.2.5)'/n    'x-ms-date': 'REDACTED'/n    'x-ms-client-request-id': '20cc0496-d7ee-11ec-ab26-0242ac140004'/n    'Authorization': 'REDACTED'/nA body is sent with the request
[2022-05-20 03:37:09,639] {_universal.py:503} INFO - Response status: 409/nResponse headers:/n    'Content-Length': '220'/n    'Content-Type': 'application/xml'/n    'Server': 'Windows-Azure-Blob/1.0 Microsoft-HTTPAPI/2.0'/n    'x-ms-request-id': '9080a070-c01e-0017-22fa-6b2148000000'/n    'x-ms-client-request-id': '20cc0496-d7ee-11ec-ab26-0242ac140004'/n    'x-ms-version': 'REDACTED'/n    'x-ms-error-code': 'REDACTED'/n    'Date': 'Fri, 20 May 2022 03:37:10 GMT'
[2022-05-20 03:37:09,644] {taskinstance.py:1718} ERROR - Task failed with exception
Traceback (most recent call last):
  File "/home/airflow/.local/lib/python3.8/site-packages/azure/storage/blob/_upload_helpers.py", line 94, in upload_block_blob
    return client.upload(
  File "/home/airflow/.local/lib/python3.8/site-packages/azure/storage/blob/_generated/operations/_block_blob_operations.py", line 228, in upload
    map_error(status_code=response.status_code, response=response, error_map=error_map)
  File "/home/airflow/.local/lib/python3.8/site-packages/azure/core/exceptions.py", line 105, in map_error
    raise error
azure.core.exceptions.ResourceExistsError: Operation returned an invalid status 'The specified blob already exists.'
Content: <?xml version="1.0" encoding="utf-8"?><Error><Code>BlobAlreadyExists</Code><Message>The specified blob already exists.
RequestId:9080a070-c01e-0017-22fa-6b2148000000
Time:2022-05-20T03:37:11.2451206Z</Message></Error>

During handling of the above exception, another exception occurred:

Traceback (most recent call last):
  File "/home/airflow/.local/lib/python3.8/site-packages/airflow/models/taskinstance.py", line 1334, in _run_raw_task
    self._execute_task_with_callbacks(context)
  File "/home/airflow/.local/lib/python3.8/site-packages/airflow/models/taskinstance.py", line 1460, in _execute_task_with_callbacks
    result = self._execute_task(context, self.task)
  File "/home/airflow/.local/lib/python3.8/site-packages/airflow/models/taskinstance.py", line 1516, in _execute_task
    result = execute_callable(context=context)
  File "/opt/airflow/plugins/custom_operators/riot_datadragon_toADLS_Operator.py", line 56, in execute
    self.upload_to_azureLake()
  File "/opt/airflow/plugins/custom_operators/riot_datadragon_toADLS_Operator.py", line 88, in upload_to_azureLake
    wasb_hook.load_file(
  File "/home/airflow/.local/lib/python3.8/site-packages/airflow/providers/microsoft/azure/hooks/wasb.py", line 254, in load_file
    self.upload(
  File "/home/airflow/.local/lib/python3.8/site-packages/airflow/providers/microsoft/azure/hooks/wasb.py", line 339, in upload
    return blob_client.upload_blob(data, blob_type, length=length, **kwargs)
  File "/home/airflow/.local/lib/python3.8/site-packages/azure/core/tracing/decorator.py", line 83, in wrapper_use_tracer
    return func(*args, **kwargs)
  File "/home/airflow/.local/lib/python3.8/site-packages/azure/storage/blob/_blob_client.py", line 693, in upload_blob
    return upload_block_blob(**options)
  File "/home/airflow/.local/lib/python3.8/site-packages/azure/storage/blob/_upload_helpers.py", line 157, in upload_block_blob
    process_storage_error(error)
  File "/home/airflow/.local/lib/python3.8/site-packages/azure/storage/blob/_shared/response_handlers.py", line 150, in process_storage_error
    error.raise_with_traceback()
  File "/home/airflow/.local/lib/python3.8/site-packages/azure/core/exceptions.py", line 247, in raise_with_traceback
    raise super(AzureError, self).with_traceback(self.exc_traceback)
  File "/home/airflow/.local/lib/python3.8/site-packages/azure/storage/blob/_upload_helpers.py", line 94, in upload_block_blob
    return client.upload(
  File "/home/airflow/.local/lib/python3.8/site-packages/azure/storage/blob/_generated/operations/_block_blob_operations.py", line 228, in upload
    map_error(status_code=response.status_code, response=response, error_map=error_map)
  File "/home/airflow/.local/lib/python3.8/site-packages/azure/core/exceptions.py", line 105, in map_error
    raise error
azure.core.exceptions.ResourceExistsError: The specified blob already exists.
RequestId:9080a070-c01e-0017-22fa-6b2148000000
Time:2022-05-20T03:37:11.2451206Z
ErrorCode:BlobAlreadyExists
Error:None
Content: <?xml version="1.0" encoding="utf-8"?><Error><Code>BlobAlreadyExists</Code><Message>The specified blob already exists.
RequestId:9080a070-c01e-0017-22fa-6b2148000000
Time:2022-05-20T03:37:11.2451206Z</Message></Error>
[2022-05-20 03:37:09,669] {taskinstance.py:1272} INFO - Marking task as FAILED. dag_id=league_of_legends_dag, task_id=paths.path_items.staging_items, execution_date=20220401T160000, start_date=20220520T033708, end_date=20220520T033709
[2022-05-20 03:37:09,691] {standard_task_runner.py:89} ERROR - Failed to execute job 529 for task paths.path_items.staging_items
Traceback (most recent call last):
  File "/home/airflow/.local/lib/python3.8/site-packages/azure/storage/blob/_upload_helpers.py", line 94, in upload_block_blob
    return client.upload(
  File "/home/airflow/.local/lib/python3.8/site-packages/azure/storage/blob/_generated/operations/_block_blob_operations.py", line 228, in upload
    map_error(status_code=response.status_code, response=response, error_map=error_map)
  File "/home/airflow/.local/lib/python3.8/site-packages/azure/core/exceptions.py", line 105, in map_error
    raise error
azure.core.exceptions.ResourceExistsError: Operation returned an invalid status 'The specified blob already exists.'
Content: <?xml version="1.0" encoding="utf-8"?><Error><Code>BlobAlreadyExists</Code><Message>The specified blob already exists.
RequestId:9080a070-c01e-0017-22fa-6b2148000000
Time:2022-05-20T03:37:11.2451206Z</Message></Error>

During handling of the above exception, another exception occurred:

Traceback (most recent call last):
  File "/home/airflow/.local/lib/python3.8/site-packages/airflow/task/task_runner/standard_task_runner.py", line 85, in _start_by_fork
    args.func(args, dag=self.dag)
  File "/home/airflow/.local/lib/python3.8/site-packages/airflow/cli/cli_parser.py", line 48, in command
    return func(*args, **kwargs)
  File "/home/airflow/.local/lib/python3.8/site-packages/airflow/utils/cli.py", line 92, in wrapper
    return f(*args, **kwargs)
  File "/home/airflow/.local/lib/python3.8/site-packages/airflow/cli/commands/task_command.py", line 298, in task_run
    _run_task_by_selected_method(args, dag, ti)
  File "/home/airflow/.local/lib/python3.8/site-packages/airflow/cli/commands/task_command.py", line 107, in _run_task_by_selected_method
    _run_raw_task(args, ti)
  File "/home/airflow/.local/lib/python3.8/site-packages/airflow/cli/commands/task_command.py", line 180, in _run_raw_task
    ti._run_raw_task(
  File "/home/airflow/.local/lib/python3.8/site-packages/airflow/utils/session.py", line 70, in wrapper
    return func(*args, session=session, **kwargs)
  File "/home/airflow/.local/lib/python3.8/site-packages/airflow/models/taskinstance.py", line 1334, in _run_raw_task
    self._execute_task_with_callbacks(context)
  File "/home/airflow/.local/lib/python3.8/site-packages/airflow/models/taskinstance.py", line 1460, in _execute_task_with_callbacks
    result = self._execute_task(context, self.task)
  File "/home/airflow/.local/lib/python3.8/site-packages/airflow/models/taskinstance.py", line 1516, in _execute_task
    result = execute_callable(context=context)
  File "/opt/airflow/plugins/custom_operators/riot_datadragon_toADLS_Operator.py", line 56, in execute
    self.upload_to_azureLake()
  File "/opt/airflow/plugins/custom_operators/riot_datadragon_toADLS_Operator.py", line 88, in upload_to_azureLake
    wasb_hook.load_file(
  File "/home/airflow/.local/lib/python3.8/site-packages/airflow/providers/microsoft/azure/hooks/wasb.py", line 254, in load_file
    self.upload(
  File "/home/airflow/.local/lib/python3.8/site-packages/airflow/providers/microsoft/azure/hooks/wasb.py", line 339, in upload
    return blob_client.upload_blob(data, blob_type, length=length, **kwargs)
  File "/home/airflow/.local/lib/python3.8/site-packages/azure/core/tracing/decorator.py", line 83, in wrapper_use_tracer
    return func(*args, **kwargs)
  File "/home/airflow/.local/lib/python3.8/site-packages/azure/storage/blob/_blob_client.py", line 693, in upload_blob
    return upload_block_blob(**options)
  File "/home/airflow/.local/lib/python3.8/site-packages/azure/storage/blob/_upload_helpers.py", line 157, in upload_block_blob
    process_storage_error(error)
  File "/home/airflow/.local/lib/python3.8/site-packages/azure/storage/blob/_shared/response_handlers.py", line 150, in process_storage_error
    error.raise_with_traceback()
  File "/home/airflow/.local/lib/python3.8/site-packages/azure/core/exceptions.py", line 247, in raise_with_traceback
    raise super(AzureError, self).with_traceback(self.exc_traceback)
  File "/home/airflow/.local/lib/python3.8/site-packages/azure/storage/blob/_upload_helpers.py", line 94, in upload_block_blob
    return client.upload(
  File "/home/airflow/.local/lib/python3.8/site-packages/azure/storage/blob/_generated/operations/_block_blob_operations.py", line 228, in upload
    map_error(status_code=response.status_code, response=response, error_map=error_map)
  File "/home/airflow/.local/lib/python3.8/site-packages/azure/core/exceptions.py", line 105, in map_error
    raise error
azure.core.exceptions.ResourceExistsError: The specified blob already exists.
RequestId:9080a070-c01e-0017-22fa-6b2148000000
Time:2022-05-20T03:37:11.2451206Z
ErrorCode:BlobAlreadyExists
Error:None
Content: <?xml version="1.0" encoding="utf-8"?><Error><Code>BlobAlreadyExists</Code><Message>The specified blob already exists.
RequestId:9080a070-c01e-0017-22fa-6b2148000000
Time:2022-05-20T03:37:11.2451206Z</Message></Error>
[2022-05-20 03:37:09,711] {local_task_job.py:154} INFO - Task exited with return code 1
[2022-05-20 03:37:09,762] {local_task_job.py:264} INFO - 0 downstream tasks scheduled from follow-on schedule check
