[2022-06-15 18:15:20,091] {taskinstance.py:1037} INFO - Dependencies all met for <TaskInstance: match_details_dag.dbt_run manual__2022-06-15T00:01:53.911524+00:00 [None]>
[2022-06-15 18:15:20,103] {taskinstance.py:1037} INFO - Dependencies all met for <TaskInstance: match_details_dag.dbt_run manual__2022-06-15T00:01:53.911524+00:00 [None]>
[2022-06-15 18:15:20,103] {taskinstance.py:1243} INFO - 
--------------------------------------------------------------------------------
[2022-06-15 18:15:20,103] {taskinstance.py:1244} INFO - Starting attempt 6 of 7
[2022-06-15 18:15:20,103] {taskinstance.py:1245} INFO - 
--------------------------------------------------------------------------------
[2022-06-15 18:15:20,116] {taskinstance.py:1264} INFO - Executing <Task(BashOperator): dbt_run> on 2022-06-15 00:01:53.911524+00:00
[2022-06-15 18:15:20,122] {standard_task_runner.py:52} INFO - Started process 218 to run task
[2022-06-15 18:15:20,125] {standard_task_runner.py:76} INFO - Running: ['***', 'tasks', 'run', 'match_details_dag', 'dbt_run', 'manual__2022-06-15T00:01:53.911524+00:00', '--job-id', '123', '--pool', 'default_pool', '--raw', '--subdir', 'DAGS_FOLDER/matchData_dag.py', '--cfg-path', '/tmp/tmp4od7zjtz', '--error-file', '/tmp/tmphndz02y3']
[2022-06-15 18:15:20,126] {standard_task_runner.py:77} INFO - Job 123: Subtask dbt_run
[2022-06-15 18:15:20,181] {logging_mixin.py:109} INFO - Running <TaskInstance: match_details_dag.dbt_run manual__2022-06-15T00:01:53.911524+00:00 [running]> on host ebe3cc7dbee2
[2022-06-15 18:15:20,233] {taskinstance.py:1429} INFO - Exporting the following env vars:
AIRFLOW_CTX_DAG_OWNER=admin
AIRFLOW_CTX_DAG_ID=match_details_dag
AIRFLOW_CTX_TASK_ID=dbt_run
AIRFLOW_CTX_EXECUTION_DATE=2022-06-15T00:01:53.911524+00:00
AIRFLOW_CTX_DAG_RUN_ID=manual__2022-06-15T00:01:53.911524+00:00
[2022-06-15 18:15:20,235] {subprocess.py:62} INFO - Tmp dir root location: 
 /tmp
[2022-06-15 18:15:20,236] {subprocess.py:74} INFO - Running command: ['bash', '-c', 'cd /opt/***/dbt && dbt deps && dbt run']
[2022-06-15 18:15:20,249] {subprocess.py:85} INFO - Output:
[2022-06-15 18:15:23,993] {subprocess.py:89} INFO - 18:15:23  Running with dbt=1.1.0
[2022-06-15 18:15:24,798] {subprocess.py:89} INFO - 18:15:24  Installing dbt-labs/dbt_utils
[2022-06-15 18:15:25,379] {subprocess.py:89} INFO - 18:15:25    Installed from version 0.8.5
[2022-06-15 18:15:25,379] {subprocess.py:89} INFO - 18:15:25    Up to date!
[2022-06-15 18:15:30,022] {subprocess.py:89} INFO - 18:15:30  Running with dbt=1.1.0
[2022-06-15 18:15:30,236] {subprocess.py:89} INFO - 18:15:30  Found 14 models, 28 tests, 0 snapshots, 0 analyses, 400 macros, 0 operations, 0 seed files, 14 sources, 0 exposures, 0 metrics
[2022-06-15 18:15:30,240] {subprocess.py:89} INFO - 18:15:30
[2022-06-15 18:15:32,168] {subprocess.py:89} INFO - 18:15:32  Concurrency: 10 threads (target='dev')
[2022-06-15 18:15:32,168] {subprocess.py:89} INFO - 18:15:32
[2022-06-15 18:15:32,190] {subprocess.py:89} INFO - 18:15:32  1 of 14 START table model PUBLIC.final_champions ............................... [RUN]
[2022-06-15 18:15:32,193] {subprocess.py:89} INFO - 18:15:32  2 of 14 START table model PUBLIC.final_items ................................... [RUN]
[2022-06-15 18:15:32,196] {subprocess.py:89} INFO - 18:15:32  3 of 14 START table model PUBLIC.final_maps .................................... [RUN]
[2022-06-15 18:15:32,197] {subprocess.py:89} INFO - 18:15:32  4 of 14 START incremental model PUBLIC.final_match_details ..................... [RUN]
[2022-06-15 18:15:32,198] {subprocess.py:89} INFO - 18:15:32  5 of 14 START incremental model PUBLIC.final_match_info ........................ [RUN]
[2022-06-15 18:15:32,199] {subprocess.py:89} INFO - 18:15:32  6 of 14 START table model PUBLIC.final_runes_reforged .......................... [RUN]
[2022-06-15 18:15:32,200] {subprocess.py:89} INFO - 18:15:32  7 of 14 START table model PUBLIC.final_summonerspells .......................... [RUN]
[2022-06-15 18:15:32,201] {subprocess.py:89} INFO - 18:15:32  8 of 14 START view model PUBLIC.stg_champions .................................. [RUN]
[2022-06-15 18:15:32,202] {subprocess.py:89} INFO - 18:15:32  9 of 14 START view model PUBLIC.stg_items ...................................... [RUN]
[2022-06-15 18:15:32,203] {subprocess.py:89} INFO - 18:15:32  10 of 14 START view model PUBLIC.stg_maps ...................................... [RUN]
[2022-06-15 18:15:35,029] {subprocess.py:89} INFO - 18:15:35  5 of 14 ERROR creating incremental model PUBLIC.final_match_info ............... [[31mERROR[0m in 2.83s]
[2022-06-15 18:15:35,038] {subprocess.py:89} INFO - 18:15:35  11 of 14 START view model PUBLIC.stg_match_details ............................. [RUN]
[2022-06-15 18:15:36,468] {subprocess.py:89} INFO - 18:15:36  4 of 14 ERROR creating incremental model PUBLIC.final_match_details ............ [[31mERROR[0m in 4.27s]
[2022-06-15 18:15:36,474] {subprocess.py:89} INFO - 18:15:36  12 of 14 START view model PUBLIC.stg_match_info ................................ [RUN]
[2022-06-15 18:15:36,483] {subprocess.py:89} INFO - 18:15:36  9 of 14 OK created view model PUBLIC.stg_items ................................. [[32mSUCCESS 1[0m in 4.28s]
[2022-06-15 18:15:36,490] {subprocess.py:89} INFO - 18:15:36  13 of 14 START view model PUBLIC.stg_runes_reforged ............................ [RUN]
[2022-06-15 18:15:36,516] {subprocess.py:89} INFO - 18:15:36  1 of 14 OK created table model PUBLIC.final_champions .......................... [[32mSUCCESS 1[0m in 4.32s]
[2022-06-15 18:15:36,517] {subprocess.py:89} INFO - 18:15:36  14 of 14 START view model PUBLIC.stg_summonerspells ............................ [RUN]
[2022-06-15 18:15:37,123] {subprocess.py:89} INFO - 18:15:37  10 of 14 OK created view model PUBLIC.stg_maps ................................. [[32mSUCCESS 1[0m in 4.66s]
[2022-06-15 18:15:37,156] {subprocess.py:89} INFO - 18:15:37  2 of 14 ERROR creating table model PUBLIC.final_items .......................... [[31mERROR[0m in 4.69s]
[2022-06-15 18:15:37,200] {subprocess.py:89} INFO - 18:15:37  8 of 14 OK created view model PUBLIC.stg_champions ............................. [[32mSUCCESS 1[0m in 4.77s]
[2022-06-15 18:15:37,260] {subprocess.py:89} INFO - 18:15:37  11 of 14 OK created view model PUBLIC.stg_match_details ........................ [[32mSUCCESS 1[0m in 2.21s]
[2022-06-15 18:15:37,298] {subprocess.py:89} INFO - 18:15:37  3 of 14 OK created table model PUBLIC.final_maps ............................... [[32mSUCCESS 1[0m in 5.10s]
[2022-06-15 18:15:37,381] {subprocess.py:89} INFO - 18:15:37  6 of 14 OK created table model PUBLIC.final_runes_reforged ..................... [[32mSUCCESS 1[0m in 5.18s]
[2022-06-15 18:15:37,393] {subprocess.py:89} INFO - 18:15:37  7 of 14 OK created table model PUBLIC.final_summonerspells ..................... [[32mSUCCESS 1[0m in 5.19s]
[2022-06-15 18:15:37,914] {subprocess.py:89} INFO - 18:15:37  13 of 14 OK created view model PUBLIC.stg_runes_reforged ....................... [[32mSUCCESS 1[0m in 1.42s]
[2022-06-15 18:15:37,925] {subprocess.py:89} INFO - 18:15:37  14 of 14 OK created view model PUBLIC.stg_summonerspells ....................... [[32mSUCCESS 1[0m in 1.41s]
[2022-06-15 18:15:38,028] {subprocess.py:89} INFO - 18:15:38  12 of 14 OK created view model PUBLIC.stg_match_info ........................... [[32mSUCCESS 1[0m in 1.55s]
[2022-06-15 18:15:38,036] {subprocess.py:89} INFO - 18:15:38
[2022-06-15 18:15:38,037] {subprocess.py:89} INFO - 18:15:38  Finished running 2 incremental models, 7 view models, 5 table models in 7.79s.
[2022-06-15 18:15:38,068] {subprocess.py:89} INFO - 18:15:38
[2022-06-15 18:15:38,069] {subprocess.py:89} INFO - 18:15:38  [31mCompleted with 3 errors and 0 warnings:[0m
[2022-06-15 18:15:38,070] {subprocess.py:89} INFO - 18:15:38
[2022-06-15 18:15:38,071] {subprocess.py:89} INFO - 18:15:38  [33mDatabase Error in model final_match_info (models/warehouse/final_match_info.sql)[0m
[2022-06-15 18:15:38,072] {subprocess.py:89} INFO - 18:15:38    000904 (42000): SQL compilation error: error line 4 at position 16
[2022-06-15 18:15:38,072] {subprocess.py:89} INFO - 18:15:38    invalid identifier 'DBT_INTERNAL_SOURCE.MATCH_ID'
[2022-06-15 18:15:38,073] {subprocess.py:89} INFO - 18:15:38    compiled SQL at target/run/leagueoflegendsdbt/models/warehouse/final_match_info.sql
[2022-06-15 18:15:38,075] {subprocess.py:89} INFO - 18:15:38
[2022-06-15 18:15:38,076] {subprocess.py:89} INFO - 18:15:38  [33mDatabase Error in model final_match_details (models/warehouse/final_match_details.sql)[0m
[2022-06-15 18:15:38,077] {subprocess.py:89} INFO - 18:15:38    000904 (42000): SQL compilation error: error line 4 at position 16
[2022-06-15 18:15:38,078] {subprocess.py:89} INFO - 18:15:38    invalid identifier 'DBT_INTERNAL_SOURCE.MATCH_ID'
[2022-06-15 18:15:38,078] {subprocess.py:89} INFO - 18:15:38    compiled SQL at target/run/leagueoflegendsdbt/models/warehouse/final_match_details.sql
[2022-06-15 18:15:38,079] {subprocess.py:89} INFO - 18:15:38
[2022-06-15 18:15:38,080] {subprocess.py:89} INFO - 18:15:38  [33mDatabase Error in model final_items (models/warehouse/final_items.sql)[0m
[2022-06-15 18:15:38,081] {subprocess.py:89} INFO - 18:15:38    000904 (42000): SQL compilation error: error line 9 at position 8
[2022-06-15 18:15:38,082] {subprocess.py:89} INFO - 18:15:38    invalid identifier 'ID'
[2022-06-15 18:15:38,083] {subprocess.py:89} INFO - 18:15:38    compiled SQL at target/run/leagueoflegendsdbt/models/warehouse/final_items.sql
[2022-06-15 18:15:38,084] {subprocess.py:89} INFO - 18:15:38
[2022-06-15 18:15:38,086] {subprocess.py:89} INFO - 18:15:38  Done. PASS=11 WARN=0 ERROR=3 SKIP=0 TOTAL=14
[2022-06-15 18:15:39,131] {subprocess.py:93} INFO - Command exited with return code 1
[2022-06-15 18:15:39,144] {taskinstance.py:1718} ERROR - Task failed with exception
Traceback (most recent call last):
  File "/home/airflow/.local/lib/python3.8/site-packages/airflow/models/taskinstance.py", line 1334, in _run_raw_task
    self._execute_task_with_callbacks(context)
  File "/home/airflow/.local/lib/python3.8/site-packages/airflow/models/taskinstance.py", line 1460, in _execute_task_with_callbacks
    result = self._execute_task(context, self.task)
  File "/home/airflow/.local/lib/python3.8/site-packages/airflow/models/taskinstance.py", line 1516, in _execute_task
    result = execute_callable(context=context)
  File "/home/airflow/.local/lib/python3.8/site-packages/airflow/operators/bash.py", line 187, in execute
    raise AirflowException(
airflow.exceptions.AirflowException: Bash command failed. The command returned a non-zero exit code 1.
[2022-06-15 18:15:39,151] {taskinstance.py:1272} INFO - Marking task as UP_FOR_RETRY. dag_id=match_details_dag, task_id=dbt_run, execution_date=20220615T000153, start_date=20220615T181520, end_date=20220615T181539
[2022-06-15 18:15:39,166] {standard_task_runner.py:89} ERROR - Failed to execute job 123 for task dbt_run
Traceback (most recent call last):
  File "/home/airflow/.local/lib/python3.8/site-packages/airflow/task/task_runner/standard_task_runner.py", line 85, in _start_by_fork
    args.func(args, dag=self.dag)
  File "/home/airflow/.local/lib/python3.8/site-packages/airflow/cli/cli_parser.py", line 48, in command
    return func(*args, **kwargs)
  File "/home/airflow/.local/lib/python3.8/site-packages/airflow/utils/cli.py", line 92, in wrapper
    return f(*args, **kwargs)
  File "/home/airflow/.local/lib/python3.8/site-packages/airflow/cli/commands/task_command.py", line 298, in task_run
    _run_task_by_selected_method(args, dag, ti)
  File "/home/airflow/.local/lib/python3.8/site-packages/airflow/cli/commands/task_command.py", line 107, in _run_task_by_selected_method
    _run_raw_task(args, ti)
  File "/home/airflow/.local/lib/python3.8/site-packages/airflow/cli/commands/task_command.py", line 180, in _run_raw_task
    ti._run_raw_task(
  File "/home/airflow/.local/lib/python3.8/site-packages/airflow/utils/session.py", line 70, in wrapper
    return func(*args, session=session, **kwargs)
  File "/home/airflow/.local/lib/python3.8/site-packages/airflow/models/taskinstance.py", line 1334, in _run_raw_task
    self._execute_task_with_callbacks(context)
  File "/home/airflow/.local/lib/python3.8/site-packages/airflow/models/taskinstance.py", line 1460, in _execute_task_with_callbacks
    result = self._execute_task(context, self.task)
  File "/home/airflow/.local/lib/python3.8/site-packages/airflow/models/taskinstance.py", line 1516, in _execute_task
    result = execute_callable(context=context)
  File "/home/airflow/.local/lib/python3.8/site-packages/airflow/operators/bash.py", line 187, in execute
    raise AirflowException(
airflow.exceptions.AirflowException: Bash command failed. The command returned a non-zero exit code 1.
[2022-06-15 18:15:39,190] {local_task_job.py:154} INFO - Task exited with return code 1
[2022-06-15 18:15:39,231] {local_task_job.py:264} INFO - 0 downstream tasks scheduled from follow-on schedule check
