[2022-05-19 23:37:16,969] {taskinstance.py:1037} INFO - Dependencies all met for <TaskInstance: league_of_legends_dag.paths.path_maps.Create_StagingSnowflake_Tables_maps manual__2022-05-19T23:08:18.611675+00:00 [queued]>
[2022-05-19 23:37:16,982] {taskinstance.py:1037} INFO - Dependencies all met for <TaskInstance: league_of_legends_dag.paths.path_maps.Create_StagingSnowflake_Tables_maps manual__2022-05-19T23:08:18.611675+00:00 [queued]>
[2022-05-19 23:37:16,982] {taskinstance.py:1243} INFO - 
--------------------------------------------------------------------------------
[2022-05-19 23:37:16,982] {taskinstance.py:1244} INFO - Starting attempt 8 of 8
[2022-05-19 23:37:16,982] {taskinstance.py:1245} INFO - 
--------------------------------------------------------------------------------
[2022-05-19 23:37:16,995] {taskinstance.py:1264} INFO - Executing <Task(SnowflakeOperator): paths.path_maps.Create_StagingSnowflake_Tables_maps> on 2022-05-19 23:08:18.611675+00:00
[2022-05-19 23:37:17,002] {standard_task_runner.py:52} INFO - Started process 4136 to run task
[2022-05-19 23:37:17,004] {standard_task_runner.py:76} INFO - Running: ['***', 'tasks', 'run', 'league_of_legends_dag', 'paths.path_maps.Create_StagingSnowflake_Tables_maps', 'manual__2022-05-19T23:08:18.611675+00:00', '--job-id', '397', '--raw', '--subdir', 'DAGS_FOLDER/dataDragon_dag.py', '--cfg-path', '/tmp/tmpnjhyzu8p', '--error-file', '/tmp/tmpzxb0m8bd']
[2022-05-19 23:37:17,005] {standard_task_runner.py:77} INFO - Job 397: Subtask paths.path_maps.Create_StagingSnowflake_Tables_maps
[2022-05-19 23:37:17,063] {logging_mixin.py:109} INFO - Running <TaskInstance: league_of_legends_dag.paths.path_maps.Create_StagingSnowflake_Tables_maps manual__2022-05-19T23:08:18.611675+00:00 [running]> on host ca9a242fab95
[2022-05-19 23:37:17,123] {taskinstance.py:1429} INFO - Exporting the following env vars:
AIRFLOW_CTX_DAG_OWNER=admin
AIRFLOW_CTX_DAG_ID=league_of_legends_dag
AIRFLOW_CTX_TASK_ID=paths.path_maps.Create_StagingSnowflake_Tables_maps
AIRFLOW_CTX_EXECUTION_DATE=2022-05-19T23:08:18.611675+00:00
AIRFLOW_CTX_DAG_RUN_ID=manual__2022-05-19T23:08:18.611675+00:00
[2022-05-19 23:37:17,124] {snowflake.py:118} INFO - Executing: CREATE OR REPLACE TABLE STAGING_DATADRAGON_MAPS (json_data variant);
[2022-05-19 23:37:17,134] {connection.py:257} INFO - Snowflake Connector for Python Version: 2.5.1, Python Version: 3.8.12, Platform: Linux-5.10.102.1-microsoft-standard-WSL2-x86_64-with-glibc2.2.5
[2022-05-19 23:37:17,134] {connection.py:868} INFO - This connection is in OCSP Fail Open Mode. TLS Certificates would be checked for validity and revocation status. Any other Certificate Revocation related exceptions or OCSP Responder failures would be disregarded in favor of connectivity.
[2022-05-19 23:37:17,135] {connection.py:886} INFO - Setting use_openssl_only mode to False
[2022-05-19 23:37:17,904] {cursor.py:637} INFO - query: [ALTER SESSION SET autocommit=True]
[2022-05-19 23:37:18,054] {cursor.py:661} INFO - query execution done
[2022-05-19 23:37:18,055] {snowflake.py:324} INFO - Running statement: CREATE OR REPLACE TABLE STAGING_DATADRAGON_MAPS (json_data variant);, parameters: None
[2022-05-19 23:37:18,055] {cursor.py:637} INFO - query: [CREATE OR REPLACE TABLE STAGING_DATADRAGON_MAPS (json_data variant);]
[2022-05-19 23:37:18,242] {cursor.py:661} INFO - query execution done
[2022-05-19 23:37:18,247] {connection.py:499} INFO - closed
[2022-05-19 23:37:18,292] {connection.py:502} INFO - No async queries seem to be running, deleting session
[2022-05-19 23:37:18,371] {taskinstance.py:1718} ERROR - Task failed with exception
Traceback (most recent call last):
  File "/home/airflow/.local/lib/python3.8/site-packages/airflow/models/taskinstance.py", line 1334, in _run_raw_task
    self._execute_task_with_callbacks(context)
  File "/home/airflow/.local/lib/python3.8/site-packages/airflow/models/taskinstance.py", line 1460, in _execute_task_with_callbacks
    result = self._execute_task(context, self.task)
  File "/home/airflow/.local/lib/python3.8/site-packages/airflow/models/taskinstance.py", line 1516, in _execute_task
    result = execute_callable(context=context)
  File "/home/airflow/.local/lib/python3.8/site-packages/airflow/providers/snowflake/operators/snowflake.py", line 120, in execute
    execution_info = hook.run(self.sql, autocommit=self.autocommit, parameters=self.parameters)
  File "/home/airflow/.local/lib/python3.8/site-packages/airflow/providers/snowflake/hooks/snowflake.py", line 328, in run
    cur.execute(sql_statement)
  File "/home/airflow/.local/lib/python3.8/site-packages/snowflake/connector/cursor.py", line 721, in execute
    Error.errorhandler_wrapper(
  File "/home/airflow/.local/lib/python3.8/site-packages/snowflake/connector/errors.py", line 258, in errorhandler_wrapper
    cursor.errorhandler(connection, cursor, error_class, error_value)
  File "/home/airflow/.local/lib/python3.8/site-packages/snowflake/connector/errors.py", line 188, in default_errorhandler
    raise error_class(
snowflake.connector.errors.ProgrammingError: 090106 (22000): 01a46169-0000-f1b3-0000-d9690003719a: Cannot perform CREATE TABLE. This session does not have a current schema. Call 'USE SCHEMA', or use a qualified name.
[2022-05-19 23:37:18,384] {taskinstance.py:1272} INFO - Marking task as FAILED. dag_id=league_of_legends_dag, task_id=paths.path_maps.Create_StagingSnowflake_Tables_maps, execution_date=20220519T230818, start_date=20220519T233716, end_date=20220519T233718
[2022-05-19 23:37:18,399] {standard_task_runner.py:89} ERROR - Failed to execute job 397 for task paths.path_maps.Create_StagingSnowflake_Tables_maps
Traceback (most recent call last):
  File "/home/airflow/.local/lib/python3.8/site-packages/airflow/task/task_runner/standard_task_runner.py", line 85, in _start_by_fork
    args.func(args, dag=self.dag)
  File "/home/airflow/.local/lib/python3.8/site-packages/airflow/cli/cli_parser.py", line 48, in command
    return func(*args, **kwargs)
  File "/home/airflow/.local/lib/python3.8/site-packages/airflow/utils/cli.py", line 92, in wrapper
    return f(*args, **kwargs)
  File "/home/airflow/.local/lib/python3.8/site-packages/airflow/cli/commands/task_command.py", line 298, in task_run
    _run_task_by_selected_method(args, dag, ti)
  File "/home/airflow/.local/lib/python3.8/site-packages/airflow/cli/commands/task_command.py", line 107, in _run_task_by_selected_method
    _run_raw_task(args, ti)
  File "/home/airflow/.local/lib/python3.8/site-packages/airflow/cli/commands/task_command.py", line 180, in _run_raw_task
    ti._run_raw_task(
  File "/home/airflow/.local/lib/python3.8/site-packages/airflow/utils/session.py", line 70, in wrapper
    return func(*args, session=session, **kwargs)
  File "/home/airflow/.local/lib/python3.8/site-packages/airflow/models/taskinstance.py", line 1334, in _run_raw_task
    self._execute_task_with_callbacks(context)
  File "/home/airflow/.local/lib/python3.8/site-packages/airflow/models/taskinstance.py", line 1460, in _execute_task_with_callbacks
    result = self._execute_task(context, self.task)
  File "/home/airflow/.local/lib/python3.8/site-packages/airflow/models/taskinstance.py", line 1516, in _execute_task
    result = execute_callable(context=context)
  File "/home/airflow/.local/lib/python3.8/site-packages/airflow/providers/snowflake/operators/snowflake.py", line 120, in execute
    execution_info = hook.run(self.sql, autocommit=self.autocommit, parameters=self.parameters)
  File "/home/airflow/.local/lib/python3.8/site-packages/airflow/providers/snowflake/hooks/snowflake.py", line 328, in run
    cur.execute(sql_statement)
  File "/home/airflow/.local/lib/python3.8/site-packages/snowflake/connector/cursor.py", line 721, in execute
    Error.errorhandler_wrapper(
  File "/home/airflow/.local/lib/python3.8/site-packages/snowflake/connector/errors.py", line 258, in errorhandler_wrapper
    cursor.errorhandler(connection, cursor, error_class, error_value)
  File "/home/airflow/.local/lib/python3.8/site-packages/snowflake/connector/errors.py", line 188, in default_errorhandler
    raise error_class(
snowflake.connector.errors.ProgrammingError: 090106 (22000): 01a46169-0000-f1b3-0000-d9690003719a: Cannot perform CREATE TABLE. This session does not have a current schema. Call 'USE SCHEMA', or use a qualified name.
[2022-05-19 23:37:18,422] {local_task_job.py:154} INFO - Task exited with return code 1
[2022-05-19 23:37:18,460] {local_task_job.py:264} INFO - 0 downstream tasks scheduled from follow-on schedule check
