[2022-06-23 18:20:20,446] {taskinstance.py:1037} INFO - Dependencies all met for <TaskInstance: match_details_dag.azure_toSnowflake_paths.path_matchdetails.azure_matchdetails_snowflake scheduled__2022-06-20T00:00:00+00:00 [queued]>
[2022-06-23 18:20:20,455] {taskinstance.py:1037} INFO - Dependencies all met for <TaskInstance: match_details_dag.azure_toSnowflake_paths.path_matchdetails.azure_matchdetails_snowflake scheduled__2022-06-20T00:00:00+00:00 [queued]>
[2022-06-23 18:20:20,456] {taskinstance.py:1243} INFO - 
--------------------------------------------------------------------------------
[2022-06-23 18:20:20,456] {taskinstance.py:1244} INFO - Starting attempt 1 of 2
[2022-06-23 18:20:20,456] {taskinstance.py:1245} INFO - 
--------------------------------------------------------------------------------
[2022-06-23 18:20:20,466] {taskinstance.py:1264} INFO - Executing <Task(AzureDataLakeToSnowflakeTransferOperator): azure_toSnowflake_paths.path_matchdetails.azure_matchdetails_snowflake> on 2022-06-20 00:00:00+00:00
[2022-06-23 18:20:20,470] {standard_task_runner.py:52} INFO - Started process 87 to run task
[2022-06-23 18:20:20,473] {standard_task_runner.py:76} INFO - Running: ['***', 'tasks', 'run', 'match_details_dag', 'azure_toSnowflake_paths.path_matchdetails.azure_matchdetails_snowflake', 'scheduled__2022-06-20T00:00:00+00:00', '--job-id', '272', '--raw', '--subdir', 'DAGS_FOLDER/matchData_dag.py', '--cfg-path', '/tmp/tmp8h5mzxjo', '--error-file', '/tmp/tmph_ur2zf2']
[2022-06-23 18:20:20,474] {standard_task_runner.py:77} INFO - Job 272: Subtask azure_toSnowflake_paths.path_matchdetails.azure_matchdetails_snowflake
[2022-06-23 18:20:20,520] {logging_mixin.py:109} INFO - Running <TaskInstance: match_details_dag.azure_toSnowflake_paths.path_matchdetails.azure_matchdetails_snowflake scheduled__2022-06-20T00:00:00+00:00 [running]> on host ebe3cc7dbee2
[2022-06-23 18:20:20,562] {taskinstance.py:1429} INFO - Exporting the following env vars:
AIRFLOW_CTX_DAG_OWNER=admin
AIRFLOW_CTX_DAG_ID=match_details_dag
AIRFLOW_CTX_TASK_ID=azure_toSnowflake_paths.path_matchdetails.azure_matchdetails_snowflake
AIRFLOW_CTX_EXECUTION_DATE=2022-06-20T00:00:00+00:00
AIRFLOW_CTX_DAG_RUN_ID=scheduled__2022-06-20T00:00:00+00:00
[2022-06-23 18:20:20,563] {azureToSnowflake.py:73} INFO - Executing COPY command...
[2022-06-23 18:20:20,572] {connection.py:257} INFO - Snowflake Connector for Python Version: 2.7.8, Python Version: 3.8.12, Platform: Linux-5.10.102.1-microsoft-standard-WSL2-x86_64-with-glibc2.2.5
[2022-06-23 18:20:20,572] {connection.py:876} INFO - This connection is in OCSP Fail Open Mode. TLS Certificates would be checked for validity and revocation status. Any other Certificate Revocation related exceptions or OCSP Responder failures would be disregarded in favor of connectivity.
[2022-06-23 18:20:20,572] {connection.py:894} INFO - Setting use_openssl_only mode to False
[2022-06-23 18:20:21,182] {cursor.py:710} INFO - query: [ALTER SESSION SET autocommit=True]
[2022-06-23 18:20:21,298] {cursor.py:734} INFO - query execution done
[2022-06-23 18:20:21,298] {snowflake.py:324} INFO - Running statement: COPY INTO STAGING_MATCHDETAILS
FROM @MY_AZURE_MATCH_DETAILS_STAGE/
files=('2022/6/23/18.csv')
file_format=MATCH_DETAILS_FILEFORMAT, parameters: None
[2022-06-23 18:20:21,299] {cursor.py:710} INFO - query: [COPY INTO STAGING_MATCHDETAILS FROM @MY_AZURE_MATCH_DETAILS_STAGE/ files=('2022/...]
[2022-06-23 18:20:22,119] {cursor.py:734} INFO - query execution done
[2022-06-23 18:20:22,119] {snowflake.py:334} INFO - Statement execution info - {'file': 'azure://leagueoflegends.blob.core.windows.net/match-details/2022/6/23/18.csv', 'status': 'LOADED', 'rows_parsed': 600, 'rows_loaded': 600, 'error_limit': 1, 'errors_seen': 0, 'first_error': None, 'first_error_line': None, 'first_error_character': None, 'first_error_column_name': None}
[2022-06-23 18:20:22,120] {snowflake.py:338} INFO - Rows affected: 1
[2022-06-23 18:20:22,120] {snowflake.py:339} INFO - Snowflake query id: 01a5250c-0000-fcc5-0000-d969000590ca
[2022-06-23 18:20:22,120] {connection.py:507} INFO - closed
[2022-06-23 18:20:22,164] {connection.py:510} INFO - No async queries seem to be running, deleting session
[2022-06-23 18:20:22,254] {azureToSnowflake.py:75} INFO - COPY command completed
[2022-06-23 18:20:22,264] {taskinstance.py:1272} INFO - Marking task as SUCCESS. dag_id=match_details_dag, task_id=azure_toSnowflake_paths.path_matchdetails.azure_matchdetails_snowflake, execution_date=20220620T000000, start_date=20220623T182020, end_date=20220623T182022
[2022-06-23 18:20:22,294] {local_task_job.py:154} INFO - Task exited with return code 0
[2022-06-23 18:20:22,329] {local_task_job.py:264} INFO - 0 downstream tasks scheduled from follow-on schedule check
[2022-06-23 18:30:20,987] {taskinstance.py:1037} INFO - Dependencies all met for <TaskInstance: match_details_dag.azure_toSnowflake_paths.path_matchdetails.azure_matchdetails_snowflake scheduled__2022-06-20T00:00:00+00:00 [queued]>
[2022-06-23 18:30:20,996] {taskinstance.py:1037} INFO - Dependencies all met for <TaskInstance: match_details_dag.azure_toSnowflake_paths.path_matchdetails.azure_matchdetails_snowflake scheduled__2022-06-20T00:00:00+00:00 [queued]>
[2022-06-23 18:30:20,996] {taskinstance.py:1243} INFO - 
--------------------------------------------------------------------------------
[2022-06-23 18:30:20,996] {taskinstance.py:1244} INFO - Starting attempt 1 of 2
[2022-06-23 18:30:20,996] {taskinstance.py:1245} INFO - 
--------------------------------------------------------------------------------
[2022-06-23 18:30:21,008] {taskinstance.py:1264} INFO - Executing <Task(AzureDataLakeToSnowflakeTransferOperator): azure_toSnowflake_paths.path_matchdetails.azure_matchdetails_snowflake> on 2022-06-20 00:00:00+00:00
[2022-06-23 18:30:21,012] {standard_task_runner.py:52} INFO - Started process 159 to run task
[2022-06-23 18:30:21,015] {standard_task_runner.py:76} INFO - Running: ['***', 'tasks', 'run', 'match_details_dag', 'azure_toSnowflake_paths.path_matchdetails.azure_matchdetails_snowflake', 'scheduled__2022-06-20T00:00:00+00:00', '--job-id', '279', '--raw', '--subdir', 'DAGS_FOLDER/matchData_dag.py', '--cfg-path', '/tmp/tmpj94e07qn', '--error-file', '/tmp/tmpvnrl66ic']
[2022-06-23 18:30:21,016] {standard_task_runner.py:77} INFO - Job 279: Subtask azure_toSnowflake_paths.path_matchdetails.azure_matchdetails_snowflake
[2022-06-23 18:30:21,059] {logging_mixin.py:109} INFO - Running <TaskInstance: match_details_dag.azure_toSnowflake_paths.path_matchdetails.azure_matchdetails_snowflake scheduled__2022-06-20T00:00:00+00:00 [running]> on host ebe3cc7dbee2
[2022-06-23 18:30:21,105] {taskinstance.py:1429} INFO - Exporting the following env vars:
AIRFLOW_CTX_DAG_OWNER=admin
AIRFLOW_CTX_DAG_ID=match_details_dag
AIRFLOW_CTX_TASK_ID=azure_toSnowflake_paths.path_matchdetails.azure_matchdetails_snowflake
AIRFLOW_CTX_EXECUTION_DATE=2022-06-20T00:00:00+00:00
AIRFLOW_CTX_DAG_RUN_ID=scheduled__2022-06-20T00:00:00+00:00
[2022-06-23 18:30:21,106] {azureToSnowflake.py:73} INFO - Executing COPY command...
[2022-06-23 18:30:21,115] {connection.py:257} INFO - Snowflake Connector for Python Version: 2.7.8, Python Version: 3.8.12, Platform: Linux-5.10.102.1-microsoft-standard-WSL2-x86_64-with-glibc2.2.5
[2022-06-23 18:30:21,115] {connection.py:876} INFO - This connection is in OCSP Fail Open Mode. TLS Certificates would be checked for validity and revocation status. Any other Certificate Revocation related exceptions or OCSP Responder failures would be disregarded in favor of connectivity.
[2022-06-23 18:30:21,115] {connection.py:894} INFO - Setting use_openssl_only mode to False
[2022-06-23 18:30:21,885] {cursor.py:710} INFO - query: [ALTER SESSION SET autocommit=True]
[2022-06-23 18:30:22,005] {cursor.py:734} INFO - query execution done
[2022-06-23 18:30:22,006] {snowflake.py:324} INFO - Running statement: COPY INTO STAGING_MATCHDETAILS
FROM @MY_AZURE_MATCH_DETAILS_STAGE/
files=('2022/6/23/18.csv')
file_format=MATCH_DETAILS_FILEFORMAT, parameters: None
[2022-06-23 18:30:22,006] {cursor.py:710} INFO - query: [COPY INTO STAGING_MATCHDETAILS FROM @MY_AZURE_MATCH_DETAILS_STAGE/ files=('2022/...]
[2022-06-23 18:30:22,732] {cursor.py:734} INFO - query execution done
[2022-06-23 18:30:22,732] {snowflake.py:334} INFO - Statement execution info - {'file': 'azure://leagueoflegends.blob.core.windows.net/match-details/2022/6/23/18.csv', 'status': 'LOADED', 'rows_parsed': 1000, 'rows_loaded': 1000, 'error_limit': 1, 'errors_seen': 0, 'first_error': None, 'first_error_line': None, 'first_error_character': None, 'first_error_column_name': None}
[2022-06-23 18:30:22,732] {snowflake.py:338} INFO - Rows affected: 1
[2022-06-23 18:30:22,733] {snowflake.py:339} INFO - Snowflake query id: 01a52516-0000-fccb-0000-d9690005a0ea
[2022-06-23 18:30:22,733] {connection.py:507} INFO - closed
[2022-06-23 18:30:22,778] {connection.py:510} INFO - No async queries seem to be running, deleting session
[2022-06-23 18:30:22,843] {azureToSnowflake.py:75} INFO - COPY command completed
[2022-06-23 18:30:22,856] {taskinstance.py:1272} INFO - Marking task as SUCCESS. dag_id=match_details_dag, task_id=azure_toSnowflake_paths.path_matchdetails.azure_matchdetails_snowflake, execution_date=20220620T000000, start_date=20220623T183020, end_date=20220623T183022
[2022-06-23 18:30:22,914] {local_task_job.py:154} INFO - Task exited with return code 0
[2022-06-23 18:30:22,949] {local_task_job.py:264} INFO - 1 downstream tasks scheduled from follow-on schedule check
[2022-06-23 21:20:48,431] {taskinstance.py:1037} INFO - Dependencies all met for <TaskInstance: match_details_dag.azure_toSnowflake_paths.path_matchdetails.azure_matchdetails_snowflake scheduled__2022-06-20T00:00:00+00:00 [queued]>
[2022-06-23 21:20:48,442] {taskinstance.py:1037} INFO - Dependencies all met for <TaskInstance: match_details_dag.azure_toSnowflake_paths.path_matchdetails.azure_matchdetails_snowflake scheduled__2022-06-20T00:00:00+00:00 [queued]>
[2022-06-23 21:20:48,443] {taskinstance.py:1243} INFO - 
--------------------------------------------------------------------------------
[2022-06-23 21:20:48,443] {taskinstance.py:1244} INFO - Starting attempt 1 of 2
[2022-06-23 21:20:48,443] {taskinstance.py:1245} INFO - 
--------------------------------------------------------------------------------
[2022-06-23 21:20:48,455] {taskinstance.py:1264} INFO - Executing <Task(AzureDataLakeToSnowflakeTransferOperator): azure_toSnowflake_paths.path_matchdetails.azure_matchdetails_snowflake> on 2022-06-20 00:00:00+00:00
[2022-06-23 21:20:48,461] {standard_task_runner.py:52} INFO - Started process 1188 to run task
[2022-06-23 21:20:48,463] {standard_task_runner.py:76} INFO - Running: ['***', 'tasks', 'run', 'match_details_dag', 'azure_toSnowflake_paths.path_matchdetails.azure_matchdetails_snowflake', 'scheduled__2022-06-20T00:00:00+00:00', '--job-id', '294', '--raw', '--subdir', 'DAGS_FOLDER/matchData_dag.py', '--cfg-path', '/tmp/tmptln5yyd7', '--error-file', '/tmp/tmpgyfgj61x']
[2022-06-23 21:20:48,464] {standard_task_runner.py:77} INFO - Job 294: Subtask azure_toSnowflake_paths.path_matchdetails.azure_matchdetails_snowflake
[2022-06-23 21:20:48,520] {logging_mixin.py:109} INFO - Running <TaskInstance: match_details_dag.azure_toSnowflake_paths.path_matchdetails.azure_matchdetails_snowflake scheduled__2022-06-20T00:00:00+00:00 [running]> on host ebe3cc7dbee2
[2022-06-23 21:20:48,579] {taskinstance.py:1429} INFO - Exporting the following env vars:
AIRFLOW_CTX_DAG_OWNER=admin
AIRFLOW_CTX_DAG_ID=match_details_dag
AIRFLOW_CTX_TASK_ID=azure_toSnowflake_paths.path_matchdetails.azure_matchdetails_snowflake
AIRFLOW_CTX_EXECUTION_DATE=2022-06-20T00:00:00+00:00
AIRFLOW_CTX_DAG_RUN_ID=scheduled__2022-06-20T00:00:00+00:00
[2022-06-23 21:20:48,579] {azureToSnowflake.py:73} INFO - Executing COPY command...
[2022-06-23 21:20:48,591] {connection.py:257} INFO - Snowflake Connector for Python Version: 2.7.8, Python Version: 3.8.12, Platform: Linux-5.10.102.1-microsoft-standard-WSL2-x86_64-with-glibc2.2.5
[2022-06-23 21:20:48,592] {connection.py:876} INFO - This connection is in OCSP Fail Open Mode. TLS Certificates would be checked for validity and revocation status. Any other Certificate Revocation related exceptions or OCSP Responder failures would be disregarded in favor of connectivity.
[2022-06-23 21:20:48,592] {connection.py:894} INFO - Setting use_openssl_only mode to False
[2022-06-23 21:20:49,113] {cursor.py:710} INFO - query: [ALTER SESSION SET autocommit=True]
[2022-06-23 21:20:49,218] {cursor.py:734} INFO - query execution done
[2022-06-23 21:20:49,220] {snowflake.py:324} INFO - Running statement: COPY INTO STAGING_MATCHDETAILS
FROM @MY_AZURE_MATCH_DETAILS_STAGE/
files=('2022/6/23/21.csv')
file_format=MATCH_DETAILS_FILEFORMAT, parameters: None
[2022-06-23 21:20:49,220] {cursor.py:710} INFO - query: [COPY INTO STAGING_MATCHDETAILS FROM @MY_AZURE_MATCH_DETAILS_STAGE/ files=('2022/...]
[2022-06-23 21:20:50,567] {cursor.py:734} INFO - query execution done
[2022-06-23 21:20:50,567] {snowflake.py:334} INFO - Statement execution info - {'file': 'azure://leagueoflegends.blob.core.windows.net/match-details/2022/6/23/21.csv', 'status': 'LOADED', 'rows_parsed': 1000, 'rows_loaded': 1000, 'error_limit': 1, 'errors_seen': 0, 'first_error': None, 'first_error_line': None, 'first_error_character': None, 'first_error_column_name': None}
[2022-06-23 21:20:50,568] {snowflake.py:338} INFO - Rows affected: 1
[2022-06-23 21:20:50,569] {snowflake.py:339} INFO - Snowflake query id: 01a525c0-0000-fccb-0000-d9690005a47a
[2022-06-23 21:20:50,569] {connection.py:507} INFO - closed
[2022-06-23 21:20:50,613] {connection.py:510} INFO - No async queries seem to be running, deleting session
[2022-06-23 21:20:50,710] {azureToSnowflake.py:75} INFO - COPY command completed
[2022-06-23 21:20:50,722] {taskinstance.py:1272} INFO - Marking task as SUCCESS. dag_id=match_details_dag, task_id=azure_toSnowflake_paths.path_matchdetails.azure_matchdetails_snowflake, execution_date=20220620T000000, start_date=20220623T212048, end_date=20220623T212050
[2022-06-23 21:20:50,765] {local_task_job.py:154} INFO - Task exited with return code 0
[2022-06-23 21:20:50,812] {local_task_job.py:264} INFO - 0 downstream tasks scheduled from follow-on schedule check
[2022-06-23 21:58:16,069] {taskinstance.py:1037} INFO - Dependencies all met for <TaskInstance: match_details_dag.azure_toSnowflake_paths.path_matchdetails.azure_matchdetails_snowflake scheduled__2022-06-20T00:00:00+00:00 [queued]>
[2022-06-23 21:58:16,087] {taskinstance.py:1037} INFO - Dependencies all met for <TaskInstance: match_details_dag.azure_toSnowflake_paths.path_matchdetails.azure_matchdetails_snowflake scheduled__2022-06-20T00:00:00+00:00 [queued]>
[2022-06-23 21:58:16,088] {taskinstance.py:1243} INFO - 
--------------------------------------------------------------------------------
[2022-06-23 21:58:16,088] {taskinstance.py:1244} INFO - Starting attempt 1 of 2
[2022-06-23 21:58:16,088] {taskinstance.py:1245} INFO - 
--------------------------------------------------------------------------------
[2022-06-23 21:58:16,109] {taskinstance.py:1264} INFO - Executing <Task(AzureDataLakeToSnowflakeTransferOperator): azure_toSnowflake_paths.path_matchdetails.azure_matchdetails_snowflake> on 2022-06-20 00:00:00+00:00
[2022-06-23 21:58:16,116] {standard_task_runner.py:52} INFO - Started process 1453 to run task
[2022-06-23 21:58:16,120] {standard_task_runner.py:76} INFO - Running: ['***', 'tasks', 'run', 'match_details_dag', 'azure_toSnowflake_paths.path_matchdetails.azure_matchdetails_snowflake', 'scheduled__2022-06-20T00:00:00+00:00', '--job-id', '308', '--raw', '--subdir', 'DAGS_FOLDER/matchData_dag.py', '--cfg-path', '/tmp/tmprb4cmwqr', '--error-file', '/tmp/tmpobtn8tn6']
[2022-06-23 21:58:16,121] {standard_task_runner.py:77} INFO - Job 308: Subtask azure_toSnowflake_paths.path_matchdetails.azure_matchdetails_snowflake
[2022-06-23 21:58:16,198] {logging_mixin.py:109} INFO - Running <TaskInstance: match_details_dag.azure_toSnowflake_paths.path_matchdetails.azure_matchdetails_snowflake scheduled__2022-06-20T00:00:00+00:00 [running]> on host ebe3cc7dbee2
[2022-06-23 21:58:16,270] {taskinstance.py:1429} INFO - Exporting the following env vars:
AIRFLOW_CTX_DAG_OWNER=admin
AIRFLOW_CTX_DAG_ID=match_details_dag
AIRFLOW_CTX_TASK_ID=azure_toSnowflake_paths.path_matchdetails.azure_matchdetails_snowflake
AIRFLOW_CTX_EXECUTION_DATE=2022-06-20T00:00:00+00:00
AIRFLOW_CTX_DAG_RUN_ID=scheduled__2022-06-20T00:00:00+00:00
[2022-06-23 21:58:16,271] {azureToSnowflake.py:73} INFO - Executing COPY command...
[2022-06-23 21:58:16,284] {connection.py:257} INFO - Snowflake Connector for Python Version: 2.7.8, Python Version: 3.8.12, Platform: Linux-5.10.102.1-microsoft-standard-WSL2-x86_64-with-glibc2.2.5
[2022-06-23 21:58:16,285] {connection.py:876} INFO - This connection is in OCSP Fail Open Mode. TLS Certificates would be checked for validity and revocation status. Any other Certificate Revocation related exceptions or OCSP Responder failures would be disregarded in favor of connectivity.
[2022-06-23 21:58:16,285] {connection.py:894} INFO - Setting use_openssl_only mode to False
[2022-06-23 21:58:16,984] {cursor.py:710} INFO - query: [ALTER SESSION SET autocommit=True]
[2022-06-23 21:58:17,102] {cursor.py:734} INFO - query execution done
[2022-06-23 21:58:17,104] {snowflake.py:324} INFO - Running statement: COPY INTO STAGING_MATCHDETAILS
FROM @MY_AZURE_MATCH_DETAILS_STAGE/
files=('2022/6/23/21/GOLD.csv')
file_format=MATCH_DETAILS_FILEFORMAT, parameters: None
[2022-06-23 21:58:17,104] {cursor.py:710} INFO - query: [COPY INTO STAGING_MATCHDETAILS FROM @MY_AZURE_MATCH_DETAILS_STAGE/ files=('2022/...]
[2022-06-23 21:58:17,351] {cursor.py:734} INFO - query execution done
[2022-06-23 21:58:17,385] {connection.py:507} INFO - closed
[2022-06-23 21:58:17,433] {connection.py:510} INFO - No async queries seem to be running, deleting session
[2022-06-23 21:58:17,499] {taskinstance.py:1718} ERROR - Task failed with exception
Traceback (most recent call last):
  File "/home/airflow/.local/lib/python3.8/site-packages/airflow/models/taskinstance.py", line 1334, in _run_raw_task
    self._execute_task_with_callbacks(context)
  File "/home/airflow/.local/lib/python3.8/site-packages/airflow/models/taskinstance.py", line 1460, in _execute_task_with_callbacks
    result = self._execute_task(context, self.task)
  File "/home/airflow/.local/lib/python3.8/site-packages/airflow/models/taskinstance.py", line 1516, in _execute_task
    result = execute_callable(context=context)
  File "/opt/airflow/plugins/custom_transfers/azureToSnowflake.py", line 74, in execute
    snowflake_hook.run(copy_query, self.autocommit)
  File "/home/airflow/.local/lib/python3.8/site-packages/airflow/providers/snowflake/hooks/snowflake.py", line 328, in run
    cur.execute(sql_statement)
  File "/home/airflow/.local/lib/python3.8/site-packages/snowflake/connector/cursor.py", line 799, in execute
    Error.errorhandler_wrapper(self.connection, self, error_class, errvalue)
  File "/home/airflow/.local/lib/python3.8/site-packages/snowflake/connector/errors.py", line 273, in errorhandler_wrapper
    handed_over = Error.hand_to_other_handler(
  File "/home/airflow/.local/lib/python3.8/site-packages/snowflake/connector/errors.py", line 328, in hand_to_other_handler
    cursor.errorhandler(connection, cursor, error_class, error_value)
  File "/home/airflow/.local/lib/python3.8/site-packages/snowflake/connector/errors.py", line 207, in default_errorhandler
    raise error_class(
snowflake.connector.errors.ProgrammingError: 091016 (22000): 01a525e6-0000-fccb-0000-d9690005a5e6: Remote file 'azure://leagueoflegends.blob.core.windows.net/match-details/2022/6/23/21/GOLD.csv' was not found. If you are running a copy command, please make sure files are not deleted when they are being loaded or files are not being loaded into two different tables concurrently with auto purge option.
[2022-06-23 21:58:17,515] {taskinstance.py:1272} INFO - Marking task as UP_FOR_RETRY. dag_id=match_details_dag, task_id=azure_toSnowflake_paths.path_matchdetails.azure_matchdetails_snowflake, execution_date=20220620T000000, start_date=20220623T215816, end_date=20220623T215817
[2022-06-23 21:58:17,535] {standard_task_runner.py:89} ERROR - Failed to execute job 308 for task azure_toSnowflake_paths.path_matchdetails.azure_matchdetails_snowflake
Traceback (most recent call last):
  File "/home/airflow/.local/lib/python3.8/site-packages/airflow/task/task_runner/standard_task_runner.py", line 85, in _start_by_fork
    args.func(args, dag=self.dag)
  File "/home/airflow/.local/lib/python3.8/site-packages/airflow/cli/cli_parser.py", line 48, in command
    return func(*args, **kwargs)
  File "/home/airflow/.local/lib/python3.8/site-packages/airflow/utils/cli.py", line 92, in wrapper
    return f(*args, **kwargs)
  File "/home/airflow/.local/lib/python3.8/site-packages/airflow/cli/commands/task_command.py", line 298, in task_run
    _run_task_by_selected_method(args, dag, ti)
  File "/home/airflow/.local/lib/python3.8/site-packages/airflow/cli/commands/task_command.py", line 107, in _run_task_by_selected_method
    _run_raw_task(args, ti)
  File "/home/airflow/.local/lib/python3.8/site-packages/airflow/cli/commands/task_command.py", line 180, in _run_raw_task
    ti._run_raw_task(
  File "/home/airflow/.local/lib/python3.8/site-packages/airflow/utils/session.py", line 70, in wrapper
    return func(*args, session=session, **kwargs)
  File "/home/airflow/.local/lib/python3.8/site-packages/airflow/models/taskinstance.py", line 1334, in _run_raw_task
    self._execute_task_with_callbacks(context)
  File "/home/airflow/.local/lib/python3.8/site-packages/airflow/models/taskinstance.py", line 1460, in _execute_task_with_callbacks
    result = self._execute_task(context, self.task)
  File "/home/airflow/.local/lib/python3.8/site-packages/airflow/models/taskinstance.py", line 1516, in _execute_task
    result = execute_callable(context=context)
  File "/opt/airflow/plugins/custom_transfers/azureToSnowflake.py", line 74, in execute
    snowflake_hook.run(copy_query, self.autocommit)
  File "/home/airflow/.local/lib/python3.8/site-packages/airflow/providers/snowflake/hooks/snowflake.py", line 328, in run
    cur.execute(sql_statement)
  File "/home/airflow/.local/lib/python3.8/site-packages/snowflake/connector/cursor.py", line 799, in execute
    Error.errorhandler_wrapper(self.connection, self, error_class, errvalue)
  File "/home/airflow/.local/lib/python3.8/site-packages/snowflake/connector/errors.py", line 273, in errorhandler_wrapper
    handed_over = Error.hand_to_other_handler(
  File "/home/airflow/.local/lib/python3.8/site-packages/snowflake/connector/errors.py", line 328, in hand_to_other_handler
    cursor.errorhandler(connection, cursor, error_class, error_value)
  File "/home/airflow/.local/lib/python3.8/site-packages/snowflake/connector/errors.py", line 207, in default_errorhandler
    raise error_class(
snowflake.connector.errors.ProgrammingError: 091016 (22000): 01a525e6-0000-fccb-0000-d9690005a5e6: Remote file 'azure://leagueoflegends.blob.core.windows.net/match-details/2022/6/23/21/GOLD.csv' was not found. If you are running a copy command, please make sure files are not deleted when they are being loaded or files are not being loaded into two different tables concurrently with auto purge option.
[2022-06-23 21:58:17,579] {local_task_job.py:154} INFO - Task exited with return code 1
[2022-06-23 21:58:17,634] {local_task_job.py:264} INFO - 0 downstream tasks scheduled from follow-on schedule check
[2022-06-23 22:42:38,986] {taskinstance.py:1037} INFO - Dependencies all met for <TaskInstance: match_details_dag.azure_toSnowflake_paths.path_matchdetails.azure_matchdetails_snowflake scheduled__2022-06-20T00:00:00+00:00 [queued]>
[2022-06-23 22:42:38,997] {taskinstance.py:1037} INFO - Dependencies all met for <TaskInstance: match_details_dag.azure_toSnowflake_paths.path_matchdetails.azure_matchdetails_snowflake scheduled__2022-06-20T00:00:00+00:00 [queued]>
[2022-06-23 22:42:38,997] {taskinstance.py:1243} INFO - 
--------------------------------------------------------------------------------
[2022-06-23 22:42:38,997] {taskinstance.py:1244} INFO - Starting attempt 1 of 2
[2022-06-23 22:42:38,997] {taskinstance.py:1245} INFO - 
--------------------------------------------------------------------------------
[2022-06-23 22:42:39,007] {taskinstance.py:1264} INFO - Executing <Task(AzureDataLakeToSnowflakeTransferOperator): azure_toSnowflake_paths.path_matchdetails.azure_matchdetails_snowflake> on 2022-06-20 00:00:00+00:00
[2022-06-23 22:42:39,012] {standard_task_runner.py:52} INFO - Started process 85 to run task
[2022-06-23 22:42:39,014] {standard_task_runner.py:76} INFO - Running: ['***', 'tasks', 'run', 'match_details_dag', 'azure_toSnowflake_paths.path_matchdetails.azure_matchdetails_snowflake', 'scheduled__2022-06-20T00:00:00+00:00', '--job-id', '323', '--raw', '--subdir', 'DAGS_FOLDER/matchData_dag.py', '--cfg-path', '/tmp/tmpyq0hs5km', '--error-file', '/tmp/tmp3sz7b8oy']
[2022-06-23 22:42:39,015] {standard_task_runner.py:77} INFO - Job 323: Subtask azure_toSnowflake_paths.path_matchdetails.azure_matchdetails_snowflake
[2022-06-23 22:42:39,057] {logging_mixin.py:109} INFO - Running <TaskInstance: match_details_dag.azure_toSnowflake_paths.path_matchdetails.azure_matchdetails_snowflake scheduled__2022-06-20T00:00:00+00:00 [running]> on host ebe3cc7dbee2
[2022-06-23 22:42:39,101] {taskinstance.py:1429} INFO - Exporting the following env vars:
AIRFLOW_CTX_DAG_OWNER=admin
AIRFLOW_CTX_DAG_ID=match_details_dag
AIRFLOW_CTX_TASK_ID=azure_toSnowflake_paths.path_matchdetails.azure_matchdetails_snowflake
AIRFLOW_CTX_EXECUTION_DATE=2022-06-20T00:00:00+00:00
AIRFLOW_CTX_DAG_RUN_ID=scheduled__2022-06-20T00:00:00+00:00
[2022-06-23 22:42:39,101] {azureToSnowflake.py:73} INFO - Executing COPY command...
[2022-06-23 22:42:39,110] {connection.py:257} INFO - Snowflake Connector for Python Version: 2.7.8, Python Version: 3.8.12, Platform: Linux-5.10.102.1-microsoft-standard-WSL2-x86_64-with-glibc2.2.5
[2022-06-23 22:42:39,110] {connection.py:876} INFO - This connection is in OCSP Fail Open Mode. TLS Certificates would be checked for validity and revocation status. Any other Certificate Revocation related exceptions or OCSP Responder failures would be disregarded in favor of connectivity.
[2022-06-23 22:42:39,111] {connection.py:894} INFO - Setting use_openssl_only mode to False
[2022-06-23 22:42:39,584] {cursor.py:710} INFO - query: [ALTER SESSION SET autocommit=True]
[2022-06-23 22:42:39,708] {cursor.py:734} INFO - query execution done
[2022-06-23 22:42:39,709] {snowflake.py:324} INFO - Running statement: COPY INTO STAGING_MATCHDETAILS
FROM @MY_AZURE_MATCH_DETAILS_STAGE/
files=('GOLD/2022/6/23/22.csv')
file_format=MATCH_DETAILS_FILEFORMAT, parameters: None
[2022-06-23 22:42:39,709] {cursor.py:710} INFO - query: [COPY INTO STAGING_MATCHDETAILS FROM @MY_AZURE_MATCH_DETAILS_STAGE/ files=('GOLD/...]
[2022-06-23 22:42:41,505] {cursor.py:734} INFO - query execution done
[2022-06-23 22:42:41,510] {connection.py:507} INFO - closed
[2022-06-23 22:42:41,548] {connection.py:510} INFO - No async queries seem to be running, deleting session
[2022-06-23 22:42:41,614] {taskinstance.py:1718} ERROR - Task failed with exception
Traceback (most recent call last):
  File "/home/airflow/.local/lib/python3.8/site-packages/airflow/models/taskinstance.py", line 1334, in _run_raw_task
    self._execute_task_with_callbacks(context)
  File "/home/airflow/.local/lib/python3.8/site-packages/airflow/models/taskinstance.py", line 1460, in _execute_task_with_callbacks
    result = self._execute_task(context, self.task)
  File "/home/airflow/.local/lib/python3.8/site-packages/airflow/models/taskinstance.py", line 1516, in _execute_task
    result = execute_callable(context=context)
  File "/opt/airflow/plugins/custom_transfers/azureToSnowflake.py", line 74, in execute
    snowflake_hook.run(copy_query, self.autocommit)
  File "/home/airflow/.local/lib/python3.8/site-packages/airflow/providers/snowflake/hooks/snowflake.py", line 328, in run
    cur.execute(sql_statement)
  File "/home/airflow/.local/lib/python3.8/site-packages/snowflake/connector/cursor.py", line 799, in execute
    Error.errorhandler_wrapper(self.connection, self, error_class, errvalue)
  File "/home/airflow/.local/lib/python3.8/site-packages/snowflake/connector/errors.py", line 273, in errorhandler_wrapper
    handed_over = Error.hand_to_other_handler(
  File "/home/airflow/.local/lib/python3.8/site-packages/snowflake/connector/errors.py", line 328, in hand_to_other_handler
    cursor.errorhandler(connection, cursor, error_class, error_value)
  File "/home/airflow/.local/lib/python3.8/site-packages/snowflake/connector/errors.py", line 207, in default_errorhandler
    raise error_class(
snowflake.connector.errors.ProgrammingError: 100037 (22018): 01a52612-0000-fcc5-0000-d969000597b6: Boolean value '15988' is not recognized
  File 'GOLD/2022/6/23/22.csv', line 2, character 109
  Row 1, column "STAGING_MATCHDETAILS"["GAMEENDEDINSURRENDER":25]
  If you would like to continue loading when an error is encountered, use other values such as 'SKIP_FILE' or 'CONTINUE' for the ON_ERROR option. For more information on loading options, please run 'info loading_data' in a SQL client.
[2022-06-23 22:42:41,626] {taskinstance.py:1272} INFO - Marking task as UP_FOR_RETRY. dag_id=match_details_dag, task_id=azure_toSnowflake_paths.path_matchdetails.azure_matchdetails_snowflake, execution_date=20220620T000000, start_date=20220623T224238, end_date=20220623T224241
[2022-06-23 22:42:41,640] {standard_task_runner.py:89} ERROR - Failed to execute job 323 for task azure_toSnowflake_paths.path_matchdetails.azure_matchdetails_snowflake
Traceback (most recent call last):
  File "/home/airflow/.local/lib/python3.8/site-packages/airflow/task/task_runner/standard_task_runner.py", line 85, in _start_by_fork
    args.func(args, dag=self.dag)
  File "/home/airflow/.local/lib/python3.8/site-packages/airflow/cli/cli_parser.py", line 48, in command
    return func(*args, **kwargs)
  File "/home/airflow/.local/lib/python3.8/site-packages/airflow/utils/cli.py", line 92, in wrapper
    return f(*args, **kwargs)
  File "/home/airflow/.local/lib/python3.8/site-packages/airflow/cli/commands/task_command.py", line 298, in task_run
    _run_task_by_selected_method(args, dag, ti)
  File "/home/airflow/.local/lib/python3.8/site-packages/airflow/cli/commands/task_command.py", line 107, in _run_task_by_selected_method
    _run_raw_task(args, ti)
  File "/home/airflow/.local/lib/python3.8/site-packages/airflow/cli/commands/task_command.py", line 180, in _run_raw_task
    ti._run_raw_task(
  File "/home/airflow/.local/lib/python3.8/site-packages/airflow/utils/session.py", line 70, in wrapper
    return func(*args, session=session, **kwargs)
  File "/home/airflow/.local/lib/python3.8/site-packages/airflow/models/taskinstance.py", line 1334, in _run_raw_task
    self._execute_task_with_callbacks(context)
  File "/home/airflow/.local/lib/python3.8/site-packages/airflow/models/taskinstance.py", line 1460, in _execute_task_with_callbacks
    result = self._execute_task(context, self.task)
  File "/home/airflow/.local/lib/python3.8/site-packages/airflow/models/taskinstance.py", line 1516, in _execute_task
    result = execute_callable(context=context)
  File "/opt/airflow/plugins/custom_transfers/azureToSnowflake.py", line 74, in execute
    snowflake_hook.run(copy_query, self.autocommit)
  File "/home/airflow/.local/lib/python3.8/site-packages/airflow/providers/snowflake/hooks/snowflake.py", line 328, in run
    cur.execute(sql_statement)
  File "/home/airflow/.local/lib/python3.8/site-packages/snowflake/connector/cursor.py", line 799, in execute
    Error.errorhandler_wrapper(self.connection, self, error_class, errvalue)
  File "/home/airflow/.local/lib/python3.8/site-packages/snowflake/connector/errors.py", line 273, in errorhandler_wrapper
    handed_over = Error.hand_to_other_handler(
  File "/home/airflow/.local/lib/python3.8/site-packages/snowflake/connector/errors.py", line 328, in hand_to_other_handler
    cursor.errorhandler(connection, cursor, error_class, error_value)
  File "/home/airflow/.local/lib/python3.8/site-packages/snowflake/connector/errors.py", line 207, in default_errorhandler
    raise error_class(
snowflake.connector.errors.ProgrammingError: 100037 (22018): 01a52612-0000-fcc5-0000-d969000597b6: Boolean value '15988' is not recognized
  File 'GOLD/2022/6/23/22.csv', line 2, character 109
  Row 1, column "STAGING_MATCHDETAILS"["GAMEENDEDINSURRENDER":25]
  If you would like to continue loading when an error is encountered, use other values such as 'SKIP_FILE' or 'CONTINUE' for the ON_ERROR option. For more information on loading options, please run 'info loading_data' in a SQL client.
[2022-06-23 22:42:41,677] {local_task_job.py:154} INFO - Task exited with return code 1
[2022-06-23 22:42:41,713] {local_task_job.py:264} INFO - 0 downstream tasks scheduled from follow-on schedule check
[2022-06-24 00:10:36,616] {taskinstance.py:1037} INFO - Dependencies all met for <TaskInstance: match_details_dag.azure_toSnowflake_paths.path_matchdetails.azure_matchdetails_snowflake scheduled__2022-06-20T00:00:00+00:00 [queued]>
[2022-06-24 00:10:36,627] {taskinstance.py:1037} INFO - Dependencies all met for <TaskInstance: match_details_dag.azure_toSnowflake_paths.path_matchdetails.azure_matchdetails_snowflake scheduled__2022-06-20T00:00:00+00:00 [queued]>
[2022-06-24 00:10:36,627] {taskinstance.py:1243} INFO - 
--------------------------------------------------------------------------------
[2022-06-24 00:10:36,627] {taskinstance.py:1244} INFO - Starting attempt 1 of 2
[2022-06-24 00:10:36,627] {taskinstance.py:1245} INFO - 
--------------------------------------------------------------------------------
[2022-06-24 00:10:36,637] {taskinstance.py:1264} INFO - Executing <Task(AzureDataLakeToSnowflakeTransferOperator): azure_toSnowflake_paths.path_matchdetails.azure_matchdetails_snowflake> on 2022-06-20 00:00:00+00:00
[2022-06-24 00:10:36,642] {standard_task_runner.py:52} INFO - Started process 86 to run task
[2022-06-24 00:10:36,644] {standard_task_runner.py:76} INFO - Running: ['***', 'tasks', 'run', 'match_details_dag', 'azure_toSnowflake_paths.path_matchdetails.azure_matchdetails_snowflake', 'scheduled__2022-06-20T00:00:00+00:00', '--job-id', '337', '--raw', '--subdir', 'DAGS_FOLDER/matchData_dag.py', '--cfg-path', '/tmp/tmp5czy0v3m', '--error-file', '/tmp/tmpjdsd7c_u']
[2022-06-24 00:10:36,645] {standard_task_runner.py:77} INFO - Job 337: Subtask azure_toSnowflake_paths.path_matchdetails.azure_matchdetails_snowflake
[2022-06-24 00:10:36,686] {logging_mixin.py:109} INFO - Running <TaskInstance: match_details_dag.azure_toSnowflake_paths.path_matchdetails.azure_matchdetails_snowflake scheduled__2022-06-20T00:00:00+00:00 [running]> on host ebe3cc7dbee2
[2022-06-24 00:10:36,731] {taskinstance.py:1429} INFO - Exporting the following env vars:
AIRFLOW_CTX_DAG_OWNER=admin
AIRFLOW_CTX_DAG_ID=match_details_dag
AIRFLOW_CTX_TASK_ID=azure_toSnowflake_paths.path_matchdetails.azure_matchdetails_snowflake
AIRFLOW_CTX_EXECUTION_DATE=2022-06-20T00:00:00+00:00
AIRFLOW_CTX_DAG_RUN_ID=scheduled__2022-06-20T00:00:00+00:00
[2022-06-24 00:10:36,732] {azureToSnowflake.py:73} INFO - Executing COPY command...
[2022-06-24 00:10:36,739] {connection.py:257} INFO - Snowflake Connector for Python Version: 2.7.8, Python Version: 3.8.12, Platform: Linux-5.10.102.1-microsoft-standard-WSL2-x86_64-with-glibc2.2.5
[2022-06-24 00:10:36,740] {connection.py:876} INFO - This connection is in OCSP Fail Open Mode. TLS Certificates would be checked for validity and revocation status. Any other Certificate Revocation related exceptions or OCSP Responder failures would be disregarded in favor of connectivity.
[2022-06-24 00:10:36,740] {connection.py:894} INFO - Setting use_openssl_only mode to False
[2022-06-24 00:10:37,289] {cursor.py:710} INFO - query: [ALTER SESSION SET autocommit=True]
[2022-06-24 00:10:37,370] {cursor.py:734} INFO - query execution done
[2022-06-24 00:10:37,371] {snowflake.py:324} INFO - Running statement: COPY INTO STAGING_MATCHDETAILS
FROM @MY_AZURE_MATCH_DETAILS_STAGE/
files=('GOLD/2022/6/24/0.csv')
file_format=MATCH_DETAILS_FILEFORMAT, parameters: None
[2022-06-24 00:10:37,372] {cursor.py:710} INFO - query: [COPY INTO STAGING_MATCHDETAILS FROM @MY_AZURE_MATCH_DETAILS_STAGE/ files=('GOLD/...]
[2022-06-24 00:10:39,034] {cursor.py:734} INFO - query execution done
[2022-06-24 00:10:39,040] {connection.py:507} INFO - closed
[2022-06-24 00:10:39,076] {connection.py:510} INFO - No async queries seem to be running, deleting session
[2022-06-24 00:10:39,136] {taskinstance.py:1718} ERROR - Task failed with exception
Traceback (most recent call last):
  File "/home/airflow/.local/lib/python3.8/site-packages/airflow/models/taskinstance.py", line 1334, in _run_raw_task
    self._execute_task_with_callbacks(context)
  File "/home/airflow/.local/lib/python3.8/site-packages/airflow/models/taskinstance.py", line 1460, in _execute_task_with_callbacks
    result = self._execute_task(context, self.task)
  File "/home/airflow/.local/lib/python3.8/site-packages/airflow/models/taskinstance.py", line 1516, in _execute_task
    result = execute_callable(context=context)
  File "/opt/airflow/plugins/custom_transfers/azureToSnowflake.py", line 74, in execute
    snowflake_hook.run(copy_query, self.autocommit)
  File "/home/airflow/.local/lib/python3.8/site-packages/airflow/providers/snowflake/hooks/snowflake.py", line 328, in run
    cur.execute(sql_statement)
  File "/home/airflow/.local/lib/python3.8/site-packages/snowflake/connector/cursor.py", line 799, in execute
    Error.errorhandler_wrapper(self.connection, self, error_class, errvalue)
  File "/home/airflow/.local/lib/python3.8/site-packages/snowflake/connector/errors.py", line 273, in errorhandler_wrapper
    handed_over = Error.hand_to_other_handler(
  File "/home/airflow/.local/lib/python3.8/site-packages/snowflake/connector/errors.py", line 328, in hand_to_other_handler
    cursor.errorhandler(connection, cursor, error_class, error_value)
  File "/home/airflow/.local/lib/python3.8/site-packages/snowflake/connector/errors.py", line 207, in default_errorhandler
    raise error_class(
snowflake.connector.errors.ProgrammingError: 100037 (22018): 01a5266a-0000-fcc5-0000-d96900059832: Boolean value '15988' is not recognized
  File 'GOLD/2022/6/24/0.csv', line 2, character 109
  Row 1, column "STAGING_MATCHDETAILS"["GAMEENDEDINSURRENDER":25]
  If you would like to continue loading when an error is encountered, use other values such as 'SKIP_FILE' or 'CONTINUE' for the ON_ERROR option. For more information on loading options, please run 'info loading_data' in a SQL client.
[2022-06-24 00:10:39,147] {taskinstance.py:1272} INFO - Marking task as UP_FOR_RETRY. dag_id=match_details_dag, task_id=azure_toSnowflake_paths.path_matchdetails.azure_matchdetails_snowflake, execution_date=20220620T000000, start_date=20220624T001036, end_date=20220624T001039
[2022-06-24 00:10:39,160] {standard_task_runner.py:89} ERROR - Failed to execute job 337 for task azure_toSnowflake_paths.path_matchdetails.azure_matchdetails_snowflake
Traceback (most recent call last):
  File "/home/airflow/.local/lib/python3.8/site-packages/airflow/task/task_runner/standard_task_runner.py", line 85, in _start_by_fork
    args.func(args, dag=self.dag)
  File "/home/airflow/.local/lib/python3.8/site-packages/airflow/cli/cli_parser.py", line 48, in command
    return func(*args, **kwargs)
  File "/home/airflow/.local/lib/python3.8/site-packages/airflow/utils/cli.py", line 92, in wrapper
    return f(*args, **kwargs)
  File "/home/airflow/.local/lib/python3.8/site-packages/airflow/cli/commands/task_command.py", line 298, in task_run
    _run_task_by_selected_method(args, dag, ti)
  File "/home/airflow/.local/lib/python3.8/site-packages/airflow/cli/commands/task_command.py", line 107, in _run_task_by_selected_method
    _run_raw_task(args, ti)
  File "/home/airflow/.local/lib/python3.8/site-packages/airflow/cli/commands/task_command.py", line 180, in _run_raw_task
    ti._run_raw_task(
  File "/home/airflow/.local/lib/python3.8/site-packages/airflow/utils/session.py", line 70, in wrapper
    return func(*args, session=session, **kwargs)
  File "/home/airflow/.local/lib/python3.8/site-packages/airflow/models/taskinstance.py", line 1334, in _run_raw_task
    self._execute_task_with_callbacks(context)
  File "/home/airflow/.local/lib/python3.8/site-packages/airflow/models/taskinstance.py", line 1460, in _execute_task_with_callbacks
    result = self._execute_task(context, self.task)
  File "/home/airflow/.local/lib/python3.8/site-packages/airflow/models/taskinstance.py", line 1516, in _execute_task
    result = execute_callable(context=context)
  File "/opt/airflow/plugins/custom_transfers/azureToSnowflake.py", line 74, in execute
    snowflake_hook.run(copy_query, self.autocommit)
  File "/home/airflow/.local/lib/python3.8/site-packages/airflow/providers/snowflake/hooks/snowflake.py", line 328, in run
    cur.execute(sql_statement)
  File "/home/airflow/.local/lib/python3.8/site-packages/snowflake/connector/cursor.py", line 799, in execute
    Error.errorhandler_wrapper(self.connection, self, error_class, errvalue)
  File "/home/airflow/.local/lib/python3.8/site-packages/snowflake/connector/errors.py", line 273, in errorhandler_wrapper
    handed_over = Error.hand_to_other_handler(
  File "/home/airflow/.local/lib/python3.8/site-packages/snowflake/connector/errors.py", line 328, in hand_to_other_handler
    cursor.errorhandler(connection, cursor, error_class, error_value)
  File "/home/airflow/.local/lib/python3.8/site-packages/snowflake/connector/errors.py", line 207, in default_errorhandler
    raise error_class(
snowflake.connector.errors.ProgrammingError: 100037 (22018): 01a5266a-0000-fcc5-0000-d96900059832: Boolean value '15988' is not recognized
  File 'GOLD/2022/6/24/0.csv', line 2, character 109
  Row 1, column "STAGING_MATCHDETAILS"["GAMEENDEDINSURRENDER":25]
  If you would like to continue loading when an error is encountered, use other values such as 'SKIP_FILE' or 'CONTINUE' for the ON_ERROR option. For more information on loading options, please run 'info loading_data' in a SQL client.
[2022-06-24 00:10:39,188] {local_task_job.py:154} INFO - Task exited with return code 1
[2022-06-24 00:10:39,226] {local_task_job.py:264} INFO - 0 downstream tasks scheduled from follow-on schedule check
[2022-06-24 03:58:15,033] {taskinstance.py:1037} INFO - Dependencies all met for <TaskInstance: match_details_dag.azure_toSnowflake_paths.path_matchdetails.azure_matchdetails_snowflake scheduled__2022-06-20T00:00:00+00:00 [None]>
[2022-06-24 03:58:15,049] {taskinstance.py:1037} INFO - Dependencies all met for <TaskInstance: match_details_dag.azure_toSnowflake_paths.path_matchdetails.azure_matchdetails_snowflake scheduled__2022-06-20T00:00:00+00:00 [None]>
[2022-06-24 03:58:15,050] {taskinstance.py:1243} INFO - 
--------------------------------------------------------------------------------
[2022-06-24 03:58:15,050] {taskinstance.py:1244} INFO - Starting attempt 1 of 2
[2022-06-24 03:58:15,050] {taskinstance.py:1245} INFO - 
--------------------------------------------------------------------------------
[2022-06-24 03:58:15,067] {taskinstance.py:1264} INFO - Executing <Task(AzureDataLakeToSnowflakeTransferOperator): azure_toSnowflake_paths.path_matchdetails.azure_matchdetails_snowflake> on 2022-06-20 00:00:00+00:00
[2022-06-24 03:58:15,074] {standard_task_runner.py:52} INFO - Started process 92 to run task
[2022-06-24 03:58:15,079] {standard_task_runner.py:76} INFO - Running: ['***', 'tasks', 'run', 'match_details_dag', 'azure_toSnowflake_paths.path_matchdetails.azure_matchdetails_snowflake', 'scheduled__2022-06-20T00:00:00+00:00', '--job-id', '9', '--pool', 'default_pool', '--raw', '--subdir', 'DAGS_FOLDER/matchData_dag.py', '--cfg-path', '/tmp/tmp8iywm8yp', '--error-file', '/tmp/tmpr1qoeoak']
[2022-06-24 03:58:15,080] {standard_task_runner.py:77} INFO - Job 9: Subtask azure_toSnowflake_paths.path_matchdetails.azure_matchdetails_snowflake
[2022-06-24 03:58:15,142] {logging_mixin.py:109} INFO - Running <TaskInstance: match_details_dag.azure_toSnowflake_paths.path_matchdetails.azure_matchdetails_snowflake scheduled__2022-06-20T00:00:00+00:00 [running]> on host 0d320c1110d2
[2022-06-24 03:58:15,200] {taskinstance.py:1429} INFO - Exporting the following env vars:
AIRFLOW_CTX_DAG_OWNER=admin
AIRFLOW_CTX_DAG_ID=match_details_dag
AIRFLOW_CTX_TASK_ID=azure_toSnowflake_paths.path_matchdetails.azure_matchdetails_snowflake
AIRFLOW_CTX_EXECUTION_DATE=2022-06-20T00:00:00+00:00
AIRFLOW_CTX_DAG_RUN_ID=scheduled__2022-06-20T00:00:00+00:00
[2022-06-24 03:58:15,201] {azureToSnowflake.py:73} INFO - Executing COPY command...
[2022-06-24 03:58:15,213] {connection.py:257} INFO - Snowflake Connector for Python Version: 2.7.8, Python Version: 3.8.12, Platform: Linux-5.10.102.1-microsoft-standard-WSL2-x86_64-with-glibc2.2.5
[2022-06-24 03:58:15,214] {connection.py:876} INFO - This connection is in OCSP Fail Open Mode. TLS Certificates would be checked for validity and revocation status. Any other Certificate Revocation related exceptions or OCSP Responder failures would be disregarded in favor of connectivity.
[2022-06-24 03:58:15,214] {connection.py:894} INFO - Setting use_openssl_only mode to False
[2022-06-24 03:58:16,148] {cursor.py:710} INFO - query: [ALTER SESSION SET autocommit=True]
[2022-06-24 03:58:16,410] {cursor.py:734} INFO - query execution done
[2022-06-24 03:58:16,411] {snowflake.py:324} INFO - Running statement: COPY INTO STAGING_MATCHDETAILS
FROM @MY_AZURE_MATCH_DETAILS_STAGE/
files=('GOLD/2022/6/24/3.csv')
file_format=MATCH_DETAILS_FILEFORMAT, parameters: None
[2022-06-24 03:58:16,412] {cursor.py:710} INFO - query: [COPY INTO STAGING_MATCHDETAILS FROM @MY_AZURE_MATCH_DETAILS_STAGE/ files=('GOLD/...]
[2022-06-24 03:58:17,511] {cursor.py:734} INFO - query execution done
[2022-06-24 03:58:17,521] {connection.py:507} INFO - closed
[2022-06-24 03:58:17,563] {connection.py:510} INFO - No async queries seem to be running, deleting session
[2022-06-24 03:58:17,630] {taskinstance.py:1718} ERROR - Task failed with exception
Traceback (most recent call last):
  File "/home/airflow/.local/lib/python3.8/site-packages/airflow/models/taskinstance.py", line 1334, in _run_raw_task
    self._execute_task_with_callbacks(context)
  File "/home/airflow/.local/lib/python3.8/site-packages/airflow/models/taskinstance.py", line 1460, in _execute_task_with_callbacks
    result = self._execute_task(context, self.task)
  File "/home/airflow/.local/lib/python3.8/site-packages/airflow/models/taskinstance.py", line 1516, in _execute_task
    result = execute_callable(context=context)
  File "/opt/airflow/plugins/custom_transfers/azureToSnowflake.py", line 74, in execute
    snowflake_hook.run(copy_query, self.autocommit)
  File "/home/airflow/.local/lib/python3.8/site-packages/airflow/providers/snowflake/hooks/snowflake.py", line 328, in run
    cur.execute(sql_statement)
  File "/home/airflow/.local/lib/python3.8/site-packages/snowflake/connector/cursor.py", line 799, in execute
    Error.errorhandler_wrapper(self.connection, self, error_class, errvalue)
  File "/home/airflow/.local/lib/python3.8/site-packages/snowflake/connector/errors.py", line 273, in errorhandler_wrapper
    handed_over = Error.hand_to_other_handler(
  File "/home/airflow/.local/lib/python3.8/site-packages/snowflake/connector/errors.py", line 328, in hand_to_other_handler
    cursor.errorhandler(connection, cursor, error_class, error_value)
  File "/home/airflow/.local/lib/python3.8/site-packages/snowflake/connector/errors.py", line 207, in default_errorhandler
    raise error_class(
snowflake.connector.errors.ProgrammingError: 100037 (22018): 01a5274e-0000-fccb-0000-d9690005a96e: Boolean value '15988' is not recognized
  File 'GOLD/2022/6/24/3.csv', line 2, character 109
  Row 1, column "STAGING_MATCHDETAILS"["GAMEENDEDINSURRENDER":25]
  If you would like to continue loading when an error is encountered, use other values such as 'SKIP_FILE' or 'CONTINUE' for the ON_ERROR option. For more information on loading options, please run 'info loading_data' in a SQL client.
[2022-06-24 03:58:17,651] {taskinstance.py:1272} INFO - Marking task as UP_FOR_RETRY. dag_id=match_details_dag, task_id=azure_toSnowflake_paths.path_matchdetails.azure_matchdetails_snowflake, execution_date=20220620T000000, start_date=20220624T035815, end_date=20220624T035817
[2022-06-24 03:58:17,672] {standard_task_runner.py:89} ERROR - Failed to execute job 9 for task azure_toSnowflake_paths.path_matchdetails.azure_matchdetails_snowflake
Traceback (most recent call last):
  File "/home/airflow/.local/lib/python3.8/site-packages/airflow/task/task_runner/standard_task_runner.py", line 85, in _start_by_fork
    args.func(args, dag=self.dag)
  File "/home/airflow/.local/lib/python3.8/site-packages/airflow/cli/cli_parser.py", line 48, in command
    return func(*args, **kwargs)
  File "/home/airflow/.local/lib/python3.8/site-packages/airflow/utils/cli.py", line 92, in wrapper
    return f(*args, **kwargs)
  File "/home/airflow/.local/lib/python3.8/site-packages/airflow/cli/commands/task_command.py", line 298, in task_run
    _run_task_by_selected_method(args, dag, ti)
  File "/home/airflow/.local/lib/python3.8/site-packages/airflow/cli/commands/task_command.py", line 107, in _run_task_by_selected_method
    _run_raw_task(args, ti)
  File "/home/airflow/.local/lib/python3.8/site-packages/airflow/cli/commands/task_command.py", line 180, in _run_raw_task
    ti._run_raw_task(
  File "/home/airflow/.local/lib/python3.8/site-packages/airflow/utils/session.py", line 70, in wrapper
    return func(*args, session=session, **kwargs)
  File "/home/airflow/.local/lib/python3.8/site-packages/airflow/models/taskinstance.py", line 1334, in _run_raw_task
    self._execute_task_with_callbacks(context)
  File "/home/airflow/.local/lib/python3.8/site-packages/airflow/models/taskinstance.py", line 1460, in _execute_task_with_callbacks
    result = self._execute_task(context, self.task)
  File "/home/airflow/.local/lib/python3.8/site-packages/airflow/models/taskinstance.py", line 1516, in _execute_task
    result = execute_callable(context=context)
  File "/opt/airflow/plugins/custom_transfers/azureToSnowflake.py", line 74, in execute
    snowflake_hook.run(copy_query, self.autocommit)
  File "/home/airflow/.local/lib/python3.8/site-packages/airflow/providers/snowflake/hooks/snowflake.py", line 328, in run
    cur.execute(sql_statement)
  File "/home/airflow/.local/lib/python3.8/site-packages/snowflake/connector/cursor.py", line 799, in execute
    Error.errorhandler_wrapper(self.connection, self, error_class, errvalue)
  File "/home/airflow/.local/lib/python3.8/site-packages/snowflake/connector/errors.py", line 273, in errorhandler_wrapper
    handed_over = Error.hand_to_other_handler(
  File "/home/airflow/.local/lib/python3.8/site-packages/snowflake/connector/errors.py", line 328, in hand_to_other_handler
    cursor.errorhandler(connection, cursor, error_class, error_value)
  File "/home/airflow/.local/lib/python3.8/site-packages/snowflake/connector/errors.py", line 207, in default_errorhandler
    raise error_class(
snowflake.connector.errors.ProgrammingError: 100037 (22018): 01a5274e-0000-fccb-0000-d9690005a96e: Boolean value '15988' is not recognized
  File 'GOLD/2022/6/24/3.csv', line 2, character 109
  Row 1, column "STAGING_MATCHDETAILS"["GAMEENDEDINSURRENDER":25]
  If you would like to continue loading when an error is encountered, use other values such as 'SKIP_FILE' or 'CONTINUE' for the ON_ERROR option. For more information on loading options, please run 'info loading_data' in a SQL client.
[2022-06-24 03:58:17,704] {local_task_job.py:154} INFO - Task exited with return code 1
[2022-06-24 03:58:17,759] {local_task_job.py:264} INFO - 0 downstream tasks scheduled from follow-on schedule check
[2022-06-28 05:17:27,842] {taskinstance.py:1037} INFO - Dependencies all met for <TaskInstance: match_details_dag.azure_toSnowflake_paths.path_matchdetails.azure_matchdetails_snowflake scheduled__2022-06-20T00:00:00+00:00 [queued]>
[2022-06-28 05:17:27,853] {taskinstance.py:1037} INFO - Dependencies all met for <TaskInstance: match_details_dag.azure_toSnowflake_paths.path_matchdetails.azure_matchdetails_snowflake scheduled__2022-06-20T00:00:00+00:00 [queued]>
[2022-06-28 05:17:27,853] {taskinstance.py:1243} INFO - 
--------------------------------------------------------------------------------
[2022-06-28 05:17:27,853] {taskinstance.py:1244} INFO - Starting attempt 1 of 2
[2022-06-28 05:17:27,853] {taskinstance.py:1245} INFO - 
--------------------------------------------------------------------------------
[2022-06-28 05:17:27,863] {taskinstance.py:1264} INFO - Executing <Task(AzureDataLakeToSnowflakeTransferOperator): azure_toSnowflake_paths.path_matchdetails.azure_matchdetails_snowflake> on 2022-06-20 00:00:00+00:00
[2022-06-28 05:17:27,868] {standard_task_runner.py:52} INFO - Started process 85 to run task
[2022-06-28 05:17:27,870] {standard_task_runner.py:76} INFO - Running: ['***', 'tasks', 'run', 'match_details_dag', 'azure_toSnowflake_paths.path_matchdetails.azure_matchdetails_snowflake', 'scheduled__2022-06-20T00:00:00+00:00', '--job-id', '20', '--raw', '--subdir', 'DAGS_FOLDER/matchData_dag.py', '--cfg-path', '/tmp/tmpkg8y784p', '--error-file', '/tmp/tmp6v0tkxgy']
[2022-06-28 05:17:27,871] {standard_task_runner.py:77} INFO - Job 20: Subtask azure_toSnowflake_paths.path_matchdetails.azure_matchdetails_snowflake
[2022-06-28 05:17:27,913] {logging_mixin.py:109} INFO - Running <TaskInstance: match_details_dag.azure_toSnowflake_paths.path_matchdetails.azure_matchdetails_snowflake scheduled__2022-06-20T00:00:00+00:00 [running]> on host 0d320c1110d2
[2022-06-28 05:17:27,959] {taskinstance.py:1429} INFO - Exporting the following env vars:
AIRFLOW_CTX_DAG_OWNER=admin
AIRFLOW_CTX_DAG_ID=match_details_dag
AIRFLOW_CTX_TASK_ID=azure_toSnowflake_paths.path_matchdetails.azure_matchdetails_snowflake
AIRFLOW_CTX_EXECUTION_DATE=2022-06-20T00:00:00+00:00
AIRFLOW_CTX_DAG_RUN_ID=scheduled__2022-06-20T00:00:00+00:00
[2022-06-28 05:17:27,959] {azureToSnowflake.py:73} INFO - Executing COPY command...
[2022-06-28 05:17:27,968] {connection.py:257} INFO - Snowflake Connector for Python Version: 2.7.8, Python Version: 3.8.12, Platform: Linux-5.10.102.1-microsoft-standard-WSL2-x86_64-with-glibc2.2.5
[2022-06-28 05:17:27,969] {connection.py:876} INFO - This connection is in OCSP Fail Open Mode. TLS Certificates would be checked for validity and revocation status. Any other Certificate Revocation related exceptions or OCSP Responder failures would be disregarded in favor of connectivity.
[2022-06-28 05:17:27,969] {connection.py:894} INFO - Setting use_openssl_only mode to False
[2022-06-28 05:17:28,457] {cursor.py:710} INFO - query: [ALTER SESSION SET autocommit=True]
[2022-06-28 05:17:28,550] {cursor.py:734} INFO - query execution done
[2022-06-28 05:17:28,551] {snowflake.py:324} INFO - Running statement: COPY INTO STAGING_MATCHDETAILS
FROM @MY_AZURE_MATCH_DETAILS_STAGE/
files=('GOLD/2022/6/28/5.csv')
file_format=MATCH_DETAILS_FILEFORMAT, parameters: None
[2022-06-28 05:17:28,551] {cursor.py:710} INFO - query: [COPY INTO STAGING_MATCHDETAILS FROM @MY_AZURE_MATCH_DETAILS_STAGE/ files=('GOLD/...]
[2022-06-28 05:17:30,083] {cursor.py:734} INFO - query execution done
[2022-06-28 05:17:30,091] {connection.py:507} INFO - closed
[2022-06-28 05:17:30,130] {connection.py:510} INFO - No async queries seem to be running, deleting session
[2022-06-28 05:17:30,195] {taskinstance.py:1718} ERROR - Task failed with exception
Traceback (most recent call last):
  File "/home/airflow/.local/lib/python3.8/site-packages/airflow/models/taskinstance.py", line 1334, in _run_raw_task
    self._execute_task_with_callbacks(context)
  File "/home/airflow/.local/lib/python3.8/site-packages/airflow/models/taskinstance.py", line 1460, in _execute_task_with_callbacks
    result = self._execute_task(context, self.task)
  File "/home/airflow/.local/lib/python3.8/site-packages/airflow/models/taskinstance.py", line 1516, in _execute_task
    result = execute_callable(context=context)
  File "/opt/airflow/plugins/custom_transfers/azureToSnowflake.py", line 74, in execute
    snowflake_hook.run(copy_query, self.autocommit)
  File "/home/airflow/.local/lib/python3.8/site-packages/airflow/providers/snowflake/hooks/snowflake.py", line 328, in run
    cur.execute(sql_statement)
  File "/home/airflow/.local/lib/python3.8/site-packages/snowflake/connector/cursor.py", line 799, in execute
    Error.errorhandler_wrapper(self.connection, self, error_class, errvalue)
  File "/home/airflow/.local/lib/python3.8/site-packages/snowflake/connector/errors.py", line 273, in errorhandler_wrapper
    handed_over = Error.hand_to_other_handler(
  File "/home/airflow/.local/lib/python3.8/site-packages/snowflake/connector/errors.py", line 328, in hand_to_other_handler
    cursor.errorhandler(connection, cursor, error_class, error_value)
  File "/home/airflow/.local/lib/python3.8/site-packages/snowflake/connector/errors.py", line 207, in default_errorhandler
    raise error_class(
snowflake.connector.errors.ProgrammingError: 100037 (22018): 01a53e1d-0000-fe3a-0000-d9690005fde6: Boolean value '15988' is not recognized
  File 'GOLD/2022/6/28/5.csv', line 2, character 109
  Row 1, column "STAGING_MATCHDETAILS"["GAMEENDEDINSURRENDER":25]
  If you would like to continue loading when an error is encountered, use other values such as 'SKIP_FILE' or 'CONTINUE' for the ON_ERROR option. For more information on loading options, please run 'info loading_data' in a SQL client.
[2022-06-28 05:17:30,208] {taskinstance.py:1272} INFO - Marking task as UP_FOR_RETRY. dag_id=match_details_dag, task_id=azure_toSnowflake_paths.path_matchdetails.azure_matchdetails_snowflake, execution_date=20220620T000000, start_date=20220628T051727, end_date=20220628T051730
[2022-06-28 05:17:30,225] {standard_task_runner.py:89} ERROR - Failed to execute job 20 for task azure_toSnowflake_paths.path_matchdetails.azure_matchdetails_snowflake
Traceback (most recent call last):
  File "/home/airflow/.local/lib/python3.8/site-packages/airflow/task/task_runner/standard_task_runner.py", line 85, in _start_by_fork
    args.func(args, dag=self.dag)
  File "/home/airflow/.local/lib/python3.8/site-packages/airflow/cli/cli_parser.py", line 48, in command
    return func(*args, **kwargs)
  File "/home/airflow/.local/lib/python3.8/site-packages/airflow/utils/cli.py", line 92, in wrapper
    return f(*args, **kwargs)
  File "/home/airflow/.local/lib/python3.8/site-packages/airflow/cli/commands/task_command.py", line 298, in task_run
    _run_task_by_selected_method(args, dag, ti)
  File "/home/airflow/.local/lib/python3.8/site-packages/airflow/cli/commands/task_command.py", line 107, in _run_task_by_selected_method
    _run_raw_task(args, ti)
  File "/home/airflow/.local/lib/python3.8/site-packages/airflow/cli/commands/task_command.py", line 180, in _run_raw_task
    ti._run_raw_task(
  File "/home/airflow/.local/lib/python3.8/site-packages/airflow/utils/session.py", line 70, in wrapper
    return func(*args, session=session, **kwargs)
  File "/home/airflow/.local/lib/python3.8/site-packages/airflow/models/taskinstance.py", line 1334, in _run_raw_task
    self._execute_task_with_callbacks(context)
  File "/home/airflow/.local/lib/python3.8/site-packages/airflow/models/taskinstance.py", line 1460, in _execute_task_with_callbacks
    result = self._execute_task(context, self.task)
  File "/home/airflow/.local/lib/python3.8/site-packages/airflow/models/taskinstance.py", line 1516, in _execute_task
    result = execute_callable(context=context)
  File "/opt/airflow/plugins/custom_transfers/azureToSnowflake.py", line 74, in execute
    snowflake_hook.run(copy_query, self.autocommit)
  File "/home/airflow/.local/lib/python3.8/site-packages/airflow/providers/snowflake/hooks/snowflake.py", line 328, in run
    cur.execute(sql_statement)
  File "/home/airflow/.local/lib/python3.8/site-packages/snowflake/connector/cursor.py", line 799, in execute
    Error.errorhandler_wrapper(self.connection, self, error_class, errvalue)
  File "/home/airflow/.local/lib/python3.8/site-packages/snowflake/connector/errors.py", line 273, in errorhandler_wrapper
    handed_over = Error.hand_to_other_handler(
  File "/home/airflow/.local/lib/python3.8/site-packages/snowflake/connector/errors.py", line 328, in hand_to_other_handler
    cursor.errorhandler(connection, cursor, error_class, error_value)
  File "/home/airflow/.local/lib/python3.8/site-packages/snowflake/connector/errors.py", line 207, in default_errorhandler
    raise error_class(
snowflake.connector.errors.ProgrammingError: 100037 (22018): 01a53e1d-0000-fe3a-0000-d9690005fde6: Boolean value '15988' is not recognized
  File 'GOLD/2022/6/28/5.csv', line 2, character 109
  Row 1, column "STAGING_MATCHDETAILS"["GAMEENDEDINSURRENDER":25]
  If you would like to continue loading when an error is encountered, use other values such as 'SKIP_FILE' or 'CONTINUE' for the ON_ERROR option. For more information on loading options, please run 'info loading_data' in a SQL client.
[2022-06-28 05:17:30,254] {local_task_job.py:154} INFO - Task exited with return code 1
[2022-06-28 05:17:30,291] {local_task_job.py:264} INFO - 0 downstream tasks scheduled from follow-on schedule check
