[2022-06-23 23:09:09,013] {taskinstance.py:1037} INFO - Dependencies all met for <TaskInstance: match_details_dag.azure_toSnowflake_paths.path_matchdetails.azure_matchdetails_snowflake scheduled__2022-06-20T00:00:00+00:00 [None]>
[2022-06-23 23:09:09,022] {taskinstance.py:1037} INFO - Dependencies all met for <TaskInstance: match_details_dag.azure_toSnowflake_paths.path_matchdetails.azure_matchdetails_snowflake scheduled__2022-06-20T00:00:00+00:00 [None]>
[2022-06-23 23:09:09,022] {taskinstance.py:1243} INFO - 
--------------------------------------------------------------------------------
[2022-06-23 23:09:09,022] {taskinstance.py:1244} INFO - Starting attempt 4 of 5
[2022-06-23 23:09:09,022] {taskinstance.py:1245} INFO - 
--------------------------------------------------------------------------------
[2022-06-23 23:09:09,033] {taskinstance.py:1264} INFO - Executing <Task(AzureDataLakeToSnowflakeTransferOperator): azure_toSnowflake_paths.path_matchdetails.azure_matchdetails_snowflake> on 2022-06-20 00:00:00+00:00
[2022-06-23 23:09:09,038] {standard_task_runner.py:52} INFO - Started process 111 to run task
[2022-06-23 23:09:09,040] {standard_task_runner.py:76} INFO - Running: ['***', 'tasks', 'run', 'match_details_dag', 'azure_toSnowflake_paths.path_matchdetails.azure_matchdetails_snowflake', 'scheduled__2022-06-20T00:00:00+00:00', '--job-id', '329', '--pool', 'default_pool', '--raw', '--subdir', 'DAGS_FOLDER/matchData_dag.py', '--cfg-path', '/tmp/tmp3hmp979o', '--error-file', '/tmp/tmp3utxkj_l']
[2022-06-23 23:09:09,041] {standard_task_runner.py:77} INFO - Job 329: Subtask azure_toSnowflake_paths.path_matchdetails.azure_matchdetails_snowflake
[2022-06-23 23:09:09,082] {logging_mixin.py:109} INFO - Running <TaskInstance: match_details_dag.azure_toSnowflake_paths.path_matchdetails.azure_matchdetails_snowflake scheduled__2022-06-20T00:00:00+00:00 [running]> on host ebe3cc7dbee2
[2022-06-23 23:09:09,122] {taskinstance.py:1429} INFO - Exporting the following env vars:
AIRFLOW_CTX_DAG_OWNER=admin
AIRFLOW_CTX_DAG_ID=match_details_dag
AIRFLOW_CTX_TASK_ID=azure_toSnowflake_paths.path_matchdetails.azure_matchdetails_snowflake
AIRFLOW_CTX_EXECUTION_DATE=2022-06-20T00:00:00+00:00
AIRFLOW_CTX_DAG_RUN_ID=scheduled__2022-06-20T00:00:00+00:00
[2022-06-23 23:09:09,123] {azureToSnowflake.py:73} INFO - Executing COPY command...
[2022-06-23 23:09:09,131] {connection.py:257} INFO - Snowflake Connector for Python Version: 2.7.8, Python Version: 3.8.12, Platform: Linux-5.10.102.1-microsoft-standard-WSL2-x86_64-with-glibc2.2.5
[2022-06-23 23:09:09,132] {connection.py:876} INFO - This connection is in OCSP Fail Open Mode. TLS Certificates would be checked for validity and revocation status. Any other Certificate Revocation related exceptions or OCSP Responder failures would be disregarded in favor of connectivity.
[2022-06-23 23:09:09,132] {connection.py:894} INFO - Setting use_openssl_only mode to False
[2022-06-23 23:09:09,764] {cursor.py:710} INFO - query: [ALTER SESSION SET autocommit=True]
[2022-06-23 23:09:09,859] {cursor.py:734} INFO - query execution done
[2022-06-23 23:09:09,860] {snowflake.py:324} INFO - Running statement: COPY INTO STAGING_MATCHDETAILS
FROM @MY_AZURE_MATCH_DETAILS_STAGE/
files=('GOLD/2022/6/23/23.csv')
file_format=MATCH_DETAILS_FILEFORMAT, parameters: None
[2022-06-23 23:09:09,860] {cursor.py:710} INFO - query: [COPY INTO STAGING_MATCHDETAILS FROM @MY_AZURE_MATCH_DETAILS_STAGE/ files=('GOLD/...]
[2022-06-23 23:09:11,088] {cursor.py:734} INFO - query execution done
[2022-06-23 23:09:11,092] {connection.py:507} INFO - closed
[2022-06-23 23:09:11,129] {connection.py:510} INFO - No async queries seem to be running, deleting session
[2022-06-23 23:09:11,189] {taskinstance.py:1718} ERROR - Task failed with exception
Traceback (most recent call last):
  File "/home/airflow/.local/lib/python3.8/site-packages/airflow/models/taskinstance.py", line 1334, in _run_raw_task
    self._execute_task_with_callbacks(context)
  File "/home/airflow/.local/lib/python3.8/site-packages/airflow/models/taskinstance.py", line 1460, in _execute_task_with_callbacks
    result = self._execute_task(context, self.task)
  File "/home/airflow/.local/lib/python3.8/site-packages/airflow/models/taskinstance.py", line 1516, in _execute_task
    result = execute_callable(context=context)
  File "/opt/airflow/plugins/custom_transfers/azureToSnowflake.py", line 74, in execute
    snowflake_hook.run(copy_query, self.autocommit)
  File "/home/airflow/.local/lib/python3.8/site-packages/airflow/providers/snowflake/hooks/snowflake.py", line 328, in run
    cur.execute(sql_statement)
  File "/home/airflow/.local/lib/python3.8/site-packages/snowflake/connector/cursor.py", line 799, in execute
    Error.errorhandler_wrapper(self.connection, self, error_class, errvalue)
  File "/home/airflow/.local/lib/python3.8/site-packages/snowflake/connector/errors.py", line 273, in errorhandler_wrapper
    handed_over = Error.hand_to_other_handler(
  File "/home/airflow/.local/lib/python3.8/site-packages/snowflake/connector/errors.py", line 328, in hand_to_other_handler
    cursor.errorhandler(connection, cursor, error_class, error_value)
  File "/home/airflow/.local/lib/python3.8/site-packages/snowflake/connector/errors.py", line 207, in default_errorhandler
    raise error_class(
snowflake.connector.errors.ProgrammingError: 100037 (22018): 01a5262d-0000-fcc5-0000-d96900059812: Boolean value '15988' is not recognized
  File 'GOLD/2022/6/23/23.csv', line 2, character 109
  Row 1, column "STAGING_MATCHDETAILS"["GAMEENDEDINSURRENDER":25]
  If you would like to continue loading when an error is encountered, use other values such as 'SKIP_FILE' or 'CONTINUE' for the ON_ERROR option. For more information on loading options, please run 'info loading_data' in a SQL client.
[2022-06-23 23:09:11,201] {taskinstance.py:1272} INFO - Marking task as UP_FOR_RETRY. dag_id=match_details_dag, task_id=azure_toSnowflake_paths.path_matchdetails.azure_matchdetails_snowflake, execution_date=20220620T000000, start_date=20220623T230909, end_date=20220623T230911
[2022-06-23 23:09:11,212] {standard_task_runner.py:89} ERROR - Failed to execute job 329 for task azure_toSnowflake_paths.path_matchdetails.azure_matchdetails_snowflake
Traceback (most recent call last):
  File "/home/airflow/.local/lib/python3.8/site-packages/airflow/task/task_runner/standard_task_runner.py", line 85, in _start_by_fork
    args.func(args, dag=self.dag)
  File "/home/airflow/.local/lib/python3.8/site-packages/airflow/cli/cli_parser.py", line 48, in command
    return func(*args, **kwargs)
  File "/home/airflow/.local/lib/python3.8/site-packages/airflow/utils/cli.py", line 92, in wrapper
    return f(*args, **kwargs)
  File "/home/airflow/.local/lib/python3.8/site-packages/airflow/cli/commands/task_command.py", line 298, in task_run
    _run_task_by_selected_method(args, dag, ti)
  File "/home/airflow/.local/lib/python3.8/site-packages/airflow/cli/commands/task_command.py", line 107, in _run_task_by_selected_method
    _run_raw_task(args, ti)
  File "/home/airflow/.local/lib/python3.8/site-packages/airflow/cli/commands/task_command.py", line 180, in _run_raw_task
    ti._run_raw_task(
  File "/home/airflow/.local/lib/python3.8/site-packages/airflow/utils/session.py", line 70, in wrapper
    return func(*args, session=session, **kwargs)
  File "/home/airflow/.local/lib/python3.8/site-packages/airflow/models/taskinstance.py", line 1334, in _run_raw_task
    self._execute_task_with_callbacks(context)
  File "/home/airflow/.local/lib/python3.8/site-packages/airflow/models/taskinstance.py", line 1460, in _execute_task_with_callbacks
    result = self._execute_task(context, self.task)
  File "/home/airflow/.local/lib/python3.8/site-packages/airflow/models/taskinstance.py", line 1516, in _execute_task
    result = execute_callable(context=context)
  File "/opt/airflow/plugins/custom_transfers/azureToSnowflake.py", line 74, in execute
    snowflake_hook.run(copy_query, self.autocommit)
  File "/home/airflow/.local/lib/python3.8/site-packages/airflow/providers/snowflake/hooks/snowflake.py", line 328, in run
    cur.execute(sql_statement)
  File "/home/airflow/.local/lib/python3.8/site-packages/snowflake/connector/cursor.py", line 799, in execute
    Error.errorhandler_wrapper(self.connection, self, error_class, errvalue)
  File "/home/airflow/.local/lib/python3.8/site-packages/snowflake/connector/errors.py", line 273, in errorhandler_wrapper
    handed_over = Error.hand_to_other_handler(
  File "/home/airflow/.local/lib/python3.8/site-packages/snowflake/connector/errors.py", line 328, in hand_to_other_handler
    cursor.errorhandler(connection, cursor, error_class, error_value)
  File "/home/airflow/.local/lib/python3.8/site-packages/snowflake/connector/errors.py", line 207, in default_errorhandler
    raise error_class(
snowflake.connector.errors.ProgrammingError: 100037 (22018): 01a5262d-0000-fcc5-0000-d96900059812: Boolean value '15988' is not recognized
  File 'GOLD/2022/6/23/23.csv', line 2, character 109
  Row 1, column "STAGING_MATCHDETAILS"["GAMEENDEDINSURRENDER":25]
  If you would like to continue loading when an error is encountered, use other values such as 'SKIP_FILE' or 'CONTINUE' for the ON_ERROR option. For more information on loading options, please run 'info loading_data' in a SQL client.
[2022-06-23 23:09:11,222] {local_task_job.py:154} INFO - Task exited with return code 1
[2022-06-23 23:09:11,255] {local_task_job.py:264} INFO - 0 downstream tasks scheduled from follow-on schedule check
[2022-06-24 02:49:04,925] {taskinstance.py:1037} INFO - Dependencies all met for <TaskInstance: match_details_dag.azure_toSnowflake_paths.path_matchdetails.azure_matchdetails_snowflake scheduled__2022-06-20T00:00:00+00:00 [None]>
[2022-06-24 02:49:04,937] {taskinstance.py:1037} INFO - Dependencies all met for <TaskInstance: match_details_dag.azure_toSnowflake_paths.path_matchdetails.azure_matchdetails_snowflake scheduled__2022-06-20T00:00:00+00:00 [None]>
[2022-06-24 02:49:04,937] {taskinstance.py:1243} INFO - 
--------------------------------------------------------------------------------
[2022-06-24 02:49:04,937] {taskinstance.py:1244} INFO - Starting attempt 4 of 5
[2022-06-24 02:49:04,937] {taskinstance.py:1245} INFO - 
--------------------------------------------------------------------------------
[2022-06-24 02:49:04,950] {taskinstance.py:1264} INFO - Executing <Task(AzureDataLakeToSnowflakeTransferOperator): azure_toSnowflake_paths.path_matchdetails.azure_matchdetails_snowflake> on 2022-06-20 00:00:00+00:00
[2022-06-24 02:49:04,954] {standard_task_runner.py:52} INFO - Started process 69 to run task
[2022-06-24 02:49:04,957] {standard_task_runner.py:76} INFO - Running: ['***', 'tasks', 'run', 'match_details_dag', 'azure_toSnowflake_paths.path_matchdetails.azure_matchdetails_snowflake', 'scheduled__2022-06-20T00:00:00+00:00', '--job-id', '345', '--pool', 'default_pool', '--raw', '--subdir', 'DAGS_FOLDER/matchData_dag.py', '--cfg-path', '/tmp/tmp0b2yw3pt', '--error-file', '/tmp/tmphu1ndx9n']
[2022-06-24 02:49:04,957] {standard_task_runner.py:77} INFO - Job 345: Subtask azure_toSnowflake_paths.path_matchdetails.azure_matchdetails_snowflake
[2022-06-24 02:49:05,009] {logging_mixin.py:109} INFO - Running <TaskInstance: match_details_dag.azure_toSnowflake_paths.path_matchdetails.azure_matchdetails_snowflake scheduled__2022-06-20T00:00:00+00:00 [running]> on host ebe3cc7dbee2
[2022-06-24 02:49:05,058] {taskinstance.py:1429} INFO - Exporting the following env vars:
AIRFLOW_CTX_DAG_OWNER=admin
AIRFLOW_CTX_DAG_ID=match_details_dag
AIRFLOW_CTX_TASK_ID=azure_toSnowflake_paths.path_matchdetails.azure_matchdetails_snowflake
AIRFLOW_CTX_EXECUTION_DATE=2022-06-20T00:00:00+00:00
AIRFLOW_CTX_DAG_RUN_ID=scheduled__2022-06-20T00:00:00+00:00
[2022-06-24 02:49:05,059] {azureToSnowflake.py:73} INFO - Executing COPY command...
[2022-06-24 02:49:05,069] {connection.py:257} INFO - Snowflake Connector for Python Version: 2.7.8, Python Version: 3.8.12, Platform: Linux-5.10.102.1-microsoft-standard-WSL2-x86_64-with-glibc2.2.5
[2022-06-24 02:49:05,070] {connection.py:876} INFO - This connection is in OCSP Fail Open Mode. TLS Certificates would be checked for validity and revocation status. Any other Certificate Revocation related exceptions or OCSP Responder failures would be disregarded in favor of connectivity.
[2022-06-24 02:49:05,070] {connection.py:894} INFO - Setting use_openssl_only mode to False
[2022-06-24 02:49:05,782] {cursor.py:710} INFO - query: [ALTER SESSION SET autocommit=True]
[2022-06-24 02:49:05,875] {cursor.py:734} INFO - query execution done
[2022-06-24 02:49:05,875] {snowflake.py:324} INFO - Running statement: COPY INTO STAGING_MATCHDETAILS
FROM @MY_AZURE_MATCH_DETAILS_STAGE/
files=('GOLD/2022/6/24/2.csv')
file_format=MATCH_DETAILS_FILEFORMAT, parameters: None
[2022-06-24 02:49:05,876] {cursor.py:710} INFO - query: [COPY INTO STAGING_MATCHDETAILS FROM @MY_AZURE_MATCH_DETAILS_STAGE/ files=('GOLD/...]
[2022-06-24 02:49:07,386] {cursor.py:734} INFO - query execution done
[2022-06-24 02:49:07,396] {connection.py:507} INFO - closed
[2022-06-24 02:49:07,444] {connection.py:510} INFO - No async queries seem to be running, deleting session
[2022-06-24 02:49:07,514] {taskinstance.py:1718} ERROR - Task failed with exception
Traceback (most recent call last):
  File "/home/airflow/.local/lib/python3.8/site-packages/airflow/models/taskinstance.py", line 1334, in _run_raw_task
    self._execute_task_with_callbacks(context)
  File "/home/airflow/.local/lib/python3.8/site-packages/airflow/models/taskinstance.py", line 1460, in _execute_task_with_callbacks
    result = self._execute_task(context, self.task)
  File "/home/airflow/.local/lib/python3.8/site-packages/airflow/models/taskinstance.py", line 1516, in _execute_task
    result = execute_callable(context=context)
  File "/opt/airflow/plugins/custom_transfers/azureToSnowflake.py", line 74, in execute
    snowflake_hook.run(copy_query, self.autocommit)
  File "/home/airflow/.local/lib/python3.8/site-packages/airflow/providers/snowflake/hooks/snowflake.py", line 328, in run
    cur.execute(sql_statement)
  File "/home/airflow/.local/lib/python3.8/site-packages/snowflake/connector/cursor.py", line 799, in execute
    Error.errorhandler_wrapper(self.connection, self, error_class, errvalue)
  File "/home/airflow/.local/lib/python3.8/site-packages/snowflake/connector/errors.py", line 273, in errorhandler_wrapper
    handed_over = Error.hand_to_other_handler(
  File "/home/airflow/.local/lib/python3.8/site-packages/snowflake/connector/errors.py", line 328, in hand_to_other_handler
    cursor.errorhandler(connection, cursor, error_class, error_value)
  File "/home/airflow/.local/lib/python3.8/site-packages/snowflake/connector/errors.py", line 207, in default_errorhandler
    raise error_class(
snowflake.connector.errors.ProgrammingError: 100038 (22018): 01a52709-0000-fcc5-0000-d96900059912: Numeric value 'TOP' is not recognized
  File 'GOLD/2022/6/24/2.csv', line 2, character 171
  Row 1, column "STAGING_MATCHDETAILS"["KILLS":41]
  If you would like to continue loading when an error is encountered, use other values such as 'SKIP_FILE' or 'CONTINUE' for the ON_ERROR option. For more information on loading options, please run 'info loading_data' in a SQL client.
[2022-06-24 02:49:07,531] {taskinstance.py:1272} INFO - Marking task as UP_FOR_RETRY. dag_id=match_details_dag, task_id=azure_toSnowflake_paths.path_matchdetails.azure_matchdetails_snowflake, execution_date=20220620T000000, start_date=20220624T024904, end_date=20220624T024907
[2022-06-24 02:49:07,556] {standard_task_runner.py:89} ERROR - Failed to execute job 345 for task azure_toSnowflake_paths.path_matchdetails.azure_matchdetails_snowflake
Traceback (most recent call last):
  File "/home/airflow/.local/lib/python3.8/site-packages/airflow/task/task_runner/standard_task_runner.py", line 85, in _start_by_fork
    args.func(args, dag=self.dag)
  File "/home/airflow/.local/lib/python3.8/site-packages/airflow/cli/cli_parser.py", line 48, in command
    return func(*args, **kwargs)
  File "/home/airflow/.local/lib/python3.8/site-packages/airflow/utils/cli.py", line 92, in wrapper
    return f(*args, **kwargs)
  File "/home/airflow/.local/lib/python3.8/site-packages/airflow/cli/commands/task_command.py", line 298, in task_run
    _run_task_by_selected_method(args, dag, ti)
  File "/home/airflow/.local/lib/python3.8/site-packages/airflow/cli/commands/task_command.py", line 107, in _run_task_by_selected_method
    _run_raw_task(args, ti)
  File "/home/airflow/.local/lib/python3.8/site-packages/airflow/cli/commands/task_command.py", line 180, in _run_raw_task
    ti._run_raw_task(
  File "/home/airflow/.local/lib/python3.8/site-packages/airflow/utils/session.py", line 70, in wrapper
    return func(*args, session=session, **kwargs)
  File "/home/airflow/.local/lib/python3.8/site-packages/airflow/models/taskinstance.py", line 1334, in _run_raw_task
    self._execute_task_with_callbacks(context)
  File "/home/airflow/.local/lib/python3.8/site-packages/airflow/models/taskinstance.py", line 1460, in _execute_task_with_callbacks
    result = self._execute_task(context, self.task)
  File "/home/airflow/.local/lib/python3.8/site-packages/airflow/models/taskinstance.py", line 1516, in _execute_task
    result = execute_callable(context=context)
  File "/opt/airflow/plugins/custom_transfers/azureToSnowflake.py", line 74, in execute
    snowflake_hook.run(copy_query, self.autocommit)
  File "/home/airflow/.local/lib/python3.8/site-packages/airflow/providers/snowflake/hooks/snowflake.py", line 328, in run
    cur.execute(sql_statement)
  File "/home/airflow/.local/lib/python3.8/site-packages/snowflake/connector/cursor.py", line 799, in execute
    Error.errorhandler_wrapper(self.connection, self, error_class, errvalue)
  File "/home/airflow/.local/lib/python3.8/site-packages/snowflake/connector/errors.py", line 273, in errorhandler_wrapper
    handed_over = Error.hand_to_other_handler(
  File "/home/airflow/.local/lib/python3.8/site-packages/snowflake/connector/errors.py", line 328, in hand_to_other_handler
    cursor.errorhandler(connection, cursor, error_class, error_value)
  File "/home/airflow/.local/lib/python3.8/site-packages/snowflake/connector/errors.py", line 207, in default_errorhandler
    raise error_class(
snowflake.connector.errors.ProgrammingError: 100038 (22018): 01a52709-0000-fcc5-0000-d96900059912: Numeric value 'TOP' is not recognized
  File 'GOLD/2022/6/24/2.csv', line 2, character 171
  Row 1, column "STAGING_MATCHDETAILS"["KILLS":41]
  If you would like to continue loading when an error is encountered, use other values such as 'SKIP_FILE' or 'CONTINUE' for the ON_ERROR option. For more information on loading options, please run 'info loading_data' in a SQL client.
[2022-06-24 02:49:07,579] {local_task_job.py:154} INFO - Task exited with return code 1
[2022-06-24 02:49:07,629] {local_task_job.py:264} INFO - 0 downstream tasks scheduled from follow-on schedule check
